Workbook
Name AAPL: MonthlyReturns!$B:$B
Name META: MonthlyReturns!$D:$D
Name NVDA: MonthlyReturns!$C:$C
Name SMCI: MonthlyReturns!$E:$E

Sheet Data
A1: Dates | B1: Monthly | C1: Key | D1: AAPL | E1: NVDA | F1: META | G1: SMCI
A2: 45957 | B2: =EOMONTH(A2, -1)+1 -> 45931 | C2: =TEXT(A2, "yyyy-mm") -> 2025-10 | D2: 268.81 | E2: 191.49 | F2: 750.82 | G2: 51.57
A3: 45954 | B3: =EOMONTH(A3, -1)+1 -> 45931 | C3: =TEXT(A3, "yyyy-mm") -> 2025-10 | D3: 262.82 | E3: 186.26 | F3: 738.36 | G3: 48.29
A4: 45953 | B4: =EOMONTH(A4, -1)+1 -> 45931 | C4: =TEXT(A4, "yyyy-mm") -> 2025-10 | D4: 259.58 | E4: 182.16 | F4: 734 | G4: 47.92
A5: 45952 | B5: =EOMONTH(A5, -1)+1 -> 45931 | C5: =TEXT(A5, "yyyy-mm") -> 2025-10 | D5: 258.45 | E5: 180.28 | F5: 733.41 | G5: 52.5
A6: 45951 | B6: =EOMONTH(A6, -1)+1 -> 45931 | C6: =TEXT(A6, "yyyy-mm") -> 2025-10 | D6: 262.77 | E6: 181.16 | F6: 733.27 | G6: 54.82
A7: 45950 | B7: =EOMONTH(A7, -1)+1 -> 45931 | C7: =TEXT(A7, "yyyy-mm") -> 2025-10 | D7: 262.24 | E7: 182.64 | F7: 732.17 | G7: 55.04
A8: 45947 | B8: =EOMONTH(A8, -1)+1 -> 45931 | C8: =TEXT(A8, "yyyy-mm") -> 2025-10 | D8: 252.29 | E8: 183.22 | F8: 716.92 | G8: 52.18
A9: 45946 | B9: =EOMONTH(A9, -1)+1 -> 45931 | C9: =TEXT(A9, "yyyy-mm") -> 2025-10 | D9: 247.45 | E9: 181.81 | F9: 712.07 | G9: 53.84
A10: 45945 | B10: =EOMONTH(A10, -1)+1 -> 45931 | C10: =TEXT(A10, "yyyy-mm") -> 2025-10 | D10: 249.34 | E10: 179.83 | F10: 717.55 | G10: 53.94
A11: 45944 | B11: =EOMONTH(A11, -1)+1 -> 45931 | C11: =TEXT(A11, "yyyy-mm") -> 2025-10 | D11: 247.77 | E11: 180.03 | F11: 708.65 | G11: 53.11
A12: 45943 | B12: =EOMONTH(A12, -1)+1 -> 45931 | C12: =TEXT(A12, "yyyy-mm") -> 2025-10 | D12: 247.66 | E12: 188.32 | F12: 715.7 | G12: 54.75
A13: 45940 | B13: =EOMONTH(A13, -1)+1 -> 45931 | C13: =TEXT(A13, "yyyy-mm") -> 2025-10 | D13: 245.27 | E13: 183.16 | F13: 705.3 | G13: 52.86
... A2515: 42305 | B2515: =EOMONTH(A2515, -1)+1 -> 42278 | C2515: =TEXT(A2515, "yyyy-mm") -> 2015-10 | D2515: 29.82 | E2515: 0.72 | F2515: 104.2 | G2515: 2.84

Sheet MonthlyData
A1: Company Name | C1: Apple | D1: Nvidia | E1: Meta | F1: Super Micro
A2: Ticker | C2: AAPL | D2: NVDA | E2: META | F2: SMCI
A3: Market Capitalization | C3: 3989245235900 | D3: 4653207000000 | E3: 1886166062260 | F3: 30646674494
A5: Key | B5: Dates | C5: AAPL | D5: NVDA | E5: META | F5: SMCI
A6: {=_xlfn.UNIQUE(Data!C2:C2515)} -> 2025-10 | B6: =_xlfn.MINIFS(Data!$A$2:$A$2515, Data!$C$2:$C$2515, MonthlyData!A126) -> 42305 | C6: =_xlfn.XLOOKUP(B6, Data!$A$2:$A$2515, Data!$D$2:$D$2515, " ") -> 29.82 | D6: =_xlfn.XLOOKUP(B6, Data!$A$2:$A$2515, Data!$E$2:$E$2515, " ") -> 0.72 | E6: =_xlfn.XLOOKUP($B6, Data!$A$2:$A$2515, Data!$F$2:$F$2515, " ") -> 104.2 | F6: =_xlfn.XLOOKUP($B6, Data!$A$2:$A$2515, Data!$G$2:$G$2515, " ") -> 2.84
A7: 2025-09 | B7: =_xlfn.MINIFS(Data!$A$2:$A$2515, Data!$C$2:$C$2515, MonthlyData!A125) -> 42310 | C7: =_xlfn.XLOOKUP(B7, Data!$A$2:$A$2515, Data!$D$2:$D$2515, " ") -> 30.3 | D7: =_xlfn.XLOOKUP(B7, Data!$A$2:$A$2515, Data!$E$2:$E$2515, " ") -> 0.72 | E7: =_xlfn.XLOOKUP($B7, Data!$A$2:$A$2515, Data!$F$2:$F$2515, " ") -> 103.31 | F7: =_xlfn.XLOOKUP($B7, Data!$A$2:$A$2515, Data!$G$2:$G$2515, " ") -> 2.97
A8: 2025-08 | B8: =_xlfn.MINIFS(Data!$A$2:$A$2515, Data!$C$2:$C$2515, MonthlyData!A124) -> 42339 | C8: =_xlfn.XLOOKUP(B8, Data!$A$2:$A$2515, Data!$D$2:$D$2515, " ") -> 29.34 | D8: =_xlfn.XLOOKUP(B8, Data!$A$2:$A$2515, Data!$E$2:$E$2515, " ") -> 0.82 | E8: =_xlfn.XLOOKUP($B8, Data!$A$2:$A$2515, Data!$F$2:$F$2515, " ") -> 107.12 | F8: =_xlfn.XLOOKUP($B8, Data!$A$2:$A$2515, Data!$G$2:$G$2515, " ") -> 2.62
A9: 2025-07 | B9: =_xlfn.MINIFS(Data!$A$2:$A$2515, Data!$C$2:$C$2515, MonthlyData!A123) -> 42373 | C9: =_xlfn.XLOOKUP(B9, Data!$A$2:$A$2515, Data!$D$2:$D$2515, " ") -> 26.34 | D9: =_xlfn.XLOOKUP(B9, Data!$A$2:$A$2515, Data!$E$2:$E$2515, " ") -> 0.81 | E9: =_xlfn.XLOOKUP($B9, Data!$A$2:$A$2515, Data!$F$2:$F$2515, " ") -> 102.22 | F9: =_xlfn.XLOOKUP($B9, Data!$A$2:$A$2515, Data!$G$2:$G$2515, " ") -> 2.37
A10: 2025-06 | B10: =_xlfn.MINIFS(Data!$A$2:$A$2515, Data!$C$2:$C$2515, MonthlyData!A122) -> 42401 | C10: =_xlfn.XLOOKUP(B10, Data!$A$2:$A$2515, Data!$D$2:$D$2515, " ") -> 24.11 | D10: =_xlfn.XLOOKUP(B10, Data!$A$2:$A$2515, Data!$E$2:$E$2515, " ") -> 0.73 | E10: =_xlfn.XLOOKUP($B10, Data!$A$2:$A$2515, Data!$F$2:$F$2515, " ") -> 115.09 | F10: =_xlfn.XLOOKUP($B10, Data!$A$2:$A$2515, Data!$G$2:$G$2515, " ") -> 3.14
A11: 2025-05 | B11: =_xlfn.MINIFS(Data!$A$2:$A$2515, Data!$C$2:$C$2515, MonthlyData!A121) -> 42430 | C11: =_xlfn.XLOOKUP(B11, Data!$A$2:$A$2515, Data!$D$2:$D$2515, " ") -> 25.13 | D11: =_xlfn.XLOOKUP(B11, Data!$A$2:$A$2515, Data!$E$2:$E$2515, " ") -> 0.82 | E11: =_xlfn.XLOOKUP($B11, Data!$A$2:$A$2515, Data!$F$2:$F$2515, " ") -> 109.82 | F11: =_xlfn.XLOOKUP($B11, Data!$A$2:$A$2515, Data!$G$2:$G$2515, " ") -> 3.32
A12: 2025-04 | B12: =_xlfn.MINIFS(Data!$A$2:$A$2515, Data!$C$2:$C$2515, MonthlyData!A120) -> 42461 | C12: =_xlfn.XLOOKUP(B12, Data!$A$2:$A$2515, Data!$D$2:$D$2515, " ") -> 27.5 | D12: =_xlfn.XLOOKUP(B12, Data!$A$2:$A$2515, Data!$E$2:$E$2515, " ") -> 0.9 | E12: =_xlfn.XLOOKUP($B12, Data!$A$2:$A$2515, Data!$F$2:$F$2515, " ") -> 116.06 | F12: =_xlfn.XLOOKUP($B12, Data!$A$2:$A$2515, Data!$G$2:$G$2515, " ") -> 3.45
A13: 2025-03 | B13: =_xlfn.MINIFS(Data!$A$2:$A$2515, Data!$C$2:$C$2515, MonthlyData!A119) -> 42492 | C13: =_xlfn.XLOOKUP(B13, Data!$A$2:$A$2515, Data!$D$2:$D$2515, " ") -> 23.41 | D13: =_xlfn.XLOOKUP(B13, Data!$A$2:$A$2515, Data!$E$2:$E$2515, " ") -> 0.9 | E13: =_xlfn.XLOOKUP($B13, Data!$A$2:$A$2515, Data!$F$2:$F$2515, " ") -> 118.57 | F13: =_xlfn.XLOOKUP($B13, Data!$A$2:$A$2515, Data!$G$2:$G$2515, " ") -> 2.72
A14: 2025-02 | B14: =_xlfn.MINIFS(Data!$A$2:$A$2515, Data!$C$2:$C$2515, MonthlyData!A118) -> 42522 | C14: =_xlfn.XLOOKUP(B14, Data!$A$2:$A$2515, Data!$D$2:$D$2515, " ") -> 24.62 | D14: =_xlfn.XLOOKUP(B14, Data!$A$2:$A$2515, Data!$E$2:$E$2515, " ") -> 1.17 | E14: =_xlfn.XLOOKUP($B14, Data!$A$2:$A$2515, Data!$F$2:$F$2515, " ") -> 118.78 | F14: =_xlfn.XLOOKUP($B14, Data!$A$2:$A$2515, Data!$G$2:$G$2515, " ") -> 2.64
A15: 2025-01 | B15: =_xlfn.MINIFS(Data!$A$2:$A$2515, Data!$C$2:$C$2515, MonthlyData!A117) -> 42552 | C15: =_xlfn.XLOOKUP(B15, Data!$A$2:$A$2515, Data!$D$2:$D$2515, " ") -> 23.97 | D15: =_xlfn.XLOOKUP(B15, Data!$A$2:$A$2515, Data!$E$2:$E$2515, " ") -> 1.17 | E15: =_xlfn.XLOOKUP($B15, Data!$A$2:$A$2515, Data!$F$2:$F$2515, " ") -> 114.19 | F15: =_xlfn.XLOOKUP($B15, Data!$A$2:$A$2515, Data!$G$2:$G$2515, " ") -> 2.46
A16: 2024-12 | B16: =_xlfn.MINIFS(Data!$A$2:$A$2515, Data!$C$2:$C$2515, MonthlyData!A116) -> 42583 | C16: =_xlfn.XLOOKUP(B16, Data!$A$2:$A$2515, Data!$D$2:$D$2515, " ") -> 26.51 | D16: =_xlfn.XLOOKUP(B16, Data!$A$2:$A$2515, Data!$E$2:$E$2515, " ") -> 1.42 | E16: =_xlfn.XLOOKUP($B16, Data!$A$2:$A$2515, Data!$F$2:$F$2515, " ") -> 124.31 | F16: =_xlfn.XLOOKUP($B16, Data!$A$2:$A$2515, Data!$G$2:$G$2515, " ") -> 2.16
A17: 2024-11 | B17: =_xlfn.MINIFS(Data!$A$2:$A$2515, Data!$C$2:$C$2515, MonthlyData!A115) -> 42614 | C17: =_xlfn.XLOOKUP(B17, Data!$A$2:$A$2515, Data!$D$2:$D$2515, " ") -> 26.68 | D17: =_xlfn.XLOOKUP(B17, Data!$A$2:$A$2515, Data!$E$2:$E$2515, " ") -> 1.58 | E17: =_xlfn.XLOOKUP($B17, Data!$A$2:$A$2515, Data!$F$2:$F$2515, " ") -> 126.17 | F17: =_xlfn.XLOOKUP($B17, Data!$A$2:$A$2515, Data!$G$2:$G$2515, " ") -> 2.21
A18: 2024-10 | B18: =_xlfn.MINIFS(Data!$A$2:$A$2515, Data!$C$2:$C$2515, MonthlyData!A114) -> 42646 | C18: =_xlfn.XLOOKUP(B18, Data!$A$2:$A$2515, Data!$D$2:$D$2515, " ") -> 28.13 | D18: =_xlfn.XLOOKUP(B18, Data!$A$2:$A$2515, Data!$E$2:$E$2515, " ") -> 1.71 | E18: =_xlfn.XLOOKUP($B18, Data!$A$2:$A$2515, Data!$F$2:$F$2515, " ") -> 128.77 | F18: =_xlfn.XLOOKUP($B18, Data!$A$2:$A$2515, Data!$G$2:$G$2515, " ") -> 2.35
A19: 2024-09 | B19: =_xlfn.MINIFS(Data!$A$2:$A$2515, Data!$C$2:$C$2515, MonthlyData!A113) -> 42675 | C19: =_xlfn.XLOOKUP(B19, Data!$A$2:$A$2515, Data!$D$2:$D$2515, " ") -> 27.87 | D19: =_xlfn.XLOOKUP(B19, Data!$A$2:$A$2515, Data!$E$2:$E$2515, " ") -> 1.73 | E19: =_xlfn.XLOOKUP($B19, Data!$A$2:$A$2515, Data!$F$2:$F$2515, " ") -> 129.5 | F19: =_xlfn.XLOOKUP($B19, Data!$A$2:$A$2515, Data!$G$2:$G$2515, " ") -> 2.28
A20: 2024-08 | B20: =_xlfn.MINIFS(Data!$A$2:$A$2515, Data!$C$2:$C$2515, MonthlyData!A112) -> 42705 | C20: =_xlfn.XLOOKUP(B20, Data!$A$2:$A$2515, Data!$D$2:$D$2515, " ") -> 27.37 | D20: =_xlfn.XLOOKUP(B20, Data!$A$2:$A$2515, Data!$E$2:$E$2515, " ") -> 2.19 | E20: =_xlfn.XLOOKUP($B20, Data!$A$2:$A$2515, Data!$F$2:$F$2515, " ") -> 115.1 | F20: =_xlfn.XLOOKUP($B20, Data!$A$2:$A$2515, Data!$G$2:$G$2515, " ") -> 2.62
A21: 2024-07 | B21: =_xlfn.MINIFS(Data!$A$2:$A$2515, Data!$C$2:$C$2515, MonthlyData!A111) -> 42738 | C21: =_xlfn.XLOOKUP(B21, Data!$A$2:$A$2515, Data!$D$2:$D$2515, " ") -> 29.04 | D21: =_xlfn.XLOOKUP(B21, Data!$A$2:$A$2515, Data!$E$2:$E$2515, " ") -> 2.55 | E21: =_xlfn.XLOOKUP($B21, Data!$A$2:$A$2515, Data!$F$2:$F$2515, " ") -> 116.86 | F21: =_xlfn.XLOOKUP($B21, Data!$A$2:$A$2515, Data!$G$2:$G$2515, " ") -> 2.85
A22: 2024-06 | B22: =_xlfn.MINIFS(Data!$A$2:$A$2515, Data!$C$2:$C$2515, MonthlyData!A110) -> 42767 | C22: =_xlfn.XLOOKUP(B22, Data!$A$2:$A$2515, Data!$D$2:$D$2515, " ") -> 32.19 | D22: =_xlfn.XLOOKUP(B22, Data!$A$2:$A$2515, Data!$E$2:$E$2515, " ") -> 2.85 | E22: =_xlfn.XLOOKUP($B22, Data!$A$2:$A$2515, Data!$F$2:$F$2515, " ") -> 133.23 | F22: =_xlfn.XLOOKUP($B22, Data!$A$2:$A$2515, Data!$G$2:$G$2515, " ") -> 2.56
A23: 2024-05 | B23: =_xlfn.MINIFS(Data!$A$2:$A$2515, Data!$C$2:$C$2515, MonthlyData!A109) -> 42795 | C23: =_xlfn.XLOOKUP(B23, Data!$A$2:$A$2515, Data!$D$2:$D$2515, " ") -> 34.95 | D23: =_xlfn.XLOOKUP(B23, Data!$A$2:$A$2515, Data!$E$2:$E$2515, " ") -> 2.57 | E23: =_xlfn.XLOOKUP($B23, Data!$A$2:$A$2515, Data!$F$2:$F$2515, " ") -> 137.42 | F23: =_xlfn.XLOOKUP($B23, Data!$A$2:$A$2515, Data!$G$2:$G$2515, " ") -> 2.66
A24: 2024-04 | B24: =_xlfn.MINIFS(Data!$A$2:$A$2515, Data!$C$2:$C$2515, MonthlyData!A108) -> 42828 | C24: =_xlfn.XLOOKUP(B24, Data!$A$2:$A$2515, Data!$D$2:$D$2515, " ") -> 35.93 | D24: =_xlfn.XLOOKUP(B24, Data!$A$2:$A$2515, Data!$E$2:$E$2515, " ") -> 2.71 | E24: =_xlfn.XLOOKUP($B24, Data!$A$2:$A$2515, Data!$F$2:$F$2515, " ") -> 142.28 | F24: =_xlfn.XLOOKUP($B24, Data!$A$2:$A$2515, Data!$G$2:$G$2515, " ") -> 2.51
A25: 2024-03 | B25: =_xlfn.MINIFS(Data!$A$2:$A$2515, Data!$C$2:$C$2515, MonthlyData!A107) -> 42856 | C25: =_xlfn.XLOOKUP(B25, Data!$A$2:$A$2515, Data!$D$2:$D$2515, " ") -> 36.65 | D25: =_xlfn.XLOOKUP(B25, Data!$A$2:$A$2515, Data!$E$2:$E$2515, " ") -> 2.67 | E25: =_xlfn.XLOOKUP($B25, Data!$A$2:$A$2515, Data!$F$2:$F$2515, " ") -> 152.46 | F25: =_xlfn.XLOOKUP($B25, Data!$A$2:$A$2515, Data!$G$2:$G$2515, " ") -> 2.45
A26: 2024-02 | B26: =_xlfn.MINIFS(Data!$A$2:$A$2515, Data!$C$2:$C$2515, MonthlyData!A106) -> 42887 | C26: =_xlfn.XLOOKUP(B26, Data!$A$2:$A$2515, Data!$D$2:$D$2515, " ") -> 38.3 | D26: =_xlfn.XLOOKUP(B26, Data!$A$2:$A$2515, Data!$E$2:$E$2515, " ") -> 3.61 | E26: =_xlfn.XLOOKUP($B26, Data!$A$2:$A$2515, Data!$F$2:$F$2515, " ") -> 151.53 | F26: =_xlfn.XLOOKUP($B26, Data!$A$2:$A$2515, Data!$G$2:$G$2515, " ") -> 2.47
A27: 2024-01 | B27: =_xlfn.MINIFS(Data!$A$2:$A$2515, Data!$C$2:$C$2515, MonthlyData!A105) -> 42919 | C27: =_xlfn.XLOOKUP(B27, Data!$A$2:$A$2515, Data!$D$2:$D$2515, " ") -> 35.88 | D27: =_xlfn.XLOOKUP(B27, Data!$A$2:$A$2515, Data!$E$2:$E$2515, " ") -> 3.48 | E27: =_xlfn.XLOOKUP($B27, Data!$A$2:$A$2515, Data!$F$2:$F$2515, " ") -> 148.43 | F27: =_xlfn.XLOOKUP($B27, Data!$A$2:$A$2515, Data!$G$2:$G$2515, " ") -> 2.45
A28: 2023-12 | B28: =_xlfn.MINIFS(Data!$A$2:$A$2515, Data!$C$2:$C$2515, MonthlyData!A104) -> 42948 | C28: =_xlfn.XLOOKUP(B28, Data!$A$2:$A$2515, Data!$D$2:$D$2515, " ") -> 37.51 | D28: =_xlfn.XLOOKUP(B28, Data!$A$2:$A$2515, Data!$E$2:$E$2515, " ") -> 4.11 | E28: =_xlfn.XLOOKUP($B28, Data!$A$2:$A$2515, Data!$F$2:$F$2515, " ") -> 169.86 | F28: =_xlfn.XLOOKUP($B28, Data!$A$2:$A$2515, Data!$G$2:$G$2515, " ") -> 2.71
A29: 2023-11 | B29: =_xlfn.MINIFS(Data!$A$2:$A$2515, Data!$C$2:$C$2515, MonthlyData!A103) -> 42979 | C29: =_xlfn.XLOOKUP(B29, Data!$A$2:$A$2515, Data!$D$2:$D$2515, " ") -> 41.01 | D29: =_xlfn.XLOOKUP(B29, Data!$A$2:$A$2515, Data!$E$2:$E$2515, " ") -> 4.26 | E29: =_xlfn.XLOOKUP($B29, Data!$A$2:$A$2515, Data!$F$2:$F$2515, " ") -> 172.02 | F29: =_xlfn.XLOOKUP($B29, Data!$A$2:$A$2515, Data!$G$2:$G$2515, " ") -> 2.68
A30: 2023-10 | B30: =_xlfn.MINIFS(Data!$A$2:$A$2515, Data!$C$2:$C$2515, MonthlyData!A102) -> 43010 | C30: =_xlfn.XLOOKUP(B30, Data!$A$2:$A$2515, Data!$D$2:$D$2515, " ") -> 38.45 | D30: =_xlfn.XLOOKUP(B30, Data!$A$2:$A$2515, Data!$E$2:$E$2515, " ") -> 4.48 | E30: =_xlfn.XLOOKUP($B30, Data!$A$2:$A$2515, Data!$F$2:$F$2515, " ") -> 169.47 | F30: =_xlfn.XLOOKUP($B30, Data!$A$2:$A$2515, Data!$G$2:$G$2515, " ") -> 2.33
A31: 2023-09 | B31: =_xlfn.MINIFS(Data!$A$2:$A$2515, Data!$C$2:$C$2515, MonthlyData!A101) -> 43040 | C31: =_xlfn.XLOOKUP(B31, Data!$A$2:$A$2515, Data!$D$2:$D$2515, " ") -> 41.72 | D31: =_xlfn.XLOOKUP(B31, Data!$A$2:$A$2515, Data!$E$2:$E$2515, " ") -> 5.18 | E31: =_xlfn.XLOOKUP($B31, Data!$A$2:$A$2515, Data!$F$2:$F$2515, " ") -> 182.66 | F31: =_xlfn.XLOOKUP($B31, Data!$A$2:$A$2515, Data!$G$2:$G$2515, " ") -> 2.03
A32: 2023-08 | B32: =_xlfn.MINIFS(Data!$A$2:$A$2515, Data!$C$2:$C$2515, MonthlyData!A100) -> 43070 | C32: =_xlfn.XLOOKUP(B32, Data!$A$2:$A$2515, Data!$D$2:$D$2515, " ") -> 42.76 | D32: =_xlfn.XLOOKUP(B32, Data!$A$2:$A$2515, Data!$E$2:$E$2515, " ") -> 4.94 | E32: =_xlfn.XLOOKUP($B32, Data!$A$2:$A$2515, Data!$F$2:$F$2515, " ") -> 175.1 | F32: =_xlfn.XLOOKUP($B32, Data!$A$2:$A$2515, Data!$G$2:$G$2515, " ") -> 2.2
A33: 2023-07 | B33: =_xlfn.MINIFS(Data!$A$2:$A$2515, Data!$C$2:$C$2515, MonthlyData!A99) -> 43102 | C33: =_xlfn.XLOOKUP(B33, Data!$A$2:$A$2515, Data!$D$2:$D$2515, " ") -> 43.07 | D33: =_xlfn.XLOOKUP(B33, Data!$A$2:$A$2515, Data!$E$2:$E$2515, " ") -> 4.98 | E33: =_xlfn.XLOOKUP($B33, Data!$A$2:$A$2515, Data!$F$2:$F$2515, " ") -> 181.42 | F33: =_xlfn.XLOOKUP($B33, Data!$A$2:$A$2515, Data!$G$2:$G$2515, " ") -> 2.15
A34: 2023-06 | B34: =_xlfn.MINIFS(Data!$A$2:$A$2515, Data!$C$2:$C$2515, MonthlyData!A98) -> 43132 | C34: =_xlfn.XLOOKUP(B34, Data!$A$2:$A$2515, Data!$D$2:$D$2515, " ") -> 41.95 | D34: =_xlfn.XLOOKUP(B34, Data!$A$2:$A$2515, Data!$E$2:$E$2515, " ") -> 6.01 | E34: =_xlfn.XLOOKUP($B34, Data!$A$2:$A$2515, Data!$F$2:$F$2515, " ") -> 193.09 | F34: =_xlfn.XLOOKUP($B34, Data!$A$2:$A$2515, Data!$G$2:$G$2515, " ") -> 2.26
A35: 2023-05 | B35: =_xlfn.MINIFS(Data!$A$2:$A$2515, Data!$C$2:$C$2515, MonthlyData!A97) -> 43160 | C35: =_xlfn.XLOOKUP(B35, Data!$A$2:$A$2515, Data!$D$2:$D$2515, " ") -> 43.75 | D35: =_xlfn.XLOOKUP(B35, Data!$A$2:$A$2515, Data!$E$2:$E$2515, " ") -> 5.81 | E35: =_xlfn.XLOOKUP($B35, Data!$A$2:$A$2515, Data!$F$2:$F$2515, " ") -> 175.94 | F35: =_xlfn.XLOOKUP($B35, Data!$A$2:$A$2515, Data!$G$2:$G$2515, " ") -> 1.81
A36: 2023-04 | B36: =_xlfn.MINIFS(Data!$A$2:$A$2515, Data!$C$2:$C$2515, MonthlyData!A96) -> 43192 | C36: =_xlfn.XLOOKUP(B36, Data!$A$2:$A$2515, Data!$D$2:$D$2515, " ") -> 41.67 | D36: =_xlfn.XLOOKUP(B36, Data!$A$2:$A$2515, Data!$E$2:$E$2515, " ") -> 5.53 | E36: =_xlfn.XLOOKUP($B36, Data!$A$2:$A$2515, Data!$F$2:$F$2515, " ") -> 155.39 | F36: =_xlfn.XLOOKUP($B36, Data!$A$2:$A$2515, Data!$G$2:$G$2515, " ") -> 1.64
A37: 2023-03 | B37: =_xlfn.MINIFS(Data!$A$2:$A$2515, Data!$C$2:$C$2515, MonthlyData!A95) -> 43221 | C37: =_xlfn.XLOOKUP(B37, Data!$A$2:$A$2515, Data!$D$2:$D$2515, " ") -> 42.28 | D37: =_xlfn.XLOOKUP(B37, Data!$A$2:$A$2515, Data!$E$2:$E$2515, " ") -> 5.68 | E37: =_xlfn.XLOOKUP($B37, Data!$A$2:$A$2515, Data!$F$2:$F$2515, " ") -> 173.86 | F37: =_xlfn.XLOOKUP($B37, Data!$A$2:$A$2515, Data!$G$2:$G$2515, " ") -> 1.83
A38: 2023-02 | B38: =_xlfn.MINIFS(Data!$A$2:$A$2515, Data!$C$2:$C$2515, MonthlyData!A94) -> 43252 | C38: =_xlfn.XLOOKUP(B38, Data!$A$2:$A$2515, Data!$D$2:$D$2515, " ") -> 47.56 | D38: =_xlfn.XLOOKUP(B38, Data!$A$2:$A$2515, Data!$E$2:$E$2515, " ") -> 6.44 | E38: =_xlfn.XLOOKUP($B38, Data!$A$2:$A$2515, Data!$F$2:$F$2515, " ") -> 193.99 | F38: =_xlfn.XLOOKUP($B38, Data!$A$2:$A$2515, Data!$G$2:$G$2515, " ") -> 2.44
A39: 2023-01 | B39: =_xlfn.MINIFS(Data!$A$2:$A$2515, Data!$C$2:$C$2515, MonthlyData!A93) -> 43283 | C39: =_xlfn.XLOOKUP(B39, Data!$A$2:$A$2515, Data!$D$2:$D$2515, " ") -> 46.8 | D39: =_xlfn.XLOOKUP(B39, Data!$A$2:$A$2515, Data!$E$2:$E$2515, " ") -> 6.06 | E39: =_xlfn.XLOOKUP($B39, Data!$A$2:$A$2515, Data!$F$2:$F$2515, " ") -> 197.36 | F39: =_xlfn.XLOOKUP($B39, Data!$A$2:$A$2515, Data!$G$2:$G$2515, " ") -> 2.46
A40: 2022-12 | B40: =_xlfn.MINIFS(Data!$A$2:$A$2515, Data!$C$2:$C$2515, MonthlyData!A92) -> 43313 | C40: =_xlfn.XLOOKUP(B40, Data!$A$2:$A$2515, Data!$D$2:$D$2515, " ") -> 50.38 | D40: =_xlfn.XLOOKUP(B40, Data!$A$2:$A$2515, Data!$E$2:$E$2515, " ") -> 6.16 | E40: =_xlfn.XLOOKUP($B40, Data!$A$2:$A$2515, Data!$F$2:$F$2515, " ") -> 171.65 | F40: =_xlfn.XLOOKUP($B40, Data!$A$2:$A$2515, Data!$G$2:$G$2515, " ") -> 2.17
A41: 2022-11 | B41: =_xlfn.MINIFS(Data!$A$2:$A$2515, Data!$C$2:$C$2515, MonthlyData!A91) -> 43347 | C41: =_xlfn.XLOOKUP(B41, Data!$A$2:$A$2515, Data!$D$2:$D$2515, " ") -> 57.09 | D41: =_xlfn.XLOOKUP(B41, Data!$A$2:$A$2515, Data!$E$2:$E$2515, " ") -> 7.09 | E41: =_xlfn.XLOOKUP($B41, Data!$A$2:$A$2515, Data!$F$2:$F$2515, " ") -> 171.16 | F41: =_xlfn.XLOOKUP($B41, Data!$A$2:$A$2515, Data!$G$2:$G$2515, " ") -> 2.05
...

Sheet MonthlyReturns
A1: Dates | B1: AAPL | C1: NVDA | D1: META | E1: SMCI | I1: AAPL | J1: NVDA | K1: META | L1: SMCI | O1: Variance-Covariance Matrix
A2: 42310 | B2: --- | C2: --- | D2: --- | E2: --- | H2: Average Monthly Returns | I2: =AVERAGE(B2:B121) -> 0.020841136 | J2: =AVERAGE(C2:C121) -> 0.056798394 | K2: =AVERAGE(D2:D121) -> 0.022173365 | L2: =AVERAGE(E2:E121) -> 0.04197145 | O2: AAPL | P2: NVDA | Q2: META | R2: SMCI
A3: 42339 | B3: =(MonthlyData!C7-MonthlyData!C6)/MonthlyData!C6 -> 0.016096579 | C3: =(MonthlyData!D7-MonthlyData!D6)/MonthlyData!D6 -> 0 | D3: =(MonthlyData!E7-MonthlyData!E6)/MonthlyData!E6 -> -0.0085412668 | E3: =(MonthlyData!F7-MonthlyData!F6)/MonthlyData!F6 -> 0.045774648 | H3: Monthly Variance | I3: =_xlfn.VAR.S(B2:B121) -> 0.0071758097 | J3: =_xlfn.VAR.S(C2:C121) -> 0.020572775 | K3: =_xlfn.VAR.S(D2:D121) -> 0.011073994 | L3: =_xlfn.VAR.S(E2:E121) -> 0.048017242 | N3: AAPL | O3: =_xlfn.COVARIANCE.S($B$2:$B$121, B2:B121) -> 0.0071758097 | P3: =_xlfn.COVARIANCE.S($B$2:$B$121, C2:C121) -> 0.0071068701 | Q3: =_xlfn.COVARIANCE.S($B$2:$B$121, D2:D121) -> 0.0038231868 | R3: =_xlfn.COVARIANCE.S($B$2:$B$121, E2:E121) -> 0.0029922135
A4: 42373 | B4: =(MonthlyData!C8-MonthlyData!C7)/MonthlyData!C7 -> -0.031683168 | C4: =(MonthlyData!D8-MonthlyData!D7)/MonthlyData!D7 -> 0.13888889 | D4: =(MonthlyData!E8-MonthlyData!E7)/MonthlyData!E7 -> 0.036879295 | E4: =(MonthlyData!F8-MonthlyData!F7)/MonthlyData!F7 -> -0.11784512 | H4: Average Annual Returns | I4: =I2*12 -> 0.25009364 | J4: =J2*12 -> 0.68158073 | K4: =K2*12 -> 0.26608038 | L4: =L2*12 -> 0.50365741 | N4: NVDA | O4: =_xlfn.COVARIANCE.S($C$2:$C$121, B2:B121) -> 0.0071068701 | P4: =_xlfn.COVARIANCE.S($C$2:$C$121, C2:C121) -> 0.020572775 | Q4: =_xlfn.COVARIANCE.S($C$2:$C$121, D2:D121) -> 0.0073221432 | R4: =_xlfn.COVARIANCE.S($C$2:$C$121, E2:E121) -> 0.011831141
A5: 42401 | B5: =(MonthlyData!C9-MonthlyData!C8)/MonthlyData!C8 -> -0.10224949 | C5: =(MonthlyData!D9-MonthlyData!D8)/MonthlyData!D8 -> -0.012195122 | D5: =(MonthlyData!E9-MonthlyData!E8)/MonthlyData!E8 -> -0.045743092 | E5: =(MonthlyData!F9-MonthlyData!F8)/MonthlyData!F8 -> -0.095419847 | H5: Annual Variance | I5: =I3*12 -> 0.086109717 | J5: =J3*12 -> 0.24687331 | K5: =K3*12 -> 0.13288793 | L5: =L3*12 -> 0.57620691 | N5: META | O5: =_xlfn.COVARIANCE.S($D$2:$D$121, B2:B121) -> 0.0038231868 | P5: =_xlfn.COVARIANCE.S($D$2:$D$121, C2:C121) -> 0.0073221432 | Q5: =_xlfn.COVARIANCE.S($D$2:$D$121, D2:D121) -> 0.011073994 | R5: =_xlfn.COVARIANCE.S($D$2:$D$121, E2:E121) -> 0.0069604077
A6: 42430 | B6: =(MonthlyData!C10-MonthlyData!C9)/MonthlyData!C9 -> -0.084662111 | C6: =(MonthlyData!D10-MonthlyData!D9)/MonthlyData!D9 -> -0.098765432 | D6: =(MonthlyData!E10-MonthlyData!E9)/MonthlyData!E9 -> 0.12590491 | E6: =(MonthlyData!F10-MonthlyData!F9)/MonthlyData!F9 -> 0.32489451 | N6: SMCI | O6: =_xlfn.COVARIANCE.S($E$2:$E$121, B2:B121) -> 0.0029922135 | P6: =_xlfn.COVARIANCE.S($E$2:$E$121, C2:C121) -> 0.011831141 | Q6: =_xlfn.COVARIANCE.S($E$2:$E$121, D2:D121) -> 0.0069604077 | R6: =_xlfn.COVARIANCE.S($E$2:$E$121, E2:E121) -> 0.048017242
A7: 42461 | B7: =(MonthlyData!C11-MonthlyData!C10)/MonthlyData!C10 -> 0.042306097 | C7: =(MonthlyData!D11-MonthlyData!D10)/MonthlyData!D10 -> 0.12328767 | D7: =(MonthlyData!E11-MonthlyData!E10)/MonthlyData!E10 -> -0.045790251 | E7: =(MonthlyData!F11-MonthlyData!F10)/MonthlyData!F10 -> 0.057324841 | H7: Returns
A8: 42492 | B8: =(MonthlyData!C12-MonthlyData!C11)/MonthlyData!C11 -> 0.09430959 | C8: =(MonthlyData!D12-MonthlyData!D11)/MonthlyData!D11 -> 0.097560976 | D8: =(MonthlyData!E12-MonthlyData!E11)/MonthlyData!E11 -> 0.056820251 | E8: =(MonthlyData!F12-MonthlyData!F11)/MonthlyData!F11 -> 0.039156627 | H8: AAPL | I8: =I4 -> 0.25009364 | N8: Risk Free Rate | O8: 0.04
A9: 42522 | B9: =(MonthlyData!C13-MonthlyData!C12)/MonthlyData!C12 -> -0.14872727 | C9: =(MonthlyData!D13-MonthlyData!D12)/MonthlyData!D12 -> 0 | D9: =(MonthlyData!E13-MonthlyData!E12)/MonthlyData!E12 -> 0.021626745 | E9: =(MonthlyData!F13-MonthlyData!F12)/MonthlyData!F12 -> -0.2115942 | H9: NVDA | I9: =J4 -> 0.68158073 | N9: A (Risk Aversion) | O9: 18
A10: 42552 | B10: =(MonthlyData!C14-MonthlyData!C13)/MonthlyData!C13 -> 0.051687313 | C10: =(MonthlyData!D14-MonthlyData!D13)/MonthlyData!D13 -> 0.3 | D10: =(MonthlyData!E14-MonthlyData!E13)/MonthlyData!E13 -> 0.0017711057 | E10: =(MonthlyData!F14-MonthlyData!F13)/MonthlyData!F13 -> -0.029411765 | H10: META | I10: =K4 -> 0.26608038
A11: 42583 | B11: =(MonthlyData!C15-MonthlyData!C14)/MonthlyData!C14 -> -0.0264013 | C11: =(MonthlyData!D15-MonthlyData!D14)/MonthlyData!D14 -> 0 | D11: =(MonthlyData!E15-MonthlyData!E14)/MonthlyData!E14 -> -0.038642869 | E11: =(MonthlyData!F15-MonthlyData!F14)/MonthlyData!F14 -> -0.068181818 | H11: SMCI | I11: =L4 -> 0.50365741
A12: 42614 | B12: =(MonthlyData!C16-MonthlyData!C15)/MonthlyData!C15 -> 0.10596579 | C12: =(MonthlyData!D16-MonthlyData!D15)/MonthlyData!D15 -> 0.21367521 | D12: =(MonthlyData!E16-MonthlyData!E15)/MonthlyData!E15 -> 0.088624223 | E12: =(MonthlyData!F16-MonthlyData!F15)/MonthlyData!F15 -> -0.12195122
A13: 42646 | B13: =(MonthlyData!C17-MonthlyData!C16)/MonthlyData!C16 -> 0.0064126745 | C13: =(MonthlyData!D17-MonthlyData!D16)/MonthlyData!D16 -> 0.11267606 | D13: =(MonthlyData!E17-MonthlyData!E16)/MonthlyData!E16 -> 0.014962594 | E13: =(MonthlyData!F17-MonthlyData!F16)/MonthlyData!F16 -> 0.023148148 | H13: Equally Weighted Portfolios | K13: Optimal Risk Portfolio | O13: Correlation Matrix
A14: 42675 | B14: =(MonthlyData!C18-MonthlyData!C17)/MonthlyData!C17 -> 0.054347826 | C14: =(MonthlyData!D18-MonthlyData!D17)/MonthlyData!D17 -> 0.082278481 | D14: =(MonthlyData!E18-MonthlyData!E17)/MonthlyData!E17 -> 0.020607117 | E14: =(MonthlyData!F18-MonthlyData!F17)/MonthlyData!F17 -> 0.063348416 | O14: AAPL | P14: NVDA | Q14: META | R14: SMCI
A15: 42705 | B15: =(MonthlyData!C19-MonthlyData!C18)/MonthlyData!C18 -> -0.0092428013 | C15: =(MonthlyData!D19-MonthlyData!D18)/MonthlyData!D18 -> 0.011695906 | D15: =(MonthlyData!E19-MonthlyData!E18)/MonthlyData!E18 -> 0.0056690223 | E15: =(MonthlyData!F19-MonthlyData!F18)/MonthlyData!F18 -> -0.029787234 | H15: AAPL | I15: 0.25 | K15: AAPL | L15: 0 | N15: AAPL | O15: =CORREL($B$2:$B$121, B2:B121) -> 1 | P15: =CORREL($B$2:$B$121, C2:C121) -> 0.58492001 | Q15: =CORREL($B$2:$B$121, D2:D121) -> 0.42888209 | R15: =CORREL($B$2:$B$121, E2:E121) -> 0.16119758
A16: 42738 | B16: =(MonthlyData!C20-MonthlyData!C19)/MonthlyData!C19 -> -0.017940438 | C16: =(MonthlyData!D20-MonthlyData!D19)/MonthlyData!D19 -> 0.26589595 | D16: =(MonthlyData!E20-MonthlyData!E19)/MonthlyData!E19 -> -0.11119691 | E16: =(MonthlyData!F20-MonthlyData!F19)/MonthlyData!F19 -> 0.14912281 | H16: NVDA | I16: 0.25 | K16: NVDA | L16: 0.92856149 | N16: NVDA | O16: =CORREL($C$2:$C$121, B2:B121) -> 0.58492001 | P16: =CORREL($C$2:$C$121, C2:C121) -> 1 | Q16: =CORREL($C$2:$C$121, D2:D121) -> 0.48510933 | R16: =CORREL($C$2:$C$121, E2:E121) -> 0.37642771
A17: 42767 | B17: =(MonthlyData!C21-MonthlyData!C20)/MonthlyData!C20 -> 0.061015711 | C17: =(MonthlyData!D21-MonthlyData!D20)/MonthlyData!D20 -> 0.16438356 | D17: =(MonthlyData!E21-MonthlyData!E20)/MonthlyData!E20 -> 0.015291051 | E17: =(MonthlyData!F21-MonthlyData!F20)/MonthlyData!F20 -> 0.08778626 | H17: META | I17: 0.25 | K17: META | L17: 0 | N17: META | O17: =CORREL($D$2:$D$121, B2:B121) -> 0.42888209 | P17: =CORREL($D$2:$D$121, C2:C121) -> 0.48510933 | Q17: =CORREL($D$2:$D$121, D2:D121) -> 1 | R17: =CORREL($D$2:$D$121, E2:E121) -> 0.30184496
A18: 42795 | B18: =(MonthlyData!C22-MonthlyData!C21)/MonthlyData!C21 -> 0.10847107 | C18: =(MonthlyData!D22-MonthlyData!D21)/MonthlyData!D21 -> 0.11764706 | D18: =(MonthlyData!E22-MonthlyData!E21)/MonthlyData!E21 -> 0.14008215 | E18: =(MonthlyData!F22-MonthlyData!F21)/MonthlyData!F21 -> -0.10175439 | H18: SMCI | I18: 0.25 | K18: SMCI | L18: 0.071438511 | N18: SMCI | O18: =CORREL($E$2:$E$121, B2:B121) -> 0.16119758 | P18: =CORREL($E$2:$E$121, C2:C121) -> 0.37642771 | Q18: =CORREL($E$2:$E$121, D2:D121) -> 0.30184496 | R18: =CORREL($E$2:$E$121, E2:E121) -> 1
A19: 42828 | B19: =(MonthlyData!C23-MonthlyData!C22)/MonthlyData!C22 -> 0.085740913 | C19: =(MonthlyData!D23-MonthlyData!D22)/MonthlyData!D22 -> -0.098245614 | D19: =(MonthlyData!E23-MonthlyData!E22)/MonthlyData!E22 -> 0.031449373 | E19: =(MonthlyData!F23-MonthlyData!F22)/MonthlyData!F22 -> 0.0390625 | H19: Sum | I19: =SUM(I15:I18) -> 1 | K19: Sum | L19: =SUM(L15:L18) -> 1
A20: 42856 | B20: =(MonthlyData!C24-MonthlyData!C23)/MonthlyData!C23 -> 0.028040057 | C20: =(MonthlyData!D24-MonthlyData!D23)/MonthlyData!D23 -> 0.054474708 | D20: =(MonthlyData!E24-MonthlyData!E23)/MonthlyData!E23 -> 0.035366031 | E20: =(MonthlyData!F24-MonthlyData!F23)/MonthlyData!F23 -> -0.056390977
A21: 42887 | B21: =(MonthlyData!C25-MonthlyData!C24)/MonthlyData!C24 -> 0.020038965 | C21: =(MonthlyData!D25-MonthlyData!D24)/MonthlyData!D24 -> -0.014760148 | D21: =(MonthlyData!E25-MonthlyData!E24)/MonthlyData!E24 -> 0.071549058 | E21: =(MonthlyData!F25-MonthlyData!F24)/MonthlyData!F24 -> -0.023904382 | H21: Exp Return (ER) | I21: {=MMULT(TRANSPOSE(I15:I18), I8:I11)} -> 0.42535304 | K21: ER | L21: {=MMULT(TRANSPOSE(L15:L18),I8:I11)} -> 0.66887015
A22: 42919 | B22: =(MonthlyData!C26-MonthlyData!C25)/MonthlyData!C25 -> 0.045020464 | C22: =(MonthlyData!D26-MonthlyData!D25)/MonthlyData!D25 -> 0.35205993 | D22: =(MonthlyData!E26-MonthlyData!E25)/MonthlyData!E25 -> -0.0060999606 | E22: =(MonthlyData!F26-MonthlyData!F25)/MonthlyData!F25 -> 0.0081632653 | H22: Standard Deviation (Std) | I22: {=SQRT(MMULT(MMULT(TRANSPOSE(I15:I18),O3:R6),I15:I18))} -> 0.10213709 | K22: SD | L22: {=SQRT(MMULT(MMULT(TRANSPOSE(L15:L18), O3:R6), L15:L18))} -> 0.13983234
A23: 42948 | B23: =(MonthlyData!C27-MonthlyData!C26)/MonthlyData!C26 -> -0.063185379 | C23: =(MonthlyData!D27-MonthlyData!D26)/MonthlyData!D26 -> -0.03601108 | D23: =(MonthlyData!E27-MonthlyData!E26)/MonthlyData!E26 -> -0.020457995 | E23: =(MonthlyData!F27-MonthlyData!F26)/MonthlyData!F26 -> -0.008097166 | K23: Sharpe Ratio | L23: =(L21 - O8)/L22 -> 4.4973155
A24: 42979 | B24: =(MonthlyData!C28-MonthlyData!C27)/MonthlyData!C27 -> 0.045429208 | C24: =(MonthlyData!D28-MonthlyData!D27)/MonthlyData!D27 -> 0.18103448 | D24: =(MonthlyData!E28-MonthlyData!E27)/MonthlyData!E27 -> 0.14437782 | E24: =(MonthlyData!F28-MonthlyData!F27)/MonthlyData!F27 -> 0.10612245
A25: 43010 | B25: =(MonthlyData!C29-MonthlyData!C28)/MonthlyData!C28 -> 0.093308451 | C25: =(MonthlyData!D29-MonthlyData!D28)/MonthlyData!D28 -> 0.03649635 | D25: =(MonthlyData!E29-MonthlyData!E28)/MonthlyData!E28 -> 0.012716355 | E25: =(MonthlyData!F29-MonthlyData!F28)/MonthlyData!F28 -> -0.011070111
A26: 43040 | B26: =(MonthlyData!C30-MonthlyData!C29)/MonthlyData!C29 -> -0.062423799 | C26: =(MonthlyData!D30-MonthlyData!D29)/MonthlyData!D29 -> 0.051643192 | D26: =(MonthlyData!E30-MonthlyData!E29)/MonthlyData!E29 -> -0.014823858 | E26: =(MonthlyData!F30-MonthlyData!F29)/MonthlyData!F29 -> -0.13059701 | H26: y* - How much should be held in risky portfolio | I26: =(L21-O8)/(O9*L22) -> 0.24985086 | K26: Weight in RF
A27: 43070 | B27: =(MonthlyData!C31-MonthlyData!C30)/MonthlyData!C30 -> 0.085045514 | C27: =(MonthlyData!D31-MonthlyData!D30)/MonthlyData!D30 -> 0.15625 | D27: =(MonthlyData!E31-MonthlyData!E30)/MonthlyData!E30 -> 0.077830885 | E27: =(MonthlyData!F31-MonthlyData!F30)/MonthlyData!F30 -> -0.12875536 | L27: =I33 -> 0.069916171 | M27: =I32 -> 0.35443508
A28: 43102 | B28: =(MonthlyData!C32-MonthlyData!C31)/MonthlyData!C31 -> 0.024928092 | C28: =(MonthlyData!D32-MonthlyData!D31)/MonthlyData!D31 -> -0.046332046 | D28: =(MonthlyData!E32-MonthlyData!E31)/MonthlyData!E31 -> -0.041388372 | E28: =(MonthlyData!F32-MonthlyData!F31)/MonthlyData!F31 -> 0.083743842 | K28: 1 | L28: 0 | M28: 0.04
A29: 43132 | B29: =(MonthlyData!C33-MonthlyData!C32)/MonthlyData!C32 -> 0.0072497661 | C29: =(MonthlyData!D33-MonthlyData!D32)/MonthlyData!D32 -> 0.008097166 | D29: =(MonthlyData!E33-MonthlyData!E32)/MonthlyData!E32 -> 0.036093661 | E29: =(MonthlyData!F33-MonthlyData!F32)/MonthlyData!F32 -> -0.022727273 | H29: Combination of Tangent Portfolio and RF | K29: 0.9 | L29: 0.013983234 | M29: 0.10288702
A30: 43160 | B30: =(MonthlyData!C34-MonthlyData!C33)/MonthlyData!C33 -> -0.026004179 | C30: =(MonthlyData!D34-MonthlyData!D33)/MonthlyData!D33 -> 0.20682731 | D30: =(MonthlyData!E34-MonthlyData!E33)/MonthlyData!E33 -> 0.064325874 | E30: =(MonthlyData!F34-MonthlyData!F33)/MonthlyData!F33 -> 0.051162791 | K30: 0.8 | L30: 0.027966468 | M30: 0.16577403
A31: 43192 | B31: =(MonthlyData!C35-MonthlyData!C34)/MonthlyData!C34 -> 0.042908224 | C31: =(MonthlyData!D35-MonthlyData!D34)/MonthlyData!D34 -> -0.03327787 | D31: =(MonthlyData!E35-MonthlyData!E34)/MonthlyData!E34 -> -0.088818686 | E31: =(MonthlyData!F35-MonthlyData!F34)/MonthlyData!F34 -> -0.19911504 | H31: Weight in RF | I31: =K33 -> 0.5 | K31: 0.7 | L31: 0.041949702 | M31: 0.22866105
A32: 43221 | B32: =(MonthlyData!C36-MonthlyData!C35)/MonthlyData!C35 -> -0.047542857 | C32: =(MonthlyData!D36-MonthlyData!D35)/MonthlyData!D35 -> -0.048192771 | D32: =(MonthlyData!E36-MonthlyData!E35)/MonthlyData!E35 -> -0.11680118 | E32: =(MonthlyData!F36-MonthlyData!F35)/MonthlyData!F35 -> -0.093922652 | H32: Mean | I32: =I31*O8+(1-I31)*L21 -> 0.35443508 | K32: 0.6 | L32: 0.055932937 | M32: 0.29154806
A33: 43252 | B33: =(MonthlyData!C37-MonthlyData!C36)/MonthlyData!C36 -> 0.014638829 | C33: =(MonthlyData!D37-MonthlyData!D36)/MonthlyData!D36 -> 0.027124774 | D33: =(MonthlyData!E37-MonthlyData!E36)/MonthlyData!E36 -> 0.11886222 | E33: =(MonthlyData!F37-MonthlyData!F36)/MonthlyData!F36 -> 0.11585366 | H33: SD | I33: =(1-I31)*L22 -> 0.069916171 | K33: 0.5 | L33: 0.069916171 | M33: 0.35443508
A34: 43283 | B34: =(MonthlyData!C38-MonthlyData!C37)/MonthlyData!C37 -> 0.12488174 | C34: =(MonthlyData!D38-MonthlyData!D37)/MonthlyData!D37 -> 0.13380282 | D34: =(MonthlyData!E38-MonthlyData!E37)/MonthlyData!E37 -> 0.11578281 | E34: =(MonthlyData!F38-MonthlyData!F37)/MonthlyData!F37 -> 0.33333333 | K34: 0.4 | L34: 0.083899405 | M34: 0.41732209
A35: 43313 | B35: =(MonthlyData!C39-MonthlyData!C38)/MonthlyData!C38 -> -0.015979815 | C35: =(MonthlyData!D39-MonthlyData!D38)/MonthlyData!D38 -> -0.059006211 | D35: =(MonthlyData!E39-MonthlyData!E38)/MonthlyData!E38 -> 0.017372029 | E35: =(MonthlyData!F39-MonthlyData!F38)/MonthlyData!F38 -> 0.0081967213 | K35: 0.3 | L35: 0.097882639 | M35: 0.48020911
A36: 43347 | B36: =(MonthlyData!C40-MonthlyData!C39)/MonthlyData!C39 -> 0.076495726 | C36: =(MonthlyData!D40-MonthlyData!D39)/MonthlyData!D39 -> 0.01650165 | D36: =(MonthlyData!E40-MonthlyData!E39)/MonthlyData!E39 -> -0.13026956 | E36: =(MonthlyData!F40-MonthlyData!F39)/MonthlyData!F39 -> -0.11788618 | K36: 0.2 | L36: 0.11186587 | M36: 0.54309612
A37: 43374 | B37: =(MonthlyData!C41-MonthlyData!C40)/MonthlyData!C40 -> 0.13318777 | C37: =(MonthlyData!D41-MonthlyData!D40)/MonthlyData!D40 -> 0.15097403 | D37: =(MonthlyData!E41-MonthlyData!E40)/MonthlyData!E40 -> -0.0028546461 | E37: =(MonthlyData!F41-MonthlyData!F40)/MonthlyData!F40 -> -0.055299539 | K37: 0.1 | L37: 0.12584911 | M37: 0.60598314
A38: 43405 | B38: =(MonthlyData!C42-MonthlyData!C41)/MonthlyData!C41 -> -0.0047293747 | C38: =(MonthlyData!D42-MonthlyData!D41)/MonthlyData!D41 -> 0.019746121 | D38: =(MonthlyData!E42-MonthlyData!E41)/MonthlyData!E41 -> -0.050946483 | E38: =(MonthlyData!F42-MonthlyData!F41)/MonthlyData!F41 -> 0.048780488 | K38: 0 | L38: 0.13983234 | M38: 0.66887015
A39: 43437 | B39: =(MonthlyData!C43-MonthlyData!C42)/MonthlyData!C42 -> -0.02217529 | C39: =(MonthlyData!D43-MonthlyData!D42)/MonthlyData!D42 -> -0.2461964 | D39: =(MonthlyData!E43-MonthlyData!E42)/MonthlyData!E42 -> -0.065808914 | E39: =(MonthlyData!F43-MonthlyData!F42)/MonthlyData!F42 -> -0.35813953 | K39: -0.1 | L39: 0.15381558 | M39: 0.73175717
A40: 43467 | B40: =(MonthlyData!C44-MonthlyData!C43)/MonthlyData!C43 -> -0.16828654 | C40: =(MonthlyData!D44-MonthlyData!D43)/MonthlyData!D43 -> -0.22018349 | D40: =(MonthlyData!E44-MonthlyData!E43)/MonthlyData!E43 -> -0.070247117 | E40: =(MonthlyData!F44-MonthlyData!F43)/MonthlyData!F43 -> 0.086956522 | K40: -0.2 | L40: 0.16779881 | M40: 0.79464418
...
