Workbook
Name n: Matrixes!$C$4
Name stddev: Matrixes!$C$5:$O$5
Name var: Matrixes!$C$11:$O$23
Name X: Data!$AB$7:$AN$69

Sheet Data
A1: Start Date | B1: =TODAY()- 91 -> 45923
A2: End Date | B2: =TODAY()-1 -> 46013
A4: Daily Close | B4: NVDA | C4: SOFI | D4: GME | E4: GOOGL | F4: MSFT | G4: AMZN | H4: AAPL | I4: SWPPX | J4: RXRX | K4: FUBO | L4: BBAI | M4: RCAT | N4: QUBT | O4: Returns | AB4: Excess Returns
A5: Date | B5: Close | C5: Close | D5: Close | E5: Close | F5: Close | G5: Close | H5: Close | I5: Close | J5: Close | K5: Close | L5: Close | M5: Close | N5: Close | O5: NVDA | P5: SOFI | Q5: GME | R5: GOOGL | S5: MSFT | T5: AMZN | U5: AAPL | V5: SWPPX | W5: RXRX | X5: FUBO | Y5: BBAI | Z5: RCAT | AA5: QUBT | AB5: NVDA | AC5: SOFI | AD5: GME | AE5: GOOGL | AF5: MSFT | AG5: AMZN | AH5: AAPL | AI5: SWPPX | AJ5: RXRX | AK5: FUBO | AL5: BBAI | AM5: RCAT | AN5: QUBT
A6: 45923 | B6: $ 178.43 | C6: $ 29.09 | D6: $ 26.80 | E6: $ 251.66 | F6: $ 509.23 | G6: $ 220.71 | H6: $ 254.43 | I6: $ 17.19 | J6: $ 4.81 | K6: $ 4.45 | L6: $ 7.99 | M6: $ 11.77 | N6: $ 21.41 | O6: -- | P6: -- | Q6: -- | R6: -- | S6: -- | T6: -- | U6: -- | V6: -- | W6: -- | X6: -- | Y6: -- | Z6: -- | AA6: --
A7: 45924 | B7: $ 176.97 | C7: $ 28.44 | D7: $ 26.25 | E7: $ 247.14 | F7: $ 510.15 | G7: $ 220.21 | H7: $ 252.31 | I7: $ 17.14 | J7: $ 4.88 | K7: $ 4.15 | L7: $ 7.59 | M7: $ 10.38 | N7: $ 21.41 | O7: -0.0082 | P7: -0.0223 | Q7: -0.0205 | R7: -0.018 | S7: 0.0018 | T7: -0.0023 | U7: -0.0083 | V7: -0.0029 | W7: 0.0146 | X7: -0.0674 | Y7: -0.0501 | Z7: -0.1181 | AA7: 0.0002 | AB7: -0.0089 | AC7: -0.0223 | AD7: -0.0175 | AE7: -0.0214 | AF7: 0.0025 | AG7: -0.003 | AH7: -0.0094 | AI7: -0.0033 | AJ7: 0.0144 | AK7: -0.0598 | AL7: -0.0487 | AM7: -0.1167 | AN7: 0.0065
A8: 45925 | B8: $ 177.69 | C8: $ 28.12 | D8: $ 25.27 | E8: $ 245.79 | F8: $ 507.03 | G8: $ 218.15 | H8: $ 256.87 | I8: $ 17.05 | J8: $ 4.63 | K8: $ 4.09 | L8: $ 7.14 | M8: $ 10.17 | N8: $ 20.58 | O8: 0.0041 | P8: -0.0113 | Q8: -0.0373 | R8: -0.0055 | S8: -0.0061 | T8: -0.0094 | U8: 0.0181 | V8: -0.0053 | W8: -0.0512 | X8: -0.0145 | Y8: -0.0593 | Z8: -0.0202 | AA8: -0.0388 | AB8: 0.0033 | AC8: -0.0112 | AD8: -0.0343 | AE8: -0.0089 | AF8: -0.0054 | AG8: -0.0101 | AH8: 0.017 | AI8: -0.0057 | AJ8: -0.0514 | AK8: -0.0069 | AL8: -0.0579 | AM8: -0.0188 | AN8: -0.0325
A9: 45926 | B9: $ 178.19 | C9: $ 27.98 | D9: $ 26.42 | E9: $ 246.54 | F9: $ 511.46 | G9: $ 219.78 | H9: $ 255.46 | I9: $ 17.16 | J9: $ 4.72 | K9: $ 4.20 | L9: $ 6.73 | M9: $ 10.14 | N9: $ 20.15 | O9: 0.0028 | P9: -0.005 | Q9: 0.0455 | R9: 0.0031 | S9: 0.0087 | T9: 0.0075 | U9: -0.0055 | V9: 0.0065 | W9: 0.0194 | X9: 0.0269 | Y9: -0.0574 | Z9: -0.0029 | AA9: -0.0211 | AB9: 0.0021 | AC9: -0.0049 | AD9: 0.0486 | AE9: -0.0004 | AF9: 0.0094 | AG9: 0.0067 | AH9: -0.0066 | AI9: 0.006 | AJ9: 0.0192 | AK9: 0.0345 | AL9: -0.0561 | AM9: -0.0016 | AN9: -0.0149
A10: 45929 | B10: $ 181.85 | C10: $ 27.55 | D10: $ 27.21 | E10: $ 244.05 | F10: $ 514.60 | G10: $ 222.17 | H10: $ 254.43 | I10: $ 17.20 | J10: $ 4.91 | K10: $ 4.27 | L10: $ 6.46 | M10: $ 10.16 | N10: $ 18.85 | O10: 0.0205 | P10: -0.0154 | Q10: 0.0299 | R10: -0.0101 | S10: 0.0061 | T10: 0.0109 | U10: -0.004 | V10: 0.0023 | W10: 0.0403 | X10: 0.0167 | Y10: -0.0401 | Z10: 0.002 | AA10: -0.0643 | AB10: 0.0198 | AC10: -0.0153 | AD10: 0.033 | AE10: -0.0136 | AF10: 0.0068 | AG10: 0.0101 | AH10: -0.0051 | AI10: 0.0019 | AJ10: 0.0401 | AK10: 0.0243 | AL10: -0.0387 | AM10: 0.0034 | AN10: -0.0581
A11: 45930 | B11: $ 186.58 | C11: $ 26.42 | D11: $ 27.28 | E11: $ 243.10 | F11: $ 517.95 | G11: $ 219.57 | H11: $ 254.63 | I11: $ 17.27 | J11: $ 4.88 | K11: $ 4.15 | L11: $ 6.52 | M11: $ 10.35 | N11: $ 18.41 | O11: 0.026 | P11: -0.041 | Q11: 0.0026 | R11: -0.0039 | S11: 0.0065 | T11: -0.0117 | U11: 0.0008 | V11: 0.0041 | W11: -0.0061 | X11: -0.0281 | Y11: 0.0093 | Z11: 0.0187 | AA11: -0.0233 | AB11: 0.0253 | AC11: -0.0409 | AD11: 0.0056 | AE11: -0.0074 | AF11: 0.0072 | AG11: -0.0125 | AH11: -0.0003 | AI11: 0.0036 | AJ11: -0.0063 | AK11: -0.0205 | AL11: 0.0107 | AM11: 0.0201 | AN11: -0.0171
A12: 45931 | B12: $ 187.24 | C12: $ 25.76 | D12: $ 27.69 | E12: $ 244.90 | F12: $ 519.71 | G12: $ 220.63 | H12: $ 255.45 | I12: $ 17.33 | J12: $ 5.10 | K12: $ 3.90 | L12: $ 6.98 | M12: $ 10.47 | N12: $ 18.97 | O12: 0.0035 | P12: -0.025 | Q12: 0.015 | R12: 0.0074 | S12: 0.0034 | T12: 0.0048 | U12: 0.0032 | V12: 0.0035 | W12: 0.0451 | X12: -0.0602 | Y12: 0.0706 | Z12: 0.0116 | AA12: 0.0304 | AB12: 0.0028 | AC12: -0.0249 | AD12: 0.0181 | AE12: 0.0039 | AF12: 0.0041 | AG12: 0.0041 | AH12: 0.0022 | AI12: 0.003 | AJ12: 0.0449 | AK12: -0.0527 | AL12: 0.0719 | AM12: 0.013 | AN12: 0.0367
A13: 45932 | B13: $ 188.89 | C13: $ 25.97 | D13: $ 27.22 | E13: $ 245.69 | F13: $ 515.74 | G13: $ 222.41 | H13: $ 257.13 | I13: $ 17.34 | J13: $ 5.52 | K13: $ 3.95 | L13: $ 7.27 | M13: $ 11.52 | N13: $ 19.98 | O13: 0.0088 | P13: 0.0082 | Q13: -0.017 | R13: 0.0032 | S13: -0.0076 | T13: 0.0081 | U13: 0.0066 | V13: 0.0006 | W13: 0.0824 | X13: 0.0128 | Y13: 0.0415 | Z13: 0.1003 | AA13: 0.0532 | AB13: 0.0081 | AC13: 0.0082 | AD13: -0.0139 | AE13: -0.0003 | AF13: -0.0069 | AG13: 0.0073 | AH13: 0.0055 | AI13: 0.0002 | AJ13: 0.0822 | AK13: 0.0204 | AL13: 0.0429 | AM13: 0.1017 | AN13: 0.0595
A14: 45933 | B14: $ 187.62 | C14: $ 25.24 | D14: $ 25.38 | E14: $ 245.35 | F14: $ 517.35 | G14: $ 219.51 | H14: $ 258.02 | I14: $ 17.35 | J14: $ 5.49 | K14: $ 3.96 | L14: $ 7.19 | M14: $ 12.89 | N14: $ 24.62 | O14: -0.0067 | P14: -0.0281 | Q14: -0.0676 | R14: -0.0014 | S14: 0.0031 | T14: -0.013 | U14: 0.0035 | V14: 0.0006 | W14: -0.0054 | X14: 0.0025 | Y14: -0.011 | Z14: 0.1189 | AA14: 0.2322 | AB14: -0.0074 | AC14: -0.028 | AD14: -0.0645 | AE14: -0.0049 | AF14: 0.0038 | AG14: -0.0138 | AH14: 0.0024 | AI14: 0.0001 | AJ14: -0.0056 | AK14: 0.0101 | AL14: -0.0096 | AM14: 0.1203 | AN14: 0.2385
A15: 45936 | B15: $ 185.54 | C15: $ 26.36 | D15: $ 25.05 | E15: $ 250.43 | F15: $ 528.57 | G15: $ 220.90 | H15: $ 256.69 | I15: $ 17.41 | J15: $ 5.53 | K15: $ 3.92 | L15: $ 7.69 | M15: $ 14.58 | N15: $ 22.16 | O15: -0.0111 | P15: 0.0444 | Q15: -0.013 | R15: 0.0207 | S15: 0.0217 | T15: 0.0063 | U15: -0.0052 | V15: 0.0035 | W15: 0.0073 | X15: -0.0101 | Y15: 0.0695 | Z15: 0.1311 | AA15: -0.0999 | AB15: -0.0118 | AC15: 0.0444 | AD15: -0.0099 | AE15: 0.0172 | AF15: 0.0224 | AG15: 0.0056 | AH15: -0.0062 | AI15: 0.003 | AJ15: 0.0071 | AK15: -0.0025 | AL15: 0.0709 | AM15: 0.1325 | AN15: -0.0937
A16: 45937 | B16: $ 185.04 | C16: $ 28.14 | D16: $ 24.35 | E16: $ 245.76 | F16: $ 523.98 | G16: $ 221.78 | H16: $ 256.48 | I16: $ 17.35 | J16: $ 5.23 | K16: $ 3.87 | L16: $ 7.44 | M16: $ 14.79 | N16: $ 22.01 | O16: -0.0027 | P16: 0.0675 | Q16: -0.0279 | R16: -0.0186 | S16: -0.0087 | T16: 0.004 | U16: -0.0008 | V16: -0.0034 | W16: -0.0542 | X16: -0.0128 | Y16: -0.0325 | Z16: 0.0144 | AA16: -0.0068 | AB16: -0.0034 | AC16: 0.0676 | AD16: -0.0249 | AE16: -0.0221 | AF16: -0.008 | AG16: 0.0032 | AH16: -0.0019 | AI16: -0.0039 | AJ16: -0.0545 | AK16: -0.0052 | AL16: -0.0311 | AM16: 0.0158 | AN16: -0.0005
A17: 45938 | B17: $ 189.11 | C17: $ 28.02 | D17: $ 24.41 | E17: $ 244.62 | F17: $ 524.85 | G17: $ 225.22 | H17: $ 258.06 | I17: $ 17.45 | J17: $ 6.09 | K17: $ 3.88 | L17: $ 7.29 | M17: $ 14.35 | N17: $ 20.82 | O17: 0.022 | P17: -0.0043 | Q17: 0.0025 | R17: -0.0046 | S17: 0.0017 | T17: 0.0155 | U17: 0.0062 | V17: 0.0058 | W17: 0.1644 | X17: 0.0026 | Y17: -0.0202 | Z17: -0.0297 | AA17: -0.0541 | AB17: 0.0213 | AC17: -0.0042 | AD17: 0.0055 | AE17: -0.0081 | AF17: 0.0024 | AG17: 0.0148 | AH17: 0.0051 | AI17: 0.0053 | AJ17: 0.1642 | AK17: 0.0102 | AL17: -0.0188 | AM17: -0.0284 | AN17: -0.0478
A18: 45939 | B18: $ 192.57 | C18: $ 28.45 | D18: $ 24.07 | E18: $ 241.53 | F18: $ 522.40 | G18: $ 227.74 | H18: $ 254.04 | I18: $ 17.40 | J18: $ 5.91 | K18: $ 3.83 | L18: $ 7.49 | M18: $ 14.66 | N18: $ 21.32 | O18: 0.0183 | P18: 0.0153 | Q18: -0.0139 | R18: -0.0126 | S18: -0.0047 | T18: 0.0112 | U18: -0.0156 | V18: -0.0029 | W18: -0.0296 | X18: -0.0129 | Y18: 0.0274 | Z18: 0.0216 | AA18: 0.024 | AB18: 0.0176 | AC18: 0.0154 | AD18: -0.0109 | AE18: -0.0161 | AF18: -0.004 | AG18: 0.0104 | AH18: -0.0166 | AI18: -0.0033 | AJ18: -0.0298 | AK18: -0.0053 | AL18: 0.0288 | AM18: 0.023 | AN18: 0.0302
... A69: 46013 | B69: $ 183.69 | C69: $ 27.35 | D69: $ 21.74 | E69: $ 309.78 | F69: $ 484.92 | G69: $ 228.43 | H69: $ 270.97 | I69: $ 17.62 | J69: $ 4.40 | K69: $ 2.65 | L69: $ 6.39 | M69: $ 9.22 | N69: $ 12.29 | O69: 0.0149 | P69: 0.004 | Q69: -0.0342 | R69: 0.0085 | S69: -0.0021 | T69: 0.0048 | U69: -0.0099 | V69: 0.0069 | W69: 0.0329 | X69: -0.0221 | Y69: 0.0208 | Z69: 0.1453 | AA69: 0.1286 | AB69: 0.0142 | AC69: 0.0041 | AD69: -0.0311 | AE69: 0.005 | AF69: -0.0014 | AG69: 0.004 | AH69: -0.0109 | AI69: 0.0064 | AJ69: 0.0327 | AK69: -0.0146 | AL69: 0.0221 | AM69: 0.1467 | AN69: 0.1348

Sheet Matrixes
C2: NVDA | D2: SOFI | E2: GME | F2: GOOGL | G2: MSFT | H2: AMZN | I2: AAPL | J2: SWPPX | K2: RXRX | L2: FUBO | M2: BBAI | N2: RCAT | O2: QUBT | AK2: σp | AL2: E(rp)
B3: Expected Returns <== E(r) | C3: =AVERAGE(Data!O7:O69) -> 0.00072539683 | D3: =AVERAGE(Data!P7:P69) -> -8.2539683e-05 | E3: =AVERAGE(Data!Q7:Q69) -> -0.0030650794 | F3: =AVERAGE(Data!R7:R69) -> 0.0034746032 | G3: =AVERAGE(Data!S7:S69) -> -0.00070634921 | H3: =AVERAGE(Data!T7:T69) -> 0.00074603175 | I3: =AVERAGE(Data!U7:U69) -> 0.0010619048 | J3: =AVERAGE(Data!V7:V69) -> 0.00042857143 | ... O3: =AVERAGE(Data!AA7:AA69) -> -0.0062365079 | R3: Equally Weighted | S3: NVDA | T3: SOFI | U3: GME | V3: GOOGL | W3: MSFT | X3: AMZN | Y3: AAPL | Z3: SWPPX | AA3: RXRX | AB3: FUBO | AC3: BBAI | AD3: RCAT | AE3: QUBT | AJ3: Trials | AK3: =S44 -> 0.026362218 | AL3: =S43 -> -0.0010649805
B4: n | C4: =COUNT(Data!O7:O69) -> 63 | D4: =COUNT(Data!P7:P69) -> 63 | E4: =COUNT(Data!Q7:Q69) -> 63 | F4: =COUNT(Data!R7:R69) -> 63 | G4: =COUNT(Data!S7:S69) -> 63 | H4: =COUNT(Data!T7:T69) -> 63 | I4: =COUNT(Data!U7:U69) -> 63 | J4: =COUNT(Data!V7:V69) -> 63 | ... O4: =COUNT(Data!AA7:AA69) -> 63 | R4: Weights | S4: =1/13 -> 0.076923077 | T4: =1/13 -> 0.076923077 | U4: =1/13 -> 0.076923077 | V4: =1/13 -> 0.076923077 | W4: =1/13 -> 0.076923077 | X4: =1/13 -> 0.076923077 | Y4: =1/13 -> 0.076923077 | Z4: =1/13 -> 0.076923077 | ... AE4: =1/13 -> 0.076923077 | AF4: =SUM(S4:AE4) -> 1 | AJ4: 1 | AK4: 0.026771321 | AL4: -0.00038373353
B5: Stddev <== σ | C5: =_xlfn.STDEV.S(Data!O7:O69) -> 0.023159593 | D5: =_xlfn.STDEV.S(Data!P7:P69) -> 0.042569645 | E5: =_xlfn.STDEV.S(Data!Q7:Q69) -> 0.022566834 | F5: =_xlfn.STDEV.S(Data!R7:R69) -> 0.019145091 | G5: =_xlfn.STDEV.S(Data!S7:S69) -> 0.012068165 | H5: =_xlfn.STDEV.S(Data!T7:T69) -> 0.020795578 | I5: =_xlfn.STDEV.S(Data!U7:U69) -> 0.011299949 | J5: =_xlfn.STDEV.S(Data!V7:V69) -> 0.0083715037 | ... O5: =_xlfn.STDEV.S(Data!AA7:AA69) -> 0.072652987 | R5: E(rp) | S5: =SUMPRODUCT(S4:AE4, $C$3:$O$3) -> -0.0010611722 | T5: <-- Daily | U5: =(1+S5)^252-1 -> -0.23475357 | V5: <-- Annual | AJ5: 2 | AK5: 0.024830024 | AL5: -0.00091325487
B6: variance <== 𝜎^2 | C6: =C5^2 -> 0.00053636676 | D6: =D5^2 -> 0.0018121747 | E6: =E5^2 -> 0.00050926199 | F6: =F5^2 -> 0.00036653451 | G6: =G5^2 -> 0.0001456406 | H6: =H5^2 -> 0.00043245607 | I6: =I5^2 -> 0.00012768885 | J6: =J5^2 -> 7.0082074e-05 | ... O6: =O5^2 -> 0.0052784565 | R6: σp | S6: {=SQRT(MMULT(MMULT(S4:AE4, var), TRANSPOSE(S4:AE4)))} -> 0.023388776 | AJ6: 3 | AK6: 0.016505935 | AL6: -0.0004531896
B7: Modified sharpe <== E(r) /σ | C7: =C3/C5 -> 0.031321656 | D7: =D3/D5 -> -0.0019389328 | E7: =E3/E5 -> -0.1358223 | F7: =F3/F5 -> 0.18148794 | G7: =G3/G5 -> -0.05852996 | H7: =H3/H5 -> 0.035874537 | I7: =I3/I5 -> 0.093974297 | J7: =J3/J5 -> 0.05119408 | ... O7: =O3/O5 -> -0.085839663 | R7: E(rp)/σp | S7: =S5/S6 -> -0.045371 | AJ7: 4 | AK7: 0.019823172 | AL7: -0.00036293009
AJ8: 5 | AK8: 0.021801602 | AL8: -0.0011089697
R9: Risk Min optimized portfolio | S9: NVDA | T9: SOFI | U9: GME | V9: GOOGL | W9: MSFT | X9: AMZN | Y9: AAPL | Z9: SWPPX | AA9: RXRX | AB9: FUBO | AC9: BBAI | AD9: RCAT | AE9: QUBT | AJ9: 6 | AK9: 0.022885334 | AL9: -0.00066130619
B10: Var-Covar Matrix | C10: NVDA | D10: SOFI | E10: GME | F10: GOOGL | G10: MSFT | H10: AMZN | I10: AAPL | J10: SWPPX | K10: RXRX | L10: FUBO | M10: BBAI | N10: RCAT | O10: QUBT | R10: Weights | S10: 0 | T10: 0 | U10: 0 | V10: 0 | W10: 0.06115887 | X10: 0 | Y10: 0.067077105 | Z10: 0.87176404 | AA10: 0 | AB10: 0 | AC10: 0 | AD10: 0 | AE10: 0 | AF10: =SUM(S10:AE10) -> 1 | AJ10: 7 | AK10: 0.020601514 | AL10: -0.0015631469
B11: {=TRANSPOSE(C10:O10)} -> NVDA | C11: {=MMULT(TRANSPOSE(X),X)/(n-1)} -> 0.00053659613 | D11: 0.00046905968 | E11: 9.5025323e-05 | F11: 0.00015007742 | G11: 0.00013826613 | H11: 0.00020539065 | I11: 5.6055484e-05 | J11: 0.00012338081 | K11: 9.8070968e-05 | L11: 9.3791935e-05 | M11: 0.00040651597 | N11: 0.00055966339 | O11: 0.00041200774 | R11: E(rp) | S11: =SUMPRODUCT(S10:AE10, $C$3:$O$3) -> 0.00040164314 | T11: <-- Daily | U11: =(1+S11)^252-1 -> 0.106491 | V11: <-- Annual | AJ11: 8 | AK11: 0.020586911 | AL11: -0.0010476415
B12: SOFI | C12: 0.00046905968 | D12: 0.0018122381 | E12: 0.00020245145 | F12: 0.0003209829 | G12: 0.00023740306 | H12: 0.00051794 | I12: 0.00021018016 | J12: 0.00024804694 | K12: 0.00077211952 | L12: 0.0006008079 | M12: 0.0014745208 | N12: 0.0014862144 | O12: 0.00096263968 | R12: σp | S12: {=SQRT(MMULT(MMULT(S10:AE10, var), TRANSPOSE(S10:AE10)))} -> 0.0080953635 | AJ12: 9 | AK12: 0.025442773 | AL12: -0.0007279672
B13: GME | C13: 9.5025323e-05 | D13: 0.00020245145 | E13: 0.00050954742 | F13: 4.7456935e-05 | G13: 8.4893226e-05 | H13: 9.6973548e-05 | I13: 3.5194516e-05 | J13: 7.1053065e-05 | K13: 0.00050689113 | L13: 0.00019668371 | M13: 0.00021072952 | N13: 0.00010657952 | O13: -4.8414516e-05 | R13: E(rp)/σp | S13: =S11/S12 -> 0.049613972 | AJ13: 10 | AK13: 0.023218812 | AL13: -0.00047178003
B14: GOOGL | C14: 0.00015007742 | D14: 0.0003209829 | E14: 4.7456935e-05 | F14: 0.0003669 | G14: 1.5985806e-05 | H14: 0.00012026 | I14: 8.2175806e-05 | J14: 9.5572742e-05 | K14: 0.00029324113 | L14: 5.33e-05 | M14: 0.00048708855 | N14: 0.00047604968 | O14: 0.00045253742 | AJ14: 11 | AK14: 0.023445529 | AL14: -0.0008409224
B15: MSFT | C15: 0.00013826613 | D15: 0.00023740306 | E15: 8.4893226e-05 | F15: 1.5985806e-05 | G15: 0.00014570597 | H15: 7.0198387e-05 | I15: 2.2383226e-05 | J15: 5.1467097e-05 | K15: 0.00010466129 | L15: 5.2181774e-05 | M15: 0.00014255419 | N15: 0.0002131221 | O15: 7.6234355e-05 | R15: Target-Return, Minimum-Risk | S15: NVDA | T15: SOFI | U15: GME | V15: GOOGL | W15: MSFT | X15: AMZN | Y15: AAPL | Z15: SWPPX | AA15: RXRX | AB15: FUBO | AC15: BBAI | AD15: RCAT | AE15: QUBT | AJ15: 12 | AK15: 0.021967463 | AL15: -0.0019176101
B16: AMZN | C16: 0.00020539065 | D16: 0.00051794 | E16: 9.6973548e-05 | F16: 0.00012026 | G16: 7.0198387e-05 | H16: 0.00043326677 | I16: 7.0370968e-05 | J16: 0.00010878274 | K16: 0.00026990952 | L16: 0.00012249855 | M16: 0.00026258823 | N16: 0.0004908929 | O16: 0.00036199774 | R16: Weights | S16: 0 | T16: 0 | U16: 0 | V16: 0 | W16: 0.06115887 | X16: 0 | Y16: 0.067077105 | Z16: 0.87176404 | AA16: 0 | AB16: 0 | AC16: 0 | AD16: 0 | AE16: 0 | AF16: =SUM(S16:AE16) -> 1 | AJ16: 13 | AK16: 0.021740292 | AL16: -0.0010971154
B17: AAPL | C17: 5.6055484e-05 | D17: 0.00021018016 | E17: 3.5194516e-05 | F17: 8.2175806e-05 | G17: 2.2383226e-05 | H17: 7.0370968e-05 | I17: 0.00012764613 | J17: 4.8446129e-05 | K17: 0.00021008984 | L17: 7.4600323e-05 | M17: 0.00013066 | N17: 0.00013319258 | O17: 5.8914516e-05 | R17: E(rp) | S17: =SUMPRODUCT(S16:AE16, $C$3:$O$3) -> 0.00040164314 | T17: <-- Daily | U17: =(1+S17)^252-1 -> 0.106491 | V17: <-- Annual | AJ17: 14 | AK17: 0.023190758 | AL17: -0.0011320918
B18: SWPPX | C18: 0.00012338081 | D18: 0.00024804694 | E18: 7.1053065e-05 | F18: 9.5572742e-05 | G18: 5.1467097e-05 | H18: 0.00010878274 | I18: 4.8446129e-05 | J18: 6.9842097e-05 | K18: 0.00021385468 | L18: 8.5098548e-05 | M18: 0.00028489258 | N18: 0.00033889468 | O18: 0.00024736113 | R18: σp | S18: {=SQRT(MMULT(MMULT(S16:AE16, var), TRANSPOSE(S16:AE16)))} -> 0.0080953635 | AJ18: 15 | AK18: 0.02850357 | AL18: -0.00079251216
B19: RXRX | C19: 9.8070968e-05 | D19: 0.00077211952 | E19: 0.00050689113 | F19: 0.00029324113 | G19: 0.00010466129 | H19: 0.00026990952 | I19: 0.00021008984 | J19: 0.00021385468 | K19: 0.0033709923 | L19: 0.00036046032 | M19: 0.0012033797 | N19: 0.0015164313 | O19: 0.0010624258 | R19: E(rp)/σp | S19: =S17/S18 -> 0.049613972 | AJ19: 16 | AK19: 0.022424566 | AL19: -0.0012278623
B20: FUBO | C20: 9.3791935e-05 | D20: 0.0006008079 | E20: 0.00019668371 | F20: 5.33e-05 | G20: 5.2181774e-05 | H20: 0.00012249855 | I20: 7.4600323e-05 | J20: 8.5098548e-05 | K20: 0.00036046032 | L20: 0.0012337135 | M20: 0.0010599989 | N20: 0.0011130665 | O20: 0.00081550177 | AJ20: 17 | AK20: 0.024055164 | AL20: -0.00028209691
B21: BBAI | C21: 0.00040651597 | D21: 0.0014745208 | E21: 0.00021072952 | F21: 0.00048708855 | G21: 0.00014255419 | H21: 0.00026258823 | I21: 0.00013066 | J21: 0.00028489258 | K21: 0.0012033797 | L21: 0.0010599989 | M21: 0.0045995234 | N21: 0.0035343671 | O21: 0.0026392618 | R21: Target-Risk, Maximum-Return | S21: NVDA | T21: SOFI | U21: GME | V21: GOOGL | W21: MSFT | X21: AMZN | Y21: AAPL | Z21: SWPPX | AA21: RXRX | AB21: FUBO | AC21: BBAI | AD21: RCAT | AE21: QUBT | AJ21: 18 | AK21: 0.025081339 | AL21: -0.00050512311
B22: RCAT | C22: 0.00055966339 | D22: 0.0014862144 | E22: 0.00010657952 | F22: 0.00047604968 | G22: 0.0002131221 | H22: 0.0004908929 | I22: 0.00013319258 | J22: 0.00033889468 | K22: 0.0015164313 | L22: 0.0011130665 | M22: 0.0035343671 | N22: 0.0051211105 | O22: 0.0036456771 | R22: Weights | S22: 0 | T22: 0 | U22: 0 | V22: 0.99999998 | W22: 0 | X22: 0 | Y22: 0 | Z22: 0 | AA22: 0 | AB22: 0 | AC22: 0 | AD22: 0 | AE22: 0 | AF22: =SUM(S22:AE22) -> 0.99999998 | AJ22: 19 | AK22: 0.025276179 | AL22: -0.0013799662
B23: QUBT | C23: 0.00041200774 | D23: 0.00096263968 | E23: -4.8414516e-05 | F23: 0.00045253742 | G23: 7.6234355e-05 | H23: 0.00036199774 | I23: 5.8914516e-05 | J23: 0.00024736113 | K23: 0.0010624258 | L23: 0.00081550177 | M23: 0.0026392618 | N23: 0.0036456771 | O23: 0.0052792424 | R23: E(rp) | S23: =SUMPRODUCT(S22:AE22, $C$3:$O$3) -> 0.0034746031 | T23: <-- Daily | U23: =(1+S23)^252-1 -> 1.3966749 | V23: <-- Annual | AJ23: 20 | AK23: 0.025082028 | AL23: -0.0014300345
R24: σp | S24: {=SQRT(MMULT(MMULT(S22:AE22, var), TRANSPOSE(S22:AE22)))} -> 0.019154634 | AJ24: 21 | AK24: 0.025708102 | AL24: -0.0017396439
R25: E(rp)/σp | S25: =S23/S24 -> 0.18139752 | AJ25: 22 | AK25: 0.023417681 | AL25: -0.00099081306
B26: Correlation Matrix | C26: NVDA | D26: SOFI | E26: GME | F26: GOOGL | G26: MSFT | H26: AMZN | I26: AAPL | J26: SWPPX | K26: RXRX | L26: FUBO | M26: BBAI | N26: RCAT | O26: QUBT | AJ26: 23 | AK26: 0.022635924 | AL26: -0.00062880239
B27: {=TRANSPOSE(C26:O26)} -> NVDA | C27: {=SQRT(var/MMULT(TRANSPOSE(C5:O5), C5:O5))} -> 1.0002138 | D27: 0.6897609 | E27: 0.42640167 | F27: 0.58178631 | G27: 0.70335053 | H27: 0.65303937 | I27: 0.46281278 | J27: 0.79773124 | K27: 0.27007111 | L27: 0.33955211 | M27: 0.50873396 | N27: 0.58111053 | O27: 0.49483509 | R27: Maximized sharpe portfolio | S27: NVDA | T27: SOFI | U27: GME | V27: GOOGL | W27: MSFT | X27: AMZN | Y27: AAPL | Z27: SWPPX | AA27: RXRX | AB27: FUBO | AC27: BBAI | AD27: RCAT | AE27: QUBT | AJ27: 24 | AK27: 0.018338589 | AL27: -0.00020590559
B28: SOFI | C28: 0.6897609 | D28: 1.0000175 | E28: 0.45906599 | F28: 0.62757006 | G28: 0.67978649 | H28: 0.76489921 | I28: 0.66100935 | J28: 0.83428643 | K28: 0.55894054 | L28: 0.63387986 | M28: 0.71464906 | N28: 0.69847597 | O28: 0.55789841 | R28: Weights | S28: 0 | T28: 0 | U28: 0 | V28: 0.52838841 | W28: 0 | X28: 0 | Y28: 0.47161159 | Z28: 0 | AA28: 0 | AB28: 0 | AC28: 0 | AD28: 0 | AE28: 0 | AF28: =SUM(S28:AE28) -> 1 | AJ28: 25 | AK28: 0.019558925 | AL28: 1.7550069e-05
B29: GME | C29: 0.42640167 | D29: 0.45906599 | E29: 1.0002802 | F29: 0.33142542 | G29: 0.55831666 | H29: 0.45457529 | I29: 0.37150438 | J29: 0.61327372 | K29: 0.62200717 | L29: 0.49812465 | M29: 0.37106053 | N29: 0.25689894 | O29: #NUM! | R29: E(rp) | S29: =SUMPRODUCT(S28:AE28, $C$3:$O$3) -> 0.0023367466 | T29: <-- Daily | U29: =(1+S29)^252-1 -> 0.80069592 | V29: <-- Annual | AJ29: 26 | AK29: 0.02572674 | AL29: -0.00012360888
B30: GOOGL | C30: 0.58178631 | D30: 0.62757006 | E30: 0.33142542 | F30: 1.0004985 | G30: 0.26303767 | H30: 0.54959957 | I30: 0.61631825 | J30: 0.77221204 | K30: 0.51363793 | L30: 0.28152959 | M30: 0.61248102 | N30: 0.58946521 | O30: 0.57038986 | R30: σp | S30: {=SQRT(MMULT(MMULT(S28:AE28, var), TRANSPOSE(S28:AE28)))} -> 0.013106585 | AJ30: 27 | AK30: 0.029919529 | AL30: -0.0012771821
B31: MSFT | C31: 0.70335053 | D31: 0.67978649 | E31: 0.55831666 | F31: 0.26303767 | G31: 1.0002244 | H31: 0.52888037 | I31: 0.40513753 | J31: 0.71374402 | K31: 0.3864967 | L31: 0.35085523 | M31: 0.41733688 | N31: 0.49676888 | O31: 0.29486825 | R31: E(rp)/σp | S31: =S29/S30 -> 0.17828798 | AJ31: 28 | AK31: 0.022744571 | AL31: -0.0011201487
B32: AMZN | C32: 0.65303937 | D32: 0.76489921 | E32: 0.45457529 | F32: 0.54959957 | G32: 0.52888037 | H32: 1.0009369 | I32: 0.54723393 | J32: 0.79048342 | K32: 0.47282122 | L32: 0.40951435 | M32: 0.43148879 | N32: 0.57433944 | O32: 0.48948647 | AJ32: 29 | AK32: 0.022855775 | AL32: -0.000517471
B33: AAPL | C33: 0.46281278 | D33: 0.66100935 | E33: 0.37150438 | F33: 0.61631825 | G33: 0.40513753 | H33: 0.54723393 | I33: 0.99983271 | J33: 0.71563169 | K33: 0.56589733 | L33: 0.4335321 | M33: 0.41290532 | N33: 0.40584718 | O33: 0.26788363 | R33: Maximized Risk | S33: NVDA | T33: SOFI | U33: GME | V33: GOOGL | W33: MSFT | X33: AMZN | Y33: AAPL | Z33: SWPPX | AA33: RXRX | AB33: FUBO | AC33: BBAI | AD33: RCAT | AE33: QUBT | AJ33: 30 | AK33: 0.022446197 | AL33: -0.00082368674
B34: SWPPX | C34: 0.79773124 | D34: 0.83428643 | E34: 0.61327372 | F34: 0.77221204 | G34: 0.71374402 | H34: 0.79048342 | I34: 0.71563169 | J34: 0.99828642 | K34: 0.66333208 | L34: 0.53795815 | M34: 0.70836358 | N34: 0.75212738 | O34: 0.6377306 | R34: Weights | S34: 0 | T34: 0 | U34: 0 | V34: 0 | W34: 0 | X34: 0 | Y34: 0 | Z34: 0 | AA34: 0 | AB34: 0 | AC34: 0 | AD34: 0 | AE34: 1.0000001 | AF34: =SUM(S34:AE34) -> 1.0000001 | AJ34: 31 | AK34: 0.022132076 | AL34: -0.00081113983
B35: RXRX | C35: 0.27007111 | D35: 0.55894054 | E35: 0.62200717 | F35: 0.51363793 | G35: 0.3864967 | H35: 0.47282122 | I35: 0.56589733 | J35: 0.66333208 | K35: 1.000059 | L35: 0.42042763 | M35: 0.55283062 | N35: 0.60415099 | O35: 0.50187543 | R35: E(rp) | S35: =SUMPRODUCT(S34:AE34, $C$3:$O$3) -> -0.0062365083 | T35: <-- Daily | U35: =(1+S35)^252-1 -> -0.79330711 | V35: <-- Annual | AJ35: 32 | AK35: 0.025825224 | AL35: -0.0014836283
B36: FUBO | C36: 0.33955211 | D36: 0.63387986 | E36: 0.49812465 | F36: 0.28152959 | G36: 0.35085523 | H36: 0.40951435 | I36: 0.4335321 | J36: 0.53795815 | K36: 0.42042763 | L36: 0.99996655 | M36: 0.66705131 | N36: 0.66544239 | O36: 0.56529464 | R36: σp | S36: {=SQRT(MMULT(MMULT(S34:AE34, var), TRANSPOSE(S34:AE34)))} -> 0.0726584 | AJ36: 33 | AK36: 0.024329413 | AL36: -0.0012401303
B37: BBAI | C37: 0.50873396 | D37: 0.71464906 | E37: 0.37106053 | F37: 0.61248102 | G37: 0.41733688 | H37: 0.43148879 | I37: 0.41290532 | J37: 0.70836358 | K37: 0.55283062 | L37: 0.66705131 | M37: 0.99997972 | N37: 0.85336333 | O37: 0.73186653 | R37: E(rp)/σp | S37: =S35/S36 -> -0.085833274 | AJ37: 34 | AK37: 0.016760625 | AL37: -0.00097053598
B38: RCAT | C38: 0.58111053 | D38: 0.69847597 | E38: 0.25689894 | F38: 0.58946521 | G38: 0.49676888 | H38: 0.57433944 | I38: 0.40584718 | J38: 0.75212738 | K38: 0.60415099 | L38: 0.66544239 | M38: 0.85336333 | N38: 1.0000083 | O38: 0.83738104 | AJ38: 35 | AK38: 0.023983208 | AL38: -0.0011504457
B39: QUBT | C39: 0.49483509 | D39: 0.55789841 | E39: #NUM! | F39: 0.57038986 | G39: 0.29486825 | H39: 0.48948647 | I39: 0.26788363 | J39: 0.6377306 | K39: 0.50187543 | L39: 0.56529464 | M39: 0.73186653 | N39: 0.83738104 | O39: 1.0000744 | AJ39: 36 | AK39: 0.02592434 | AL39: -0.00063118102
S40: NVDA | T40: SOFI | U40: GME | V40: GOOGL | W40: MSFT | X40: AMZN | Y40: AAPL | Z40: SWPPX | AA40: RXRX | AB40: FUBO | AC40: BBAI | AD40: RCAT | AE40: QUBT | AJ40: 37 | AK40: 0.024198004 | AL40: -0.0006129971
R41: randarray | S41: {=_xlfn.RANDARRAY(1, 13)} -> 0.34079071 | T41: 0.77045707 | U41: 0.66124475 | V41: 0.8419012 | W41: 0.44910169 | X41: 0.31640593 | Y41: 0.56792383 | Z41: 0.65071851 | AA41: 0.81828477 | AB41: 0.58788431 | AC41: 0.73325419 | AD41: 0.83809455 | AE41: 0.67487559 | AF41: =SUM(_xlfn.ANCHORARRAY(S41)) -> 8.2509371 | AJ41: 38 | AK41: 0.024000289 | AL41: -0.00028987295
...
