Workbook

Sheet Data
B2: Ticker | C2: TSLA | F2: E(r) | G2: =AVERAGE(D5:D66) -> #DIV/0!
B3: =STOCKHISTORY1($C$2, TODAY() - 91, TODAY()-) | D3: Returns | F3: σ | G3: =_xlfn.STDEV.S(D5:D66) -> #DIV/0!
D4: -- | F4: σ annualized | G4: =G3*SQRT(252) -> #DIV/0!
D5: =C5/C4-1 -> #DIV/0! | F5: σ^2 | G5: =G3^2 -> #DIV/0!
D6: =C6/C5-1 -> #DIV/0!
D7: =C7/C6-1 -> #DIV/0!
D8: =C8/C7-1 -> #DIV/0!
D9: =C9/C8-1 -> #DIV/0!
D10: =C10/C9-1 -> #DIV/0!
D11: =C11/C10-1 -> #DIV/0!
D12: =C12/C11-1 -> #DIV/0!
D13: =C13/C12-1 -> #DIV/0!
D14: =C14/C13-1 -> #DIV/0!
D15: =C15/C14-1 -> #DIV/0!
D16: =C16/C15-1 -> #DIV/0!
D17: =C17/C16-1 -> #DIV/0!
... D66: =C66/C65-1 -> #DIV/0!

Sheet N-Step Model
B1: Variables | C1: Inputs
B2: Ticker | C2: =Data!C2 -> TSLA | H2: Choose
B3: S_0 | C3: =Data!C66 -> 0 | F3: Type of Option | H3: American Put
B4: X | C4: 395
B5: σ | C5: =Data!G4 -> #DIV/0!
B6: T | C6: 0.25
B7: N | C7: 10
B8: Dt | C8: =C6/C7 -> 0.025
B9: rF | C9: 0.0404
B10: U | C10: =EXP(C5*SQRT(C8)) -> #DIV/0!
B11: D | C11: =1/C10 -> #DIV/0! | F11: Discounted | H11: =EXP(-$C$9*$C$8) -> 0.99899051
B12: P | C12: =(((1+C9)^C8) - C11) / (C10 - C11) -> #DIV/0! | F12: Compounded | H12: =EXP($C$9*$C$8) -> 1.0010105
B16: t
B17: 0 | C17: 1 | D17: 2 | E17: 3 | F17: 4 | G17: 5 | H17: 6 | I17: 7 | J17: 8 | K17: 9 | L17: 10
L20: =IF(K$17<$C$7, K21*$C$10, 0) -> #DIV/0!
K21: =IF(J$17<$C$7, J22*$C$10, 0) -> #DIV/0! | L21: {=_xlfn.IFS($H$3="European Call", L48, $H$3="European Put", L75, $H$3="American Call", L102, $H$3="American Put", L129)} -> #DIV/0!
J22: =IF(I$17<$C$7, I23*$C$10, 0) -> #DIV/0! | K22: {=_xlfn.IFS($H$3="European Call", K49, $H$3="European Put", K76, $H$3="American Call", K103, $H$3="American Put", K130)} -> #DIV/0! | L22: =IF(K$17<$C$7, K23*$C$10, 0) -> #DIV/0!
B23: Stock Price | I23: =IF(H$17<$C$7, H24*$C$10, 0) -> #DIV/0! | J23: {=_xlfn.IFS($H$3="European Call", J50, $H$3="European Put", J77, $H$3="American Call", J104, $H$3="American Put", J131)} -> #DIV/0! | K23: =IF(J$17<$C$7, J24*$C$10, 0) -> #DIV/0! | L23: {=_xlfn.IFS($H$3="European Call", L50, $H$3="European Put", L77, $H$3="American Call", L104, $H$3="American Put", L131)} -> #DIV/0!
B24: Option Price | H24: =IF(G$17<$C$7, G25*$C$10, 0) -> #DIV/0! | I24: {=_xlfn.IFS($H$3="European Call", I51, $H$3="European Put", I78, $H$3="American Call", I105, $H$3="American Put", I132)} -> #DIV/0! | J24: =IF(I$17<$C$7, I25*$C$10, 0) -> #DIV/0! | K24: {=_xlfn.IFS($H$3="European Call", K51, $H$3="European Put", K78, $H$3="American Call", K105, $H$3="American Put", K132)} -> #DIV/0! | L24: =IF(K$17<$C$7, K23*$C$11, 0) -> #DIV/0!
G25: =IF(F$17<$C$7, F26*$C$10, 0) -> #DIV/0! | H25: {=_xlfn.IFS($H$3="European Call", H52, $H$3="European Put", H79, $H$3="American Call", H106, $H$3="American Put", H133)} -> #DIV/0! | I25: =IF(H$17<$C$7, H26*$C$10, 0) -> #DIV/0! | J25: {=_xlfn.IFS($H$3="European Call", J52, $H$3="European Put", J79, $H$3="American Call", J106, $H$3="American Put", J133)} -> #DIV/0! | K25: =IF(J$17<$C$7, J24*$C$11, 0) -> #DIV/0! | L25: {=_xlfn.IFS($H$3="European Call", L52, $H$3="European Put", L79, $H$3="American Call", L106, $H$3="American Put", L133)} -> #DIV/0!
F26: =IF(E$17<$C$7, E27*$C$10, 0) -> #DIV/0! | G26: {=_xlfn.IFS($H$3="European Call", G53, $H$3="European Put", G80, $H$3="American Call", G107, $H$3="American Put", G134)} -> #DIV/0! | H26: =IF(G$17<$C$7, G27*$C$10, 0) -> #DIV/0! | I26: {=_xlfn.IFS($H$3="European Call", I53, $H$3="European Put", I80, $H$3="American Call", I107, $H$3="American Put", I134)} -> #DIV/0! | J26: =IF(I$17<$C$7, I25*$C$11, 0) -> #DIV/0! | K26: {=_xlfn.IFS($H$3="European Call", K53, $H$3="European Put", K80, $H$3="American Call", K107, $H$3="American Put", K134)} -> #DIV/0! | L26: =IF(K$17<$C$7, K25*$C$11, 0) -> #DIV/0!
E27: =IF(D$17<$C$7, D28*$C$10, 0) -> #DIV/0! | F27: {=_xlfn.IFS($H$3="European Call", F54, $H$3="European Put", F81, $H$3="American Call", F108, $H$3="American Put", F135)} -> #DIV/0! | G27: =IF(F$17<$C$7, F28*$C$10, 0) -> #DIV/0! | H27: {=_xlfn.IFS($H$3="European Call", H54, $H$3="European Put", H81, $H$3="American Call", H108, $H$3="American Put", H135)} -> #DIV/0! | I27: =IF(H$17<$C$7, H26*$C$11, 0) -> #DIV/0! | J27: {=_xlfn.IFS($H$3="European Call", J54, $H$3="European Put", J81, $H$3="American Call", J108, $H$3="American Put", J135)} -> #DIV/0! | K27: =IF(J$17<$C$7, J26*$C$11, 0) -> #DIV/0! | L27: {=_xlfn.IFS($H$3="European Call", L54, $H$3="European Put", L81, $H$3="American Call", L108, $H$3="American Put", L135)} -> #DIV/0!
D28: =IF(C$17<$C$7, C29*$C$10, 0) -> #DIV/0! | E28: {=_xlfn.IFS($H$3="European Call", E55, $H$3="European Put", E82, $H$3="American Call", E109, $H$3="American Put", E136)} -> #DIV/0! | F28: =IF(E$17<$C$7, E29*$C$10, 0) -> #DIV/0! | G28: {=_xlfn.IFS($H$3="European Call", G55, $H$3="European Put", G82, $H$3="American Call", G109, $H$3="American Put", G136)} -> #DIV/0! | H28: =IF(G$17<$C$7, G27*$C$11, 0) -> #DIV/0! | I28: {=_xlfn.IFS($H$3="European Call", I55, $H$3="European Put", I82, $H$3="American Call", I109, $H$3="American Put", I136)} -> #DIV/0! | J28: =IF(I$17<$C$7, I27*$C$11, 0) -> #DIV/0! | K28: {=_xlfn.IFS($H$3="European Call", K55, $H$3="European Put", K82, $H$3="American Call", K109, $H$3="American Put", K136)} -> #DIV/0! | L28: =IF(K$17<$C$7, K27*$C$11, 0) -> #DIV/0!
C29: =IF(B$17<$C$7, B30*$C$10, 0) -> #DIV/0! | D29: {=_xlfn.IFS($H$3="European Call", D56, $H$3="European Put", D83, $H$3="American Call", D110, $H$3="American Put", D137)} -> #DIV/0! | E29: =IF(D$17<$C$7, D30*$C$10, 0) -> #DIV/0! | F29: {=_xlfn.IFS($H$3="European Call", F56, $H$3="European Put", F83, $H$3="American Call", F110, $H$3="American Put", F137)} -> #DIV/0! | G29: =IF(F$17<$C$7, F28*$C$11, 0) -> #DIV/0! | H29: {=_xlfn.IFS($H$3="European Call", H56, $H$3="European Put", H83, $H$3="American Call", H110, $H$3="American Put", H137)} -> #DIV/0! | I29: =IF(H$17<$C$7, H28*$C$11, 0) -> #DIV/0! | J29: {=_xlfn.IFS($H$3="European Call", J56, $H$3="European Put", J83, $H$3="American Call", J110, $H$3="American Put", J137)} -> #DIV/0! | K29: =IF(J$17<$C$7, J28*$C$11, 0) -> #DIV/0! | L29: {=_xlfn.IFS($H$3="European Call", L56, $H$3="European Put", L83, $H$3="American Call", L110, $H$3="American Put", L137)} -> #DIV/0!
B30: =C3 -> 0 | C30: {=_xlfn.IFS($H$3="European Call", C57, $H$3="European Put", C84, $H$3="American Call", C111, $H$3="American Put", C138)} -> #DIV/0! | D30: =IF(C$17<$C$7, C29*$C$11, 0) -> #DIV/0! | E30: {=_xlfn.IFS($H$3="European Call", E57, $H$3="European Put", E84, $H$3="American Call", E111, $H$3="American Put", E138)} -> #DIV/0! | F30: =IF(E$17<$C$7, E29*$C$11, 0) -> #DIV/0! | G30: {=_xlfn.IFS($H$3="European Call", G57, $H$3="European Put", G84, $H$3="American Call", G111, $H$3="American Put", G138)} -> #DIV/0! | H30: =IF(G$17<$C$7, G29*$C$11, 0) -> #DIV/0! | I30: {=_xlfn.IFS($H$3="European Call", I57, $H$3="European Put", I84, $H$3="American Call", I111, $H$3="American Put", I138)} -> #DIV/0! | J30: =IF(I$17<$C$7, I29*$C$11, 0) -> #DIV/0! | K30: {=_xlfn.IFS($H$3="European Call", K57, $H$3="European Put", K84, $H$3="American Call", K111, $H$3="American Put", K138)} -> #DIV/0! | L30: =IF(K$17<$C$7, K29*$C$11, 0) -> #DIV/0!
B31: {=_xlfn.IFS($H$3="European Call", B58, $H$3="European Put", B85, $H$3="American Call", B112, $H$3="American Put", B139)} -> 0 | C31: =IF(B$17<$C$7, B30*$C$11, 0) -> #DIV/0! | D31: {=_xlfn.IFS($H$3="European Call", D58, $H$3="European Put", D85, $H$3="American Call", D112, $H$3="American Put", D139)} -> #DIV/0! | E31: =IF(D$17<$C$7, D30*$C$11, 0) -> #DIV/0! | F31: {=_xlfn.IFS($H$3="European Call", F58, $H$3="European Put", F85, $H$3="American Call", F112, $H$3="American Put", F139)} -> #DIV/0! | G31: =IF(F$17<$C$7, F30*$C$11, 0) -> #DIV/0! | H31: {=_xlfn.IFS($H$3="European Call", H58, $H$3="European Put", H85, $H$3="American Call", H112, $H$3="American Put", H139)} -> #DIV/0! | I31: =IF(H$17<$C$7, H30*$C$11, 0) -> #DIV/0! | J31: {=_xlfn.IFS($H$3="European Call", J58, $H$3="European Put", J85, $H$3="American Call", J112, $H$3="American Put", J139)} -> #DIV/0! | K31: =IF(J$17<$C$7, J30*$C$11, 0) -> #DIV/0! | L31: {=_xlfn.IFS($H$3="European Call", L58, $H$3="European Put", L85, $H$3="American Call", L112, $H$3="American Put", L139)} -> #DIV/0!
C32: {=_xlfn.IFS($H$3="European Call", C59, $H$3="European Put", C86, $H$3="American Call", C113, $H$3="American Put", C140)} -> #DIV/0! | D32: =IF(C$17<$C$7, C31*$C$11, 0) -> #DIV/0! | E32: {=_xlfn.IFS($H$3="European Call", E59, $H$3="European Put", E86, $H$3="American Call", E113, $H$3="American Put", E140)} -> #DIV/0! | F32: =IF(E$17<$C$7, E31*$C$11, 0) -> #DIV/0! | G32: {=_xlfn.IFS($H$3="European Call", G59, $H$3="European Put", G86, $H$3="American Call", G113, $H$3="American Put", G140)} -> #DIV/0! | H32: =IF(G$17<$C$7, G31*$C$11, 0) -> #DIV/0! | I32: {=_xlfn.IFS($H$3="European Call", I59, $H$3="European Put", I86, $H$3="American Call", I113, $H$3="American Put", I140)} -> #DIV/0! | J32: =IF(I$17<$C$7, I31*$C$11, 0) -> #DIV/0! | K32: {=_xlfn.IFS($H$3="European Call", K59, $H$3="European Put", K86, $H$3="American Call", K113, $H$3="American Put", K140)} -> #DIV/0! | L32: =IF(K$17<$C$7, K31*$C$11, 0) -> #DIV/0!
D33: {=_xlfn.IFS($H$3="European Call", D60, $H$3="European Put", D87, $H$3="American Call", D114, $H$3="American Put", D141)} -> #DIV/0! | E33: =IF(D$17<$C$7, D32*$C$11, 0) -> #DIV/0! | F33: {=_xlfn.IFS($H$3="European Call", F60, $H$3="European Put", F87, $H$3="American Call", F114, $H$3="American Put", F141)} -> #DIV/0! | G33: =IF(F$17<$C$7, F32*$C$11, 0) -> #DIV/0! | H33: {=_xlfn.IFS($H$3="European Call", H60, $H$3="European Put", H87, $H$3="American Call", H114, $H$3="American Put", H141)} -> #DIV/0! | I33: =IF(H$17<$C$7, H32*$C$11, 0) -> #DIV/0! | J33: {=_xlfn.IFS($H$3="European Call", J60, $H$3="European Put", J87, $H$3="American Call", J114, $H$3="American Put", J141)} -> #DIV/0! | K33: =IF(J$17<$C$7, J32*$C$11, 0) -> #DIV/0! | L33: {=_xlfn.IFS($H$3="European Call", L60, $H$3="European Put", L87, $H$3="American Call", L114, $H$3="American Put", L141)} -> #DIV/0!
E34: {=_xlfn.IFS($H$3="European Call", E61, $H$3="European Put", E88, $H$3="American Call", E115, $H$3="American Put", E142)} -> #DIV/0! | F34: =IF(E$17<$C$7, E33*$C$11, 0) -> #DIV/0! | G34: {=_xlfn.IFS($H$3="European Call", G61, $H$3="European Put", G88, $H$3="American Call", G115, $H$3="American Put", G142)} -> #DIV/0! | H34: =IF(G$17<$C$7, G33*$C$11, 0) -> #DIV/0! | I34: {=_xlfn.IFS($H$3="European Call", I61, $H$3="European Put", I88, $H$3="American Call", I115, $H$3="American Put", I142)} -> #DIV/0! | J34: =IF(I$17<$C$7, I33*$C$11, 0) -> #DIV/0! | K34: {=_xlfn.IFS($H$3="European Call", K61, $H$3="European Put", K88, $H$3="American Call", K115, $H$3="American Put", K142)} -> #DIV/0! | L34: =IF(K$17<$C$7, K33*$C$11, 0) -> #DIV/0!
F35: {=_xlfn.IFS($H$3="European Call", F62, $H$3="European Put", F89, $H$3="American Call", F116, $H$3="American Put", F143)} -> #DIV/0! | G35: =IF(F$17<$C$7, F34*$C$11, 0) -> #DIV/0! | H35: {=_xlfn.IFS($H$3="European Call", H62, $H$3="European Put", H89, $H$3="American Call", H116, $H$3="American Put", H143)} -> #DIV/0! | I35: =IF(H$17<$C$7, H34*$C$11, 0) -> #DIV/0! | J35: {=_xlfn.IFS($H$3="European Call", J62, $H$3="European Put", J89, $H$3="American Call", J116, $H$3="American Put", J143)} -> #DIV/0! | K35: =IF(J$17<$C$7, J34*$C$11, 0) -> #DIV/0! | L35: {=_xlfn.IFS($H$3="European Call", L62, $H$3="European Put", L89, $H$3="American Call", L116, $H$3="American Put", L143)} -> #DIV/0!
G36: {=_xlfn.IFS($H$3="European Call", G63, $H$3="European Put", G90, $H$3="American Call", G117, $H$3="American Put", G144)} -> #DIV/0! | H36: =IF(G$17<$C$7, G35*$C$11, 0) -> #DIV/0! | I36: {=_xlfn.IFS($H$3="European Call", I63, $H$3="European Put", I90, $H$3="American Call", I117, $H$3="American Put", I144)} -> #DIV/0! | J36: =IF(I$17<$C$7, I35*$C$11, 0) -> #DIV/0! | K36: {=_xlfn.IFS($H$3="European Call", K63, $H$3="European Put", K90, $H$3="American Call", K117, $H$3="American Put", K144)} -> #DIV/0! | L36: =IF(K$17<$C$7, K35*$C$11, 0) -> #DIV/0!
H37: {=_xlfn.IFS($H$3="European Call", H64, $H$3="European Put", H91, $H$3="American Call", H118, $H$3="American Put", H145)} -> #DIV/0! | I37: =IF(H$17<$C$7, H36*$C$11, 0) -> #DIV/0! | J37: {=_xlfn.IFS($H$3="European Call", J64, $H$3="European Put", J91, $H$3="American Call", J118, $H$3="American Put", J145)} -> #DIV/0! | K37: =IF(J$17<$C$7, J36*$C$11, 0) -> #DIV/0! | L37: {=_xlfn.IFS($H$3="European Call", L64, $H$3="European Put", L91, $H$3="American Call", L118, $H$3="American Put", L145)} -> #DIV/0!
I38: {=_xlfn.IFS($H$3="European Call", I65, $H$3="European Put", I92, $H$3="American Call", I119, $H$3="American Put", I146)} -> #DIV/0! | J38: =IF(I$17<$C$7, I37*$C$11, 0) -> #DIV/0! | K38: {=_xlfn.IFS($H$3="European Call", K65, $H$3="European Put", K92, $H$3="American Call", K119, $H$3="American Put", K146)} -> #DIV/0! | L38: =IF(K$17<$C$7, K37*$C$11, 0) -> #DIV/0!
J39: {=_xlfn.IFS($H$3="European Call", J66, $H$3="European Put", J93, $H$3="American Call", J120, $H$3="American Put", J147)} -> #DIV/0! | K39: =IF(J$17<$C$7, J38*$C$11, 0) -> #DIV/0! | L39: {=_xlfn.IFS($H$3="European Call", L66, $H$3="European Put", L93, $H$3="American Call", L120, $H$3="American Put", L147)} -> #DIV/0!
K40: {=_xlfn.IFS($H$3="European Call", K67, $H$3="European Put", K94, $H$3="American Call", K121, $H$3="American Put", K148)} -> #DIV/0! | L40: =IF(K$17<$C$7, K39*$C$11, 0) -> #DIV/0!
L41: {=_xlfn.IFS($H$3="European Call", L68, $H$3="European Put", L95, $H$3="American Call", L122, $H$3="American Put", L149)} -> #DIV/0!
B42: European Call Option
B43: t
B44: 0 | C44: 1 | D44: 2 | E44: 3 | F44: 4 | G44: 5 | H44: 6 | I44: 7 | J44: 8 | K44: 9 | L44: 10
L48: =MAX((_xlfn.IFS(L$44>$C$7, 0, L$44<$C$7, $H$11*($C$12*M47+(1-$C$12)*M49), L$44=$C$7, MAX(0, L20-$C$4)))) -> #DIV/0!
...

Sheet Single-Step Model
B2: Variables | C2: Inputs
B3: S_0 | C3: =Data!C66 -> 0
B4: X | C4: 42 | H4: =G6*C8 -> #DIV/0! | M4: =MAX(H4-$C$4, 0) -> #DIV/0! | R4: =MAX($C$4-H4, 0) -> #DIV/0!
B5: σ | C5: =Data!G4 -> #DIV/0! | F5: Stock U | K5: Call Max | P5: Put Max
B6: Dt | C6: =0.75 -> 0.75 | E6: Stock Value TD | G6: =C3 -> 0 | J6: Call Value Premium | L6: =((C10*M4) + ((1-C10)*M8))/((1+C7)^C6) -> #DIV/0! | O6: Put Value Premium | Q6: =(($C$10*R4) + ((1-$C$10)*R8))/((1+$C$7)^$C$6) -> #DIV/0!
B7: rF | C7: 0.0404 | F7: Stock D | K7: Call Min | P7: Put Min
B8: U | C8: =EXP(C5*SQRT(C6)) -> #DIV/0! | H8: =G6*C9 -> #DIV/0! | M8: =MAX(H8-$C$4, 0) -> #DIV/0! | R8: =MAX($C$4-H8, 0) -> #DIV/0!
B9: D | C9: =1/C8 -> #DIV/0!
B10: P | C10: =(((1+C7)^C6) - C9) / (C8 - C9) -> #DIV/0!
B13: Put-Call Parity
B14: Bundle A | C14: =(L6+C4)/((1+C7)^C6) -> #DIV/0!
B15: Bundle B | C15: =Q6+C3 -> #DIV/0!
B16: Difference | C16: =C14-C15 -> #DIV/0!

Sheet Two-Step Model
B2: Variables | C2: Inputs | E2: Put-Call Parity
B3: S_0 | C3: =Data!C66 -> 0 | E3: Bundle A | F3: =B25+C4/(1+C7)^C6 -> #DIV/0!
B4: X | C4: 375 | E4: Bundle B | F4: =B33+C3 -> #DIV/0!
B5: σ | C5: =Data!G4 -> #DIV/0! | E5: Difference | F5: =F3-F4 -> #DIV/0!
B6: Dt | C6: =0.75 -> 0.75
B7: rF | C7: 0.0404
B8: U | C8: =EXP(C5*SQRT(C6)) -> #DIV/0!
B9: D | C9: =1/C8 -> #DIV/0!
B10: P | C10: =(((1+C7)^C6) - C9) / (C8 - C9) -> #DIV/0!
B14: Stock
D15: =C16*C8 -> #DIV/0!
C16: =B17*C8 -> #DIV/0!
B17: =C3 -> 0 | D17: =C16*C9 -> #DIV/0!
C18: =B17*C9 -> #DIV/0!
D19: =C18*C9 -> #DIV/0!
B22: Call
D23: =MAX(D15-$C$4, 0) -> #DIV/0!
C24: =(($C$10*D23)+((1-$C$10)*D25))/((1+$C$7)^$C$6) -> #DIV/0!
B25: =(($C$10*C24)+((1-$C$10)*C26))/((1+$C$7)^$C$6) -> #DIV/0! | D25: =MAX(D17-$C$4, 0) -> #DIV/0!
C26: =((C10*D25)+((1-C10)*D27))/(1+C7)^C6 -> #DIV/0!
D27: =MAX(D19-$C$4, 0) -> #DIV/0!
B30: Put
D31: =MAX($C$4-D15, 0) -> #DIV/0!
C32: =((D31*$C$10)+((1-$C$10)*D33))/((1+$C$7)^$C$6) -> #DIV/0!
B33: =((C32*$C$10)+((1-$C$10)*C34))/((1+$C$7)^$C$6) -> #DIV/0! | D33: =MAX($C$4-D17, 0) -> #DIV/0!
C34: =((D33*$C$10)+((1-$C$10)*D35))/((1+$C$7)^$C$6) -> #DIV/0!
D35: =MAX($C$4-D19, 0) -> #DIV/0!
