Workbook

Sheet DailyData
A1: Dates | B1: Monthly | C1: Key | D1: SPY | E1: IWM | F1: TLT | G1: GLD | H1: VNQ | I1: ORCL | J1: BLK | K1: LMT | L1: XLV | M1: SMCI
A2: 45954 | B2: =EOMONTH(A2,-1)+1 -> 45931 | C2: =TEXT(A2, "yyyy-mm") -> 2025-10 | D2: 677.25 | E2: 249.43 | F2: 91.47 | G2: 377.52 | H2: 92.43 | I2: 283.33 | J2: 1136.63 | K2: 485.41 | L2: 146.03 | M2: 48.29
A3: 45953 | B3: =EOMONTH(A3,-1)+1 -> 45931 | C3: =TEXT(A3, "yyyy-mm") -> 2025-10 | D3: 671.76 | E3: 246.42 | F3: 91.43 | G3: 378.79 | H3: 92.16 | I3: 280.07 | J3: 1125 | K3: 488.05 | L3: 146.04 | M3: 47.92
A4: 45952 | B4: =EOMONTH(A4,-1)+1 -> 45931 | C4: =TEXT(A4, "yyyy-mm") -> 2025-10 | D4: 667.8 | E4: 243.34 | F4: 92.06 | G4: 377.28 | H4: 92.22 | I4: 272.66 | J4: 1129.68 | K4: 487.14 | L4: 145.96 | M4: 52.5
A5: 45951 | B5: =EOMONTH(A5,-1)+1 -> 45931 | C5: =TEXT(A5, "yyyy-mm") -> 2025-10 | D5: 671.29 | E5: 246.99 | F5: 92 | G5: 377.24 | H5: 91.83 | I5: 275.15 | J5: 1130 | K5: 489.5 | L5: 145.13 | M5: 54.82
A6: 45950 | B6: =EOMONTH(A6,-1)+1 -> 45931 | C6: =TEXT(A6, "yyyy-mm") -> 2025-10 | D6: 671.3 | E6: 248.16 | F6: 91.55 | G6: 403.15 | H6: 92.09 | I6: 277.18 | J6: 1160 | K6: 505.9 | L6: 144.79 | M6: 55.04
A7: 45947 | B7: =EOMONTH(A7,-1)+1 -> 45931 | C7: =TEXT(A7, "yyyy-mm") -> 2025-10 | D7: 664.39 | E7: 243.41 | F7: 91.2 | G7: 388.99 | H7: 91.17 | I7: 291.31 | J7: 1161.16 | K7: 495.15 | L7: 143.27 | M7: 52.18
A8: 45946 | B8: =EOMONTH(A8,-1)+1 -> 45931 | C8: =TEXT(A8, "yyyy-mm") -> 2025-10 | D8: 660.64 | E8: 245.06 | F8: 91.34 | G8: 396.45 | H8: 90.58 | I8: 313 | J8: 1171.36 | K8: 493.25 | L8: 142.32 | M8: 53.84
A9: 45945 | B9: =EOMONTH(A9,-1)+1 -> 45931 | C9: =TEXT(A9, "yyyy-mm") -> 2025-10 | D9: 665.17 | E9: 250.33 | F9: 90.66 | G9: 387.39 | H9: 90.9 | I9: 303.62 | J9: 1202.59 | K9: 499.41 | L9: 142.56 | M9: 53.94
A10: 45944 | B10: =EOMONTH(A10,-1)+1 -> 45931 | C10: =TEXT(A10, "yyyy-mm") -> 2025-10 | D10: 662.23 | E10: 247.9 | F10: 90.86 | G10: 380.79 | H10: 89.6 | I10: 299 | J10: 1194.26 | K10: 505.18 | L10: 142.34 | M10: 53.11
A11: 45943 | B11: =EOMONTH(A11,-1)+1 -> 45931 | C11: =TEXT(A11, "yyyy-mm") -> 2025-10 | D11: 663.04 | E11: 244.41 | F11: 90.57 | G11: 378.09 | H11: 88.69 | I11: 308.01 | J11: 1155.12 | K11: 503.83 | L11: 141.95 | M11: 54.75
A12: 45940 | B12: =EOMONTH(A12,-1)+1 -> 45931 | C12: =TEXT(A12, "yyyy-mm") -> 2025-10 | D12: 653.02 | E12: 237.79 | F12: 90.62 | G12: 369.12 | H12: 88.13 | I12: 292.96 | J12: 1132.36 | K12: 505.05 | L12: 142.11 | M12: 52.86
A13: 45939 | B13: =EOMONTH(A13,-1)+1 -> 45931 | C13: =TEXT(A13, "yyyy-mm") -> 2025-10 | D13: 671.16 | E13: 245.13 | F13: 89.18 | G13: 365.43 | H13: 89.27 | I13: 296.96 | J13: 1167.43 | K13: 507.76 | L13: 144.19 | M13: 57.98
... A2516: 42303 | B2516: =EOMONTH(A2516,-1)+1 -> 42278 | C2516: =TEXT(A2516, "yyyy-mm") -> 2015-10 | D2516: 207 | E2516: 115.06 | F2516: 124.02 | G2516: 111.43 | H2516: 80.7 | I2516: 38.37 | J2516: 337.02 | K2516: 220.94 | L2516: 69.6 | M2516: 2.76

Sheet Monthly Returns
A1: Company Name | B1: S&P 500 | C1: iShares Russell | D1: iShares Yearly Bond | E1: SPDR Gold Shares | F1: Vanguard Real Estate | G1: Oracle | H1: BlackRock | I1: Lockheed Martin | J1: SPDR Select Sector Fund | K1: Super Micro Computer Inc
A2: Ticker | B2: SPY | C2: IWM | D2: TLT | E2: GLD | F2: VNQ | G2: ORCL | H2: BLK | I2: LMT | J2: XLV | K2: SMCI
A3: Market Capitalization | B3: 584012992500 | C3: 62444800500 | D3: 49904335323 | E3: 103100712000 | F3: 27488682000 | G3: 805142827620 | H3: 176010948434 | I3: 112322804156 | J3: 24123078500 | K3: 28697458043
A4: Benchmark Proposition | B4: =B3/SUM($B$3:$K$3) -> 0.29596523 | C4: =C3/SUM($B$3:$K$3) -> 0.031645683 | D4: =D3/SUM($B$3:$K$3) -> 0.025290445 | E4: =E3/SUM($B$3:$K$3) -> 0.052249225 | F4: =F3/SUM($B$3:$K$3) -> 0.013930673 | G4: =G3/SUM($B$3:$K$3) -> 0.40802908 | H4: =H3/SUM($B$3:$K$3) -> 0.089198566 | I4: =I3/SUM($B$3:$K$3) -> 0.056922783 | ... K4: =K3/SUM($B$3:$K$3) -> 0.014543255 | L4: <-- Variable
A7: Dates | B7: SPY | C7: IWM | D7: TLT | E7: GLD | F7: VNQ | G7: ORCL | H7: BLK | I7: LMT | J7: XLV | K7: SMCI
A8: 45931 | B8: =_xlfn.XLOOKUP(A8, DailyData!$A$2:$A$2516, DailyData!$D$2:$D$2516, " ") -> 668.45 | C8: =_xlfn.XLOOKUP($A8, DailyData!$A$2:$A$2516, DailyData!$E$2:$E$2516, " ") -> 242.49 | D8: =_xlfn.XLOOKUP($A8, DailyData!$A$2:$A$2516, DailyData!F$2:F$2516, " ") -> 89.29 | E8: =_xlfn.XLOOKUP($A8, DailyData!$A$2:$A$2516, DailyData!G$2:G$2516, " ") -> 356.03 | F8: =_xlfn.XLOOKUP($A8, DailyData!$A$2:$A$2516, DailyData!H$2:H$2516, " ") -> 91.56 | G8: =_xlfn.XLOOKUP($A8, DailyData!$A$2:$A$2516, DailyData!I$2:I$2516, " ") -> 289.01 | H8: =_xlfn.XLOOKUP($A8, DailyData!$A$2:$A$2516, DailyData!J$2:J$2516, " ") -> 1141.07 | I8: =_xlfn.XLOOKUP($A8, DailyData!$A$2:$A$2516, DailyData!K$2:K$2516, " ") -> 499 | J8: =_xlfn.XLOOKUP($A8, DailyData!$A$2:$A$2516, DailyData!L$2:L$2516, " ") -> 143.47 | K8: =_xlfn.XLOOKUP($A8, DailyData!$A$2:$A$2516, DailyData!M$2:M$2516, " ") -> 52.39
A9: 45902 | B9: =_xlfn.XLOOKUP(A9, DailyData!$A$2:$A$2516, DailyData!$D$2:$D$2516, " ") -> 640.27 | C9: =_xlfn.XLOOKUP($A9, DailyData!$A$2:$A$2516, DailyData!$E$2:$E$2516, " ") -> 233.9 | D9: =_xlfn.XLOOKUP($A9, DailyData!$A$2:$A$2516, DailyData!F$2:F$2516, " ") -> 85.63 | E9: =_xlfn.XLOOKUP($A9, DailyData!$A$2:$A$2516, DailyData!G$2:G$2516, " ") -> 325.59 | F9: =_xlfn.XLOOKUP($A9, DailyData!$A$2:$A$2516, DailyData!H$2:H$2516, " ") -> 90.71 | G9: =_xlfn.XLOOKUP($A9, DailyData!$A$2:$A$2516, DailyData!I$2:I$2516, " ") -> 225.3 | H9: =_xlfn.XLOOKUP($A9, DailyData!$A$2:$A$2516, DailyData!J$2:J$2516, " ") -> 1114.77 | I9: =_xlfn.XLOOKUP($A9, DailyData!$A$2:$A$2516, DailyData!K$2:K$2516, " ") -> 452.5 | J9: =_xlfn.XLOOKUP($A9, DailyData!$A$2:$A$2516, DailyData!L$2:L$2516, " ") -> 137.56 | K9: =_xlfn.XLOOKUP($A9, DailyData!$A$2:$A$2516, DailyData!M$2:M$2516, " ") -> 40.78
A10: 45870 | B10: =_xlfn.XLOOKUP(A10, DailyData!$A$2:$A$2516, DailyData!$D$2:$D$2516, " ") -> 621.72 | C10: =_xlfn.XLOOKUP($A10, DailyData!$A$2:$A$2516, DailyData!$E$2:$E$2516, " ") -> 214.92 | D10: =_xlfn.XLOOKUP($A10, DailyData!$A$2:$A$2516, DailyData!F$2:F$2516, " ") -> 87.82 | E10: =_xlfn.XLOOKUP($A10, DailyData!$A$2:$A$2516, DailyData!G$2:G$2516, " ") -> 309.11 | F10: =_xlfn.XLOOKUP($A10, DailyData!$A$2:$A$2516, DailyData!H$2:H$2516, " ") -> 88.92 | G10: =_xlfn.XLOOKUP($A10, DailyData!$A$2:$A$2516, DailyData!I$2:I$2516, " ") -> 244.42 | H10: =_xlfn.XLOOKUP($A10, DailyData!$A$2:$A$2516, DailyData!J$2:J$2516, " ") -> 1091.8 | I10: =_xlfn.XLOOKUP($A10, DailyData!$A$2:$A$2516, DailyData!K$2:K$2516, " ") -> 421.01 | J10: =_xlfn.XLOOKUP($A10, DailyData!$A$2:$A$2516, DailyData!L$2:L$2516, " ") -> 131.13 | K10: =_xlfn.XLOOKUP($A10, DailyData!$A$2:$A$2516, DailyData!M$2:M$2516, " ") -> 56.64
A11: 45839 | B11: =_xlfn.XLOOKUP(A11, DailyData!$A$2:$A$2516, DailyData!$D$2:$D$2516, " ") -> 617.65 | C11: =_xlfn.XLOOKUP($A11, DailyData!$A$2:$A$2516, DailyData!$E$2:$E$2516, " ") -> 218.01 | D11: =_xlfn.XLOOKUP($A11, DailyData!$A$2:$A$2516, DailyData!F$2:F$2516, " ") -> 88.14 | E11: =_xlfn.XLOOKUP($A11, DailyData!$A$2:$A$2516, DailyData!G$2:G$2516, " ") -> 307.55 | F11: =_xlfn.XLOOKUP($A11, DailyData!$A$2:$A$2516, DailyData!H$2:H$2516, " ") -> 89.71 | G11: =_xlfn.XLOOKUP($A11, DailyData!$A$2:$A$2516, DailyData!I$2:I$2516, " ") -> 218.96 | H11: =_xlfn.XLOOKUP($A11, DailyData!$A$2:$A$2516, DailyData!J$2:J$2516, " ") -> 1054.27 | I11: =_xlfn.XLOOKUP($A11, DailyData!$A$2:$A$2516, DailyData!K$2:K$2516, " ") -> 465.94 | J11: =_xlfn.XLOOKUP($A11, DailyData!$A$2:$A$2516, DailyData!L$2:L$2516, " ") -> 136.71 | K11: =_xlfn.XLOOKUP($A11, DailyData!$A$2:$A$2516, DailyData!M$2:M$2516, " ") -> 47.2
A12: 45810 | B12: =_xlfn.XLOOKUP(A12, DailyData!$A$2:$A$2516, DailyData!$D$2:$D$2516, " ") -> 592.71 | C12: =_xlfn.XLOOKUP($A12, DailyData!$A$2:$A$2516, DailyData!$E$2:$E$2516, " ") -> 205.71 | D12: =_xlfn.XLOOKUP($A12, DailyData!$A$2:$A$2516, DailyData!F$2:F$2516, " ") -> 85.16 | E12: =_xlfn.XLOOKUP($A12, DailyData!$A$2:$A$2516, DailyData!G$2:G$2516, " ") -> 311.67 | F12: =_xlfn.XLOOKUP($A12, DailyData!$A$2:$A$2516, DailyData!H$2:H$2516, " ") -> 89.44 | G12: =_xlfn.XLOOKUP($A12, DailyData!$A$2:$A$2516, DailyData!I$2:I$2516, " ") -> 166.57 | H12: =_xlfn.XLOOKUP($A12, DailyData!$A$2:$A$2516, DailyData!J$2:J$2516, " ") -> 978.07 | I12: =_xlfn.XLOOKUP($A12, DailyData!$A$2:$A$2516, DailyData!K$2:K$2516, " ") -> 478.82 | J12: =_xlfn.XLOOKUP($A12, DailyData!$A$2:$A$2516, DailyData!L$2:L$2516, " ") -> 132.72 | K12: =_xlfn.XLOOKUP($A12, DailyData!$A$2:$A$2516, DailyData!M$2:M$2516, " ") -> 41.2
A13: 45778 | B13: =_xlfn.XLOOKUP(A13, DailyData!$A$2:$A$2516, DailyData!$D$2:$D$2516, " ") -> 558.47 | C13: =_xlfn.XLOOKUP($A13, DailyData!$A$2:$A$2516, DailyData!$E$2:$E$2516, " ") -> 196.07 | D13: =_xlfn.XLOOKUP($A13, DailyData!$A$2:$A$2516, DailyData!F$2:F$2516, " ") -> 88.69 | E13: =_xlfn.XLOOKUP($A13, DailyData!$A$2:$A$2516, DailyData!G$2:G$2516, " ") -> 297.46 | F13: =_xlfn.XLOOKUP($A13, DailyData!$A$2:$A$2516, DailyData!H$2:H$2516, " ") -> 88.62 | G13: =_xlfn.XLOOKUP($A13, DailyData!$A$2:$A$2516, DailyData!I$2:I$2516, " ") -> 145.49 | H13: =_xlfn.XLOOKUP($A13, DailyData!$A$2:$A$2516, DailyData!J$2:J$2516, " ") -> 916.14 | I13: =_xlfn.XLOOKUP($A13, DailyData!$A$2:$A$2516, DailyData!K$2:K$2516, " ") -> 477.72 | J13: =_xlfn.XLOOKUP($A13, DailyData!$A$2:$A$2516, DailyData!L$2:L$2516, " ") -> 136.64 | K13: =_xlfn.XLOOKUP($A13, DailyData!$A$2:$A$2516, DailyData!M$2:M$2516, " ") -> 32.73
A14: 45748 | B14: =_xlfn.XLOOKUP(A14, DailyData!$A$2:$A$2516, DailyData!$D$2:$D$2516, " ") -> 560.97 | C14: =_xlfn.XLOOKUP($A14, DailyData!$A$2:$A$2516, DailyData!$E$2:$E$2516, " ") -> 199.51 | D14: =_xlfn.XLOOKUP($A14, DailyData!$A$2:$A$2516, DailyData!F$2:F$2516, " ") -> 91.49 | E14: =_xlfn.XLOOKUP($A14, DailyData!$A$2:$A$2516, DailyData!G$2:G$2516, " ") -> 287.57 | F14: =_xlfn.XLOOKUP($A14, DailyData!$A$2:$A$2516, DailyData!H$2:H$2516, " ") -> 90.58 | G14: =_xlfn.XLOOKUP($A14, DailyData!$A$2:$A$2516, DailyData!I$2:I$2516, " ") -> 141.94 | H14: =_xlfn.XLOOKUP($A14, DailyData!$A$2:$A$2516, DailyData!J$2:J$2516, " ") -> 944.08 | I14: =_xlfn.XLOOKUP($A14, DailyData!$A$2:$A$2516, DailyData!K$2:K$2516, " ") -> 448.64 | J14: =_xlfn.XLOOKUP($A14, DailyData!$A$2:$A$2516, DailyData!L$2:L$2516, " ") -> 143.34 | K14: =_xlfn.XLOOKUP($A14, DailyData!$A$2:$A$2516, DailyData!M$2:M$2516, " ") -> 35.05
A15: 45719 | B15: =_xlfn.XLOOKUP(A15, DailyData!$A$2:$A$2516, DailyData!$D$2:$D$2516, " ") -> 583.77 | C15: =_xlfn.XLOOKUP($A15, DailyData!$A$2:$A$2516, DailyData!$E$2:$E$2516, " ") -> 208.78 | D15: =_xlfn.XLOOKUP($A15, DailyData!$A$2:$A$2516, DailyData!F$2:F$2516, " ") -> 92.57 | E15: =_xlfn.XLOOKUP($A15, DailyData!$A$2:$A$2516, DailyData!G$2:G$2516, " ") -> 266.74 | F15: =_xlfn.XLOOKUP($A15, DailyData!$A$2:$A$2516, DailyData!H$2:H$2516, " ") -> 94.34 | G15: =_xlfn.XLOOKUP($A15, DailyData!$A$2:$A$2516, DailyData!I$2:I$2516, " ") -> 162.02 | H15: =_xlfn.XLOOKUP($A15, DailyData!$A$2:$A$2516, DailyData!J$2:J$2516, " ") -> 966.47 | I15: =_xlfn.XLOOKUP($A15, DailyData!$A$2:$A$2516, DailyData!K$2:K$2516, " ") -> 451.94 | J15: =_xlfn.XLOOKUP($A15, DailyData!$A$2:$A$2516, DailyData!L$2:L$2516, " ") -> 149.58 | K15: =_xlfn.XLOOKUP($A15, DailyData!$A$2:$A$2516, DailyData!M$2:M$2516, " ") -> 36.07
A16: 45691 | B16: =_xlfn.XLOOKUP(A16, DailyData!$A$2:$A$2516, DailyData!$D$2:$D$2516, " ") -> 597.77 | C16: =_xlfn.XLOOKUP($A16, DailyData!$A$2:$A$2516, DailyData!$E$2:$E$2516, " ") -> 223.83 | D16: =_xlfn.XLOOKUP($A16, DailyData!$A$2:$A$2516, DailyData!F$2:F$2516, " ") -> 88.16 | E16: =_xlfn.XLOOKUP($A16, DailyData!$A$2:$A$2516, DailyData!G$2:G$2516, " ") -> 259.94 | F16: =_xlfn.XLOOKUP($A16, DailyData!$A$2:$A$2516, DailyData!H$2:H$2516, " ") -> 90.36 | G16: =_xlfn.XLOOKUP($A16, DailyData!$A$2:$A$2516, DailyData!I$2:I$2516, " ") -> 168.6 | H16: =_xlfn.XLOOKUP($A16, DailyData!$A$2:$A$2516, DailyData!J$2:J$2516, " ") -> 1013.75 | I16: =_xlfn.XLOOKUP($A16, DailyData!$A$2:$A$2516, DailyData!K$2:K$2516, " ") -> 455.42 | J16: =_xlfn.XLOOKUP($A16, DailyData!$A$2:$A$2516, DailyData!L$2:L$2516, " ") -> 147.44 | K16: =_xlfn.XLOOKUP($A16, DailyData!$A$2:$A$2516, DailyData!M$2:M$2516, " ") -> 26.85
A17: 45659 | B17: =_xlfn.XLOOKUP(A17, DailyData!$A$2:$A$2516, DailyData!$D$2:$D$2516, " ") -> 584.64 | C17: =_xlfn.XLOOKUP($A17, DailyData!$A$2:$A$2516, DailyData!$E$2:$E$2516, " ") -> 221.14 | D17: =_xlfn.XLOOKUP($A17, DailyData!$A$2:$A$2516, DailyData!F$2:F$2516, " ") -> 87.57 | E17: =_xlfn.XLOOKUP($A17, DailyData!$A$2:$A$2516, DailyData!G$2:G$2516, " ") -> 245.42 | F17: =_xlfn.XLOOKUP($A17, DailyData!$A$2:$A$2516, DailyData!H$2:H$2516, " ") -> 88.29 | G17: =_xlfn.XLOOKUP($A17, DailyData!$A$2:$A$2516, DailyData!I$2:I$2516, " ") -> 166.03 | H17: =_xlfn.XLOOKUP($A17, DailyData!$A$2:$A$2516, DailyData!J$2:J$2516, " ") -> 1017.4 | I17: =_xlfn.XLOOKUP($A17, DailyData!$A$2:$A$2516, DailyData!K$2:K$2516, " ") -> 482.25 | J17: =_xlfn.XLOOKUP($A17, DailyData!$A$2:$A$2516, DailyData!L$2:L$2516, " ") -> 137.61 | K17: =_xlfn.XLOOKUP($A17, DailyData!$A$2:$A$2516, DailyData!M$2:M$2516, " ") -> 30.05
A18: 45628 | B18: =_xlfn.XLOOKUP(A18, DailyData!$A$2:$A$2516, DailyData!$D$2:$D$2516, " ") -> 603.63 | C18: =_xlfn.XLOOKUP($A18, DailyData!$A$2:$A$2516, DailyData!$E$2:$E$2516, " ") -> 241.75 | D18: =_xlfn.XLOOKUP($A18, DailyData!$A$2:$A$2516, DailyData!F$2:F$2516, " ") -> 93.87 | E18: =_xlfn.XLOOKUP($A18, DailyData!$A$2:$A$2516, DailyData!G$2:G$2516, " ") -> 243.44 | F18: =_xlfn.XLOOKUP($A18, DailyData!$A$2:$A$2516, DailyData!H$2:H$2516, " ") -> 96.73 | G18: =_xlfn.XLOOKUP($A18, DailyData!$A$2:$A$2516, DailyData!I$2:I$2516, " ") -> 181.41 | H18: =_xlfn.XLOOKUP($A18, DailyData!$A$2:$A$2516, DailyData!J$2:J$2516, " ") -> 1020.11 | I18: =_xlfn.XLOOKUP($A18, DailyData!$A$2:$A$2516, DailyData!K$2:K$2516, " ") -> 520.34 | J18: =_xlfn.XLOOKUP($A18, DailyData!$A$2:$A$2516, DailyData!L$2:L$2516, " ") -> 147.15 | K18: =_xlfn.XLOOKUP($A18, DailyData!$A$2:$A$2516, DailyData!M$2:M$2516, " ") -> 42
A19: 45597 | B19: =_xlfn.XLOOKUP(A19, DailyData!$A$2:$A$2516, DailyData!$D$2:$D$2516, " ") -> 571.04 | C19: =_xlfn.XLOOKUP($A19, DailyData!$A$2:$A$2516, DailyData!$E$2:$E$2516, " ") -> 218.98 | D19: =_xlfn.XLOOKUP($A19, DailyData!$A$2:$A$2516, DailyData!F$2:F$2516, " ") -> 90.84 | E19: =_xlfn.XLOOKUP($A19, DailyData!$A$2:$A$2516, DailyData!G$2:G$2516, " ") -> 252.47 | F19: =_xlfn.XLOOKUP($A19, DailyData!$A$2:$A$2516, DailyData!H$2:H$2516, " ") -> 93.11 | G19: =_xlfn.XLOOKUP($A19, DailyData!$A$2:$A$2516, DailyData!I$2:I$2516, " ") -> 170.02 | H19: =_xlfn.XLOOKUP($A19, DailyData!$A$2:$A$2516, DailyData!J$2:J$2516, " ") -> 985.08 | I19: =_xlfn.XLOOKUP($A19, DailyData!$A$2:$A$2516, DailyData!K$2:K$2516, " ") -> 545.35 | J19: =_xlfn.XLOOKUP($A19, DailyData!$A$2:$A$2516, DailyData!L$2:L$2516, " ") -> 147.74 | K19: =_xlfn.XLOOKUP($A19, DailyData!$A$2:$A$2516, DailyData!M$2:M$2516, " ") -> 26.05
... A128: 42303 | B128: =_xlfn.XLOOKUP(A128, DailyData!$A$2:$A$2516, DailyData!$D$2:$D$2516, " ") -> 207 | C128: =_xlfn.XLOOKUP($A128, DailyData!$A$2:$A$2516, DailyData!$E$2:$E$2516, " ") -> 115.06 | D128: =_xlfn.XLOOKUP($A128, DailyData!$A$2:$A$2516, DailyData!F$2:F$2516, " ") -> 124.02 | E128: =_xlfn.XLOOKUP($A128, DailyData!$A$2:$A$2516, DailyData!G$2:G$2516, " ") -> 111.43 | F128: =_xlfn.XLOOKUP($A128, DailyData!$A$2:$A$2516, DailyData!H$2:H$2516, " ") -> 80.7 | G128: =_xlfn.XLOOKUP($A128, DailyData!$A$2:$A$2516, DailyData!I$2:I$2516, " ") -> 38.37 | H128: =_xlfn.XLOOKUP($A128, DailyData!$A$2:$A$2516, DailyData!J$2:J$2516, " ") -> 337.02 | I128: =_xlfn.XLOOKUP($A128, DailyData!$A$2:$A$2516, DailyData!K$2:K$2516, " ") -> 220.94 | J128: =_xlfn.XLOOKUP($A128, DailyData!$A$2:$A$2516, DailyData!L$2:L$2516, " ") -> 69.6 | K128: =_xlfn.XLOOKUP($A128, DailyData!$A$2:$A$2516, DailyData!M$2:M$2516, " ") -> 2.76

Sheet Returns
A1: ='Monthly Returns'!A7 -> Dates | B1: ='Monthly Returns'!B2 -> SPY | C1: ='Monthly Returns'!C2 -> IWM | D1: ='Monthly Returns'!D2 -> TLT | E1: ='Monthly Returns'!E2 -> GLD | F1: ='Monthly Returns'!F2 -> VNQ | G1: ='Monthly Returns'!G2 -> ORCL | H1: ='Monthly Returns'!H2 -> BLK | I1: ='Monthly Returns'!I2 -> LMT | ... K1: ='Monthly Returns'!K2 -> SMCI
A2: ='Monthly Returns'!A8 -> 45931 | B2: =LN('Monthly Returns'!B9/'Monthly Returns'!B8) -> -0.043071637 | C2: =LN('Monthly Returns'!C9/'Monthly Returns'!C8) -> -0.036066799 | D2: =LN('Monthly Returns'!D9/'Monthly Returns'!D8) -> -0.04185381 | E2: =LN('Monthly Returns'!E9/'Monthly Returns'!E8) -> -0.089376076 | F2: =LN('Monthly Returns'!F9/'Monthly Returns'!F8) -> -0.0093268905 | G2: =LN('Monthly Returns'!G9/'Monthly Returns'!G8) -> -0.24902844 | H2: =LN('Monthly Returns'!H9/'Monthly Returns'!H8) -> -0.023318313 | I2: =LN('Monthly Returns'!I9/'Monthly Returns'!I8) -> -0.097818333 | ... K2: =LN('Monthly Returns'!K9/'Monthly Returns'!K8) -> -0.25052397
A3: ='Monthly Returns'!A9 -> 45902 | B3: =LN('Monthly Returns'!B10/'Monthly Returns'!B9) -> -0.029400132 | C3: =LN('Monthly Returns'!C10/'Monthly Returns'!C9) -> -0.084627808 | D3: =LN('Monthly Returns'!D10/'Monthly Returns'!D9) -> 0.025253576 | E3: =LN('Monthly Returns'!E10/'Monthly Returns'!E9) -> -0.051941721 | F3: =LN('Monthly Returns'!F10/'Monthly Returns'!F9) -> -0.019930516 | G3: =LN('Monthly Returns'!G10/'Monthly Returns'!G9) -> 0.08145521 | H3: =LN('Monthly Returns'!H10/'Monthly Returns'!H9) -> -0.020820395 | I3: =LN('Monthly Returns'!I10/'Monthly Returns'!I9) -> -0.072131177 | ... K3: =LN('Monthly Returns'!K10/'Monthly Returns'!K9) -> 0.32852368
A4: ='Monthly Returns'!A10 -> 45870 | B4: =LN('Monthly Returns'!B11/'Monthly Returns'!B10) -> -0.0065678766 | C4: =LN('Monthly Returns'!C11/'Monthly Returns'!C10) -> 0.014275067 | D4: =LN('Monthly Returns'!D11/'Monthly Returns'!D10) -> 0.0036371943 | E4: =LN('Monthly Returns'!E11/'Monthly Returns'!E10) -> -0.005059525 | F4: =LN('Monthly Returns'!F11/'Monthly Returns'!F10) -> 0.0088451565 | G4: =LN('Monthly Returns'!G11/'Monthly Returns'!G10) -> -0.10999899 | H4: =LN('Monthly Returns'!H11/'Monthly Returns'!H10) -> -0.034979126 | I4: =LN('Monthly Returns'!I11/'Monthly Returns'!I10) -> 0.10140028 | ... K4: =LN('Monthly Returns'!K11/'Monthly Returns'!K10) -> -0.18232156
A5: ='Monthly Returns'!A11 -> 45839 | B5: =LN('Monthly Returns'!B12/'Monthly Returns'!B11) -> -0.041216713 | C5: =LN('Monthly Returns'!C12/'Monthly Returns'!C11) -> -0.058073523 | D5: =LN('Monthly Returns'!D12/'Monthly Returns'!D11) -> -0.034394619 | E5: =LN('Monthly Returns'!E12/'Monthly Returns'!E11) -> 0.01330726 | F5: =LN('Monthly Returns'!F12/'Monthly Returns'!F11) -> -0.0030142362 | G5: =LN('Monthly Returns'!G12/'Monthly Returns'!G11) -> -0.27347342 | H5: =LN('Monthly Returns'!H12/'Monthly Returns'!H11) -> -0.075022621 | I5: =LN('Monthly Returns'!I12/'Monthly Returns'!I11) -> 0.027267873 | ... K5: =LN('Monthly Returns'!K12/'Monthly Returns'!K11) -> -0.13595564
A6: ='Monthly Returns'!A12 -> 45810 | B6: =LN('Monthly Returns'!B13/'Monthly Returns'!B12) -> -0.059504339 | C6: =LN('Monthly Returns'!C13/'Monthly Returns'!C12) -> -0.047995672 | D6: =LN('Monthly Returns'!D13/'Monthly Returns'!D12) -> 0.040615303 | E6: =LN('Monthly Returns'!E13/'Monthly Returns'!E12) -> -0.046665174 | F6: =LN('Monthly Returns'!F13/'Monthly Returns'!F12) -> -0.0092104436 | G6: =LN('Monthly Returns'!G13/'Monthly Returns'!G12) -> -0.13530829 | H6: =LN('Monthly Returns'!H13/'Monthly Returns'!H12) -> -0.065412051 | I6: =LN('Monthly Returns'!I13/'Monthly Returns'!I12) -> -0.0022999571 | ... K6: =LN('Monthly Returns'!K13/'Monthly Returns'!K12) -> -0.23014617
A7: ='Monthly Returns'!A13 -> 45778 | B7: =LN('Monthly Returns'!B14/'Monthly Returns'!B13) -> 0.0044665264 | C7: =LN('Monthly Returns'!C14/'Monthly Returns'!C13) -> 0.017392622 | D7: =LN('Monthly Returns'!D14/'Monthly Returns'!D13) -> 0.031082533 | E7: =LN('Monthly Returns'!E14/'Monthly Returns'!E13) -> -0.033813453 | F7: =LN('Monthly Returns'!F14/'Monthly Returns'!F13) -> 0.021875872 | G7: =LN('Monthly Returns'!G14/'Monthly Returns'!G13) -> -0.024702923 | H7: =LN('Monthly Returns'!H14/'Monthly Returns'!H13) -> 0.030041717 | I7: =LN('Monthly Returns'!I14/'Monthly Returns'!I13) -> -0.062804002 | ... K7: =LN('Monthly Returns'!K14/'Monthly Returns'!K13) -> 0.068483525
A8: ='Monthly Returns'!A14 -> 45748 | B8: =LN('Monthly Returns'!B15/'Monthly Returns'!B14) -> 0.039839641 | C8: =LN('Monthly Returns'!C15/'Monthly Returns'!C14) -> 0.045416706 | D8: =LN('Monthly Returns'!D15/'Monthly Returns'!D14) -> 0.011735438 | E8: =LN('Monthly Returns'!E15/'Monthly Returns'!E14) -> -0.075191908 | F8: =LN('Monthly Returns'!F15/'Monthly Returns'!F14) -> 0.04067184 | G8: =LN('Monthly Returns'!G15/'Monthly Returns'!G14) -> 0.13231535 | H8: =LN('Monthly Returns'!H15/'Monthly Returns'!H14) -> 0.02343935 | I8: =LN('Monthly Returns'!I15/'Monthly Returns'!I14) -> 0.0073286433 | ... K8: =LN('Monthly Returns'!K15/'Monthly Returns'!K14) -> 0.028685881
A9: ='Monthly Returns'!A15 -> 45719 | B9: =LN('Monthly Returns'!B16/'Monthly Returns'!B15) -> 0.023698995 | C9: =LN('Monthly Returns'!C16/'Monthly Returns'!C15) -> 0.069605769 | D9: =LN('Monthly Returns'!D16/'Monthly Returns'!D15) -> -0.04881177 | E9: =LN('Monthly Returns'!E16/'Monthly Returns'!E15) -> -0.025823566 | F9: =LN('Monthly Returns'!F16/'Monthly Returns'!F15) -> -0.043103586 | G9: =LN('Monthly Returns'!G16/'Monthly Returns'!G15) -> 0.039809261 | H9: =LN('Monthly Returns'!H16/'Monthly Returns'!H15) -> 0.047761347 | I9: =LN('Monthly Returns'!I16/'Monthly Returns'!I15) -> 0.0076706424 | ... K9: =LN('Monthly Returns'!K16/'Monthly Returns'!K15) -> -0.29519567
A10: ='Monthly Returns'!A16 -> 45691 | B10: =LN('Monthly Returns'!B17/'Monthly Returns'!B16) -> -0.022209791 | C10: =LN('Monthly Returns'!C17/'Monthly Returns'!C16) -> -0.01209085 | D10: =LN('Monthly Returns'!D17/'Monthly Returns'!D16) -> -0.0067148719 | E10: =LN('Monthly Returns'!E17/'Monthly Returns'!E16) -> -0.057479807 | F10: =LN('Monthly Returns'!F17/'Monthly Returns'!F16) -> -0.023174841 | G10: =LN('Monthly Returns'!G17/'Monthly Returns'!G16) -> -0.015360551 | H10: =LN('Monthly Returns'!H17/'Monthly Returns'!H16) -> 0.003594027 | I10: =LN('Monthly Returns'!I17/'Monthly Returns'!I16) -> 0.057242582 | ... K10: =LN('Monthly Returns'!K17/'Monthly Returns'!K16) -> 0.11259684
A11: ='Monthly Returns'!A17 -> 45659 | B11: =LN('Monthly Returns'!B18/'Monthly Returns'!B17) -> 0.031965154 | C11: =LN('Monthly Returns'!C18/'Monthly Returns'!C17) -> 0.089108149 | D11: =LN('Monthly Returns'!D18/'Monthly Returns'!D17) -> 0.069472373 | E11: =LN('Monthly Returns'!E18/'Monthly Returns'!E17) -> -0.008100523 | F11: =LN('Monthly Returns'!F18/'Monthly Returns'!F17) -> 0.091296741 | G11: =LN('Monthly Returns'!G18/'Monthly Returns'!G17) -> 0.088591168 | H11: =LN('Monthly Returns'!H18/'Monthly Returns'!H17) -> 0.0026601112 | I11: =LN('Monthly Returns'!I18/'Monthly Returns'!I17) -> 0.076019792 | ... K11: =LN('Monthly Returns'!K18/'Monthly Returns'!K17) -> 0.33480696
A12: ='Monthly Returns'!A18 -> 45628 | B12: =LN('Monthly Returns'!B19/'Monthly Returns'!B18) -> -0.055502168 | C12: =LN('Monthly Returns'!C19/'Monthly Returns'!C18) -> -0.098923733 | D12: =LN('Monthly Returns'!D19/'Monthly Returns'!D18) -> -0.032811129 | E12: =LN('Monthly Returns'!E19/'Monthly Returns'!E18) -> 0.036421924 | F12: =LN('Monthly Returns'!F19/'Monthly Returns'!F18) -> -0.038142002 | G12: =LN('Monthly Returns'!G19/'Monthly Returns'!G18) -> -0.064843586 | H12: =LN('Monthly Returns'!H19/'Monthly Returns'!H18) -> -0.034942887 | I12: =LN('Monthly Returns'!I19/'Monthly Returns'!I18) -> 0.046945346 | ... K12: =LN('Monthly Returns'!K19/'Monthly Returns'!K18) -> -0.47765185
A13: ='Monthly Returns'!A19 -> 45597 | B13: =LN('Monthly Returns'!B20/'Monthly Returns'!B19) -> -0.004246887 | C13: =LN('Monthly Returns'!C20/'Monthly Returns'!C19) -> -0.0049900532 | D13: =LN('Monthly Returns'!D20/'Monthly Returns'!D19) -> 0.080855303 | E13: =LN('Monthly Returns'!E20/'Monthly Returns'!E19) -> -0.027547518 | F13: =LN('Monthly Returns'!F20/'Monthly Returns'!F19) -> 0.038762093 | G13: =LN('Monthly Returns'!G20/'Monthly Returns'!G19) -> -0.01696464 | H13: =LN('Monthly Returns'!H20/'Monthly Returns'!H19) -> -0.053225005 | I13: =LN('Monthly Returns'!I20/'Monthly Returns'!I19) -> 0.10522115 | ... K13: =LN('Monthly Returns'!K20/'Monthly Returns'!K19) -> 0.44251801
... A121: ='Monthly Returns'!A127 -> 42310 | B121: =LN('Monthly Returns'!B128/'Monthly Returns'!B127) -> -0.016244158 | C121: =LN('Monthly Returns'!C128/'Monthly Returns'!C127) -> -0.023025072 | D121: =LN('Monthly Returns'!D128/'Monthly Returns'!D127) -> 0.016831718 | E121: =LN('Monthly Returns'!E128/'Monthly Returns'!E127) -> 0.025817269 | F121: =LN('Monthly Returns'!F128/'Monthly Returns'!F127) -> -0.01096813 | G121: =LN('Monthly Returns'!G128/'Monthly Returns'!G127) -> -0.035333937 | H121: =LN('Monthly Returns'!H128/'Monthly Returns'!H127) -> -0.050763512 | I121: =LN('Monthly Returns'!I128/'Monthly Returns'!I127) -> 0.0015853966 | ... K121: =LN('Monthly Returns'!K128/'Monthly Returns'!K127) -> -0.073331273

Sheet Without Opinion
A1: Anticipated Benchmark Return | B1: 0.01 | C1: <-- Monthly Return
A2: Current T-Bill Rate (Risk Free Rate) | B2: 0.0034 | C2: <-- Monthly Risk Free Rate
A3: Annual Risk Free | B3: =(1+B2)^12-1 -> 0.041571673
A4: Normalizing Factor | B4: =(B1-B2)/B23 -> 2.6491306 | C4: =_xlfn.FORMULATEXT(B4) -> =(B1-B2)/B23
A6: Company Name | B6: ='Monthly Returns'!B1 -> S&P 500 | C6: ='Monthly Returns'!C1 -> iShares Russell | D6: ='Monthly Returns'!D1 -> iShares Yearly Bond | E6: ='Monthly Returns'!E1 -> SPDR Gold Shares | F6: ='Monthly Returns'!F1 -> Vanguard Real Estate | G6: ='Monthly Returns'!G1 -> Oracle | H6: ='Monthly Returns'!H1 -> BlackRock | I6: ='Monthly Returns'!I1 -> Lockheed Martin | ... K6: ='Monthly Returns'!K1 -> Super Micro Computer Inc
A7: Ticker | B7: ='Monthly Returns'!B2 -> SPY | C7: ='Monthly Returns'!C2 -> IWM | D7: ='Monthly Returns'!D2 -> TLT | E7: ='Monthly Returns'!E2 -> GLD | F7: ='Monthly Returns'!F2 -> VNQ | G7: ='Monthly Returns'!G2 -> ORCL | H7: ='Monthly Returns'!H2 -> BLK | I7: ='Monthly Returns'!I2 -> LMT | ... K7: ='Monthly Returns'!K2 -> SMCI
A8: Benchmark Porportion | B8: 0.29596523 | C8: 0.031645683 | D8: 0.025290445 | E8: 0.052249225 | F8: 0.013930673 | G8: 0.40802908 | H8: 0.089198566 | I8: 0.056922783 | J8: 0.012225058 | K8: 0.014543255 | L8: =SUM(B8:K8) -> 1
B10: =B7 -> SPY | C10: =C7 -> IWM | D10: =D7 -> TLT | E10: =E7 -> GLD | F10: =F7 -> VNQ | G10: =G7 -> ORCL | H10: =H7 -> BLK | I10: =I7 -> LMT | ... K10: =K7 -> SMCI | M10: ERNF | N10: <-- Expected Return with Normalizing Factor
A11: =B7 -> SPY | B11: =_xlfn.COVARIANCE.S(Returns!$B$2:$B$121, Returns!B2:B121) -> 0.0022056557 | C11: =_xlfn.COVARIANCE.S(Returns!$B$2:$B$121, Returns!C2:C121) -> 0.0027199974 | D11: =_xlfn.COVARIANCE.S(Returns!$B$2:$B$121, Returns!D2:D121) -> 6.8240104e-05 | E11: =_xlfn.COVARIANCE.S(Returns!$B$2:$B$121, Returns!E2:E121) -> 0.00016693638 | F11: =_xlfn.COVARIANCE.S(Returns!$B$2:$B$121, Returns!F2:F121) -> 0.0021814814 | G11: =_xlfn.COVARIANCE.S(Returns!$B$2:$B$121, Returns!G2:G121) -> 0.002062915 | H11: =_xlfn.COVARIANCE.S(Returns!$B$2:$B$121, Returns!H2:H121) -> 0.0027580522 | I11: =_xlfn.COVARIANCE.S(Returns!$B$2:$B$121, Returns!I2:I121) -> 0.0010096872 | ... K11: =_xlfn.COVARIANCE.S(Returns!$B$2:$B$121, Returns!K2:K121) -> 0.0031414557 | M11: {=MMULT(B11:K20, TRANSPOSE(B8:K8))*B4+B2} -> 0.0086704673
A12: =C7 -> IWM | B12: =_xlfn.COVARIANCE.S(Returns!$C$2:$C$121, Returns!B2:B121) -> 0.0027199974 | C12: =_xlfn.COVARIANCE.S(Returns!$C$2:$C$121, Returns!C2:C121) -> 0.0042486166 | D12: =_xlfn.COVARIANCE.S(Returns!$C$2:$C$121, Returns!D2:D121) -> -0.00016595087 | E12: =_xlfn.COVARIANCE.S(Returns!$C$2:$C$121, Returns!E2:E121) -> -9.9598455e-05 | F12: =_xlfn.COVARIANCE.S(Returns!$C$2:$C$121, Returns!F2:F121) -> 0.0029689796 | G12: =_xlfn.COVARIANCE.S(Returns!$C$2:$C$121, Returns!G2:G121) -> 0.0020477912 | H12: =_xlfn.COVARIANCE.S(Returns!$C$2:$C$121, Returns!H2:H121) -> 0.003651546 | I12: =_xlfn.COVARIANCE.S(Returns!$C$2:$C$121, Returns!I2:I121) -> 0.0013341125 | ... K12: =_xlfn.COVARIANCE.S(Returns!$C$2:$C$121, Returns!K2:K121) -> 0.0034162165 | M12: 0.0094457813
A13: =D7 -> TLT | B13: =_xlfn.COVARIANCE.S(Returns!$D$2:$D$121, Returns!B2:B121) -> 6.8240104e-05 | C13: =_xlfn.COVARIANCE.S(Returns!$D$2:$D$121, Returns!C2:C121) -> -0.00016595087 | D13: =_xlfn.COVARIANCE.S(Returns!$D$2:$D$121, Returns!D2:D121) -> 0.0016492006 | E13: =_xlfn.COVARIANCE.S(Returns!$D$2:$D$121, Returns!E2:E121) -> 0.00068595447 | F13: =_xlfn.COVARIANCE.S(Returns!$D$2:$D$121, Returns!F2:F121) -> 0.00054970908 | G13: =_xlfn.COVARIANCE.S(Returns!$D$2:$D$121, Returns!G2:G121) -> 0.00035741312 | H13: =_xlfn.COVARIANCE.S(Returns!$D$2:$D$121, Returns!H2:H121) -> 0.00018617315 | I13: =_xlfn.COVARIANCE.S(Returns!$D$2:$D$121, Returns!I2:I121) -> -5.8570588e-05 | ... K13: =_xlfn.COVARIANCE.S(Returns!$D$2:$D$121, Returns!K2:K121) -> 0.00053475321 | M13: 0.0041124285
A14: =E7 -> GLD | B14: =_xlfn.COVARIANCE.S(Returns!$E$2:$E$121, Returns!B2:B121) -> 0.00016693638 | C14: =_xlfn.COVARIANCE.S(Returns!$E$2:$E$121, Returns!C2:C121) -> -9.9598455e-05 | D14: =_xlfn.COVARIANCE.S(Returns!$E$2:$E$121, Returns!D2:D121) -> 0.00068595447 | E14: =_xlfn.COVARIANCE.S(Returns!$E$2:$E$121, Returns!E2:E121) -> 0.0016429594 | F14: =_xlfn.COVARIANCE.S(Returns!$E$2:$E$121, Returns!F2:F121) -> 0.00036976877 | G14: =_xlfn.COVARIANCE.S(Returns!$E$2:$E$121, Returns!G2:G121) -> 0.00027552442 | H14: =_xlfn.COVARIANCE.S(Returns!$E$2:$E$121, Returns!H2:H121) -> 0.00011273741 | I14: =_xlfn.COVARIANCE.S(Returns!$E$2:$E$121, Returns!I2:I121) -> 0.00050060632 | ... K14: =_xlfn.COVARIANCE.S(Returns!$E$2:$E$121, Returns!K2:K121) -> -0.00091667148 | M14: 0.0041794969
A15: =F7 -> VNQ | B15: =_xlfn.COVARIANCE.S(Returns!$F$2:$F$121, Returns!B2:B121) -> 0.0021814814 | C15: =_xlfn.COVARIANCE.S(Returns!$F$2:$F$121, Returns!C2:C121) -> 0.0029689796 | D15: =_xlfn.COVARIANCE.S(Returns!$F$2:$F$121, Returns!D2:D121) -> 0.00054970908 | E15: =_xlfn.COVARIANCE.S(Returns!$F$2:$F$121, Returns!E2:E121) -> 0.00036976877 | F15: =_xlfn.COVARIANCE.S(Returns!$F$2:$F$121, Returns!F2:F121) -> 0.0033430401 | G15: =_xlfn.COVARIANCE.S(Returns!$F$2:$F$121, Returns!G2:G121) -> 0.0015834079 | H15: =_xlfn.COVARIANCE.S(Returns!$F$2:$F$121, Returns!H2:H121) -> 0.0026768447 | I15: =_xlfn.COVARIANCE.S(Returns!$F$2:$F$121, Returns!I2:I121) -> 0.001129575 | ... K15: =_xlfn.COVARIANCE.S(Returns!$F$2:$F$121, Returns!K2:K121) -> 0.0019591618 | M15: 0.0082160429
A16: =G7 -> ORCL | B16: =_xlfn.COVARIANCE.S(Returns!$G$2:$G$121, Returns!B2:B121) -> 0.002062915 | C16: =_xlfn.COVARIANCE.S(Returns!$G$2:$G$121, Returns!C2:C121) -> 0.0020477912 | D16: =_xlfn.COVARIANCE.S(Returns!$G$2:$G$121, Returns!D2:D121) -> 0.00035741312 | E16: =_xlfn.COVARIANCE.S(Returns!$G$2:$G$121, Returns!E2:E121) -> 0.00027552442 | F16: =_xlfn.COVARIANCE.S(Returns!$G$2:$G$121, Returns!F2:F121) -> 0.0015834079 | G16: =_xlfn.COVARIANCE.S(Returns!$G$2:$G$121, Returns!G2:G121) -> 0.0056176054 | H16: =_xlfn.COVARIANCE.S(Returns!$G$2:$G$121, Returns!H2:H121) -> 0.0028941983 | I16: =_xlfn.COVARIANCE.S(Returns!$G$2:$G$121, Returns!I2:I121) -> 0.000997957 | ... K16: =_xlfn.COVARIANCE.S(Returns!$G$2:$G$121, Returns!K2:K121) -> 0.0052644773 | M16: 0.012461229
A17: =H7 -> BLK | B17: =_xlfn.COVARIANCE.S(Returns!$H$2:$H$121, Returns!B2:B121) -> 0.0027580522 | C17: =_xlfn.COVARIANCE.S(Returns!$H$2:$H$121, Returns!C2:C121) -> 0.003651546 | D17: =_xlfn.COVARIANCE.S(Returns!$H$2:$H$121, Returns!D2:D121) -> 0.00018617315 | E17: =_xlfn.COVARIANCE.S(Returns!$H$2:$H$121, Returns!E2:E121) -> 0.00011273741 | F17: =_xlfn.COVARIANCE.S(Returns!$H$2:$H$121, Returns!F2:F121) -> 0.0026768447 | G17: =_xlfn.COVARIANCE.S(Returns!$H$2:$H$121, Returns!G2:G121) -> 0.0028941983 | H17: =_xlfn.COVARIANCE.S(Returns!$H$2:$H$121, Returns!H2:H121) -> 0.005173536 | I17: =_xlfn.COVARIANCE.S(Returns!$H$2:$H$121, Returns!I2:I121) -> 0.001326265 | ... K17: =_xlfn.COVARIANCE.S(Returns!$H$2:$H$121, Returns!K2:K121) -> 0.0032541176 | M17: 0.010737679
A18: =I7 -> LMT | B18: =_xlfn.COVARIANCE.S(Returns!$I$2:$I$121, Returns!B2:B121) -> 0.0010096872 | C18: =_xlfn.COVARIANCE.S(Returns!$I$2:$I$121, Returns!C2:C121) -> 0.0013341125 | D18: =_xlfn.COVARIANCE.S(Returns!$I$2:$I$121, Returns!D2:D121) -> -5.8570588e-05 | E18: =_xlfn.COVARIANCE.S(Returns!$I$2:$I$121, Returns!E2:E121) -> 0.00050060632 | F18: =_xlfn.COVARIANCE.S(Returns!$I$2:$I$121, Returns!F2:F121) -> 0.001129575 | G18: =_xlfn.COVARIANCE.S(Returns!$I$2:$I$121, Returns!G2:G121) -> 0.000997957 | H18: =_xlfn.COVARIANCE.S(Returns!$I$2:$I$121, Returns!H2:H121) -> 0.001326265 | I18: =_xlfn.COVARIANCE.S(Returns!$I$2:$I$121, Returns!I2:I121) -> 0.0035456911 | ... K18: =_xlfn.COVARIANCE.S(Returns!$I$2:$I$121, Returns!K2:K121) -> 0.00073921441 | M18: 0.0064002826
A19: =J7 -> XLV | B19: =_xlfn.COVARIANCE.S(Returns!$J$2:$J$121, Returns!B2:B121) -> 0.001545371 | C19: =_xlfn.COVARIANCE.S(Returns!$J$2:$J$121, Returns!C2:C121) -> 0.0019506041 | D19: =_xlfn.COVARIANCE.S(Returns!$J$2:$J$121, Returns!D2:D121) -> 0.0001547872 | E19: =_xlfn.COVARIANCE.S(Returns!$J$2:$J$121, Returns!E2:E121) -> 0.00016406653 | F19: =_xlfn.COVARIANCE.S(Returns!$J$2:$J$121, Returns!F2:F121) -> 0.0017129906 | G19: =_xlfn.COVARIANCE.S(Returns!$J$2:$J$121, Returns!G2:G121) -> 0.0013032212 | H19: =_xlfn.COVARIANCE.S(Returns!$J$2:$J$121, Returns!H2:H121) -> 0.0020369971 | I19: =_xlfn.COVARIANCE.S(Returns!$J$2:$J$121, Returns!I2:I121) -> 0.0010645433 | ... K19: =_xlfn.COVARIANCE.S(Returns!$J$2:$J$121, Returns!K2:K121) -> 0.0013266617 | M19: 0.0070304331
A20: =K7 -> SMCI | B20: =_xlfn.COVARIANCE.S(Returns!$K$2:$K$121, Returns!B2:B121) -> 0.0031414557 | C20: =_xlfn.COVARIANCE.S(Returns!$K$2:$K$121, Returns!C2:C121) -> 0.0034162165 | D20: =_xlfn.COVARIANCE.S(Returns!$K$2:$K$121, Returns!D2:D121) -> 0.00053475321 | E20: =_xlfn.COVARIANCE.S(Returns!$K$2:$K$121, Returns!E2:E121) -> -0.00091667148 | F20: =_xlfn.COVARIANCE.S(Returns!$K$2:$K$121, Returns!F2:F121) -> 0.0019591618 | G20: =_xlfn.COVARIANCE.S(Returns!$K$2:$K$121, Returns!G2:G121) -> 0.0052644773 | H20: =_xlfn.COVARIANCE.S(Returns!$K$2:$K$121, Returns!H2:H121) -> 0.0032541176 | I20: =_xlfn.COVARIANCE.S(Returns!$K$2:$K$121, Returns!I2:I121) -> 0.00073921441 | ... K20: =_xlfn.COVARIANCE.S(Returns!$K$2:$K$121, Returns!K2:K121) -> 0.035950299 | M20: 0.014129628
A22: Average Return | B22: =AVERAGE(Returns!B2:B121) -> -0.0097686901 | C22: =AVERAGE(Returns!C2:C121) -> -0.0062125562 | D22: =AVERAGE(Returns!D2:D121) -> 0.0027379445 | E22: =AVERAGE(Returns!E2:E121) -> -0.0096801534 | F22: =AVERAGE(Returns!F2:F121) -> -0.0010521327 | G22: =AVERAGE(Returns!G2:G121) -> -0.016826545 | H22: =AVERAGE(Returns!H2:H121) -> -0.010163162 | I22: =AVERAGE(Returns!I2:I121) -> -0.006789291 | ... K22: =AVERAGE(Returns!K2:K121) -> -0.024529042 | M22: Check: Expected Return of Benchmark | O22: {=MMULT(B8:K8,_xlfn.ANCHORARRAY( M11))} -> 0.01
A23: Portfolio Variance | B23: {=MMULT(MMULT(B8:K8, B11:K20), TRANSPOSE(B8:K8))} -> 0.0024913834
A24: Portfolio Standard Dev/Month | B24: =SQRT(B23) -> 0.049913759
A25: Annualized Volatility | B25: =B24*SQRT(12) -> 0.17290633
A26: Expected Monthly Return | B26: =SUMPRODUCT(B8:K8, B22:K22) -> -0.012128136
A27: Expected Annual Return | B27: =(1+B26)^12 - 1 -> -0.13621155
A28: Sharpe Ratio | B28: =(B27-((1+(B3)^12-1))/B25) -> -0.13621155

Sheet With Opinion
A1: Anticpated Benchmark Return | B1: 0.01 | C1: <-- Monthly Return | M1: Anticpated Benchmark Return | N1: 0.01 | O1: <-- Monthly Return
A2: Current T-Bill Rate | B2: ='Without Opinion'!B2 -> 0.0034 | M2: Current T-Bill Rate | N2: 0.0034
A3: Annualized T-Bill Rate | B3: ='Without Opinion'!B3 -> 0.041571673 | M3: Annualized T-Bill Rate | N3: 0.0416
A4: Normalizing Factor | B4: {=(B1-B2)/MMULT(MMULT(B8:K8, B12:K21), TRANSPOSE(B8:K8))} -> 2.6491306 | M4: Normalizing Factor | N4: 2.6491306
A6: Company Name | B6: ='Monthly Returns'!B1 -> S&P 500 | C6: ='Monthly Returns'!C1 -> iShares Russell | D6: ='Monthly Returns'!D1 -> iShares Yearly Bond | E6: ='Monthly Returns'!E1 -> SPDR Gold Shares | F6: ='Monthly Returns'!F1 -> Vanguard Real Estate | G6: ='Monthly Returns'!G1 -> Oracle | H6: ='Monthly Returns'!H1 -> BlackRock | I6: ='Monthly Returns'!I1 -> Lockheed Martin | ... K6: ='Monthly Returns'!K1 -> Super Micro Computer Inc | M6: Company Name | N6: S&P 500 | O6: iShares Russell | P6: iShares Yearly Bond | Q6: SPDR Gold Shares | R6: Vanguard Real Estate | S6: Oracle | T6: BlackRock | U6: Lockheed Martin | V6: SPDR Select Sector Fund | W6: Super Micro Computer Inc
A7: Ticker | B7: ='Monthly Returns'!B2 -> SPY | C7: ='Monthly Returns'!C2 -> IWM | D7: ='Monthly Returns'!D2 -> TLT | E7: ='Monthly Returns'!E2 -> GLD | F7: ='Monthly Returns'!F2 -> VNQ | G7: ='Monthly Returns'!G2 -> ORCL | H7: ='Monthly Returns'!H2 -> BLK | I7: ='Monthly Returns'!I2 -> LMT | ... K7: ='Monthly Returns'!K2 -> SMCI | M7: Ticker | N7: SPY | O7: IWM | P7: TLT | Q7: GLD | R7: VNQ | S7: ORCL | T7: BLK | U7: LMT | V7: XLV | W7: SMCI
A8: Benchmark Porportion | B8: 0.29596523 | C8: 0.031645683 | D8: 0.025290445 | E8: 0.052249225 | F8: 0.013930673 | G8: 0.40802908 | H8: 0.089198566 | I8: 0.056922783 | J8: 0.012225058 | K8: 0.014543255 | M8: Benchmark Porportion | N8: 0.296 | O8: 0.0316 | P8: 0.0253 | Q8: 0.0522 | R8: 0.0139 | S8: 0.408 | T8: 0.0892 | U8: 0.0569 | V8: 0.0122 | W8: 0.0145
A10: Variance-Covariance Matrix | M10: Variance-Covariance Matrix
B11: ='Without Opinion'!B10 -> SPY | C11: ='Without Opinion'!C10 -> IWM | D11: ='Without Opinion'!D10 -> TLT | E11: ='Without Opinion'!E10 -> GLD | F11: ='Without Opinion'!F10 -> VNQ | G11: ='Without Opinion'!G10 -> ORCL | H11: ='Without Opinion'!H10 -> BLK | I11: ='Without Opinion'!I10 -> LMT | ... K11: ='Without Opinion'!K10 -> SMCI | N11: SPY | O11: IWM | P11: TLT | Q11: GLD | R11: VNQ | S11: ORCL | T11: BLK | U11: LMT | V11: XLV | W11: SMCI
A12: ='Without Opinion'!A11 -> SPY | B12: =_xlfn.COVARIANCE.S(Returns!$B$2:$B$121, Returns!B2:B121) -> 0.0022056557 | C12: =_xlfn.COVARIANCE.S(Returns!$B$2:$B$121, Returns!C2:C121) -> 0.0027199974 | D12: =_xlfn.COVARIANCE.S(Returns!$B$2:$B$121, Returns!D2:D121) -> 6.8240104e-05 | E12: =_xlfn.COVARIANCE.S(Returns!$B$2:$B$121, Returns!E2:E121) -> 0.00016693638 | F12: =_xlfn.COVARIANCE.S(Returns!$B$2:$B$121, Returns!F2:F121) -> 0.0021814814 | G12: =_xlfn.COVARIANCE.S(Returns!$B$2:$B$121, Returns!G2:G121) -> 0.002062915 | H12: =_xlfn.COVARIANCE.S(Returns!$B$2:$B$121, Returns!H2:H121) -> 0.0027580522 | I12: =_xlfn.COVARIANCE.S(Returns!$B$2:$B$121, Returns!I2:I121) -> 0.0010096872 | ... K12: =_xlfn.COVARIANCE.S(Returns!$B$2:$B$121, Returns!K2:K121) -> 0.0031414557 | M12: SPY | N12: 0.002205656 | O12: 0.002719997 | P12: 6.82401e-05 | Q12: 0.000166936 | R12: 0.002181481 | S12: 0.002062915 | T12: 0.002758052 | U12: 0.001009687 | V12: 0.001545371 | W12: 0.003141456
A13: ='Without Opinion'!A12 -> IWM | B13: =_xlfn.COVARIANCE.S(Returns!$C$2:$C$121, Returns!B2:B121) -> 0.0027199974 | C13: =_xlfn.COVARIANCE.S(Returns!$C$2:$C$121, Returns!C2:C121) -> 0.0042486166 | D13: =_xlfn.COVARIANCE.S(Returns!$C$2:$C$121, Returns!D2:D121) -> -0.00016595087 | E13: =_xlfn.COVARIANCE.S(Returns!$C$2:$C$121, Returns!E2:E121) -> -9.9598455e-05 | F13: =_xlfn.COVARIANCE.S(Returns!$C$2:$C$121, Returns!F2:F121) -> 0.0029689796 | G13: =_xlfn.COVARIANCE.S(Returns!$C$2:$C$121, Returns!G2:G121) -> 0.0020477912 | H13: =_xlfn.COVARIANCE.S(Returns!$C$2:$C$121, Returns!H2:H121) -> 0.003651546 | I13: =_xlfn.COVARIANCE.S(Returns!$C$2:$C$121, Returns!I2:I121) -> 0.0013341125 | ... K13: =_xlfn.COVARIANCE.S(Returns!$C$2:$C$121, Returns!K2:K121) -> 0.0034162165 | M13: IWM | N13: 0.002719997 | O13: 0.004248617 | P13: -0.000165951 | Q13: -9.95985e-05 | R13: 0.00296898 | S13: 0.002047791 | T13: 0.003651546 | U13: 0.001334112 | V13: 0.001950604 | W13: 0.003416216
A14: ='Without Opinion'!A13 -> TLT | B14: =_xlfn.COVARIANCE.S(Returns!$D$2:$D$121, Returns!B2:B121) -> 6.8240104e-05 | C14: =_xlfn.COVARIANCE.S(Returns!$D$2:$D$121, Returns!C2:C121) -> -0.00016595087 | D14: =_xlfn.COVARIANCE.S(Returns!$D$2:$D$121, Returns!D2:D121) -> 0.0016492006 | E14: =_xlfn.COVARIANCE.S(Returns!$D$2:$D$121, Returns!E2:E121) -> 0.00068595447 | F14: =_xlfn.COVARIANCE.S(Returns!$D$2:$D$121, Returns!F2:F121) -> 0.00054970908 | G14: =_xlfn.COVARIANCE.S(Returns!$D$2:$D$121, Returns!G2:G121) -> 0.00035741312 | H14: =_xlfn.COVARIANCE.S(Returns!$D$2:$D$121, Returns!H2:H121) -> 0.00018617315 | I14: =_xlfn.COVARIANCE.S(Returns!$D$2:$D$121, Returns!I2:I121) -> -5.8570588e-05 | ... K14: =_xlfn.COVARIANCE.S(Returns!$D$2:$D$121, Returns!K2:K121) -> 0.00053475321 | M14: TLT | N14: 6.82401e-05 | O14: -0.000165951 | P14: 0.001649201 | Q14: 0.000685954 | R14: 0.000549709 | S14: 0.000357413 | T14: 0.000186173 | U14: -5.85706e-05 | V14: 0.000154787 | W14: 0.000534753
A15: ='Without Opinion'!A14 -> GLD | B15: =_xlfn.COVARIANCE.S(Returns!$E$2:$E$121, Returns!B2:B121) -> 0.00016693638 | C15: =_xlfn.COVARIANCE.S(Returns!$E$2:$E$121, Returns!C2:C121) -> -9.9598455e-05 | D15: =_xlfn.COVARIANCE.S(Returns!$E$2:$E$121, Returns!D2:D121) -> 0.00068595447 | E15: =_xlfn.COVARIANCE.S(Returns!$E$2:$E$121, Returns!E2:E121) -> 0.0016429594 | F15: =_xlfn.COVARIANCE.S(Returns!$E$2:$E$121, Returns!F2:F121) -> 0.00036976877 | G15: =_xlfn.COVARIANCE.S(Returns!$E$2:$E$121, Returns!G2:G121) -> 0.00027552442 | H15: =_xlfn.COVARIANCE.S(Returns!$E$2:$E$121, Returns!H2:H121) -> 0.00011273741 | I15: =_xlfn.COVARIANCE.S(Returns!$E$2:$E$121, Returns!I2:I121) -> 0.00050060632 | ... K15: =_xlfn.COVARIANCE.S(Returns!$E$2:$E$121, Returns!K2:K121) -> -0.00091667148 | M15: GLD | N15: 0.000166936 | O15: -9.95985e-05 | P15: 0.000685954 | Q15: 0.001642959 | R15: 0.000369769 | S15: 0.000275524 | T15: 0.000112737 | U15: 0.000500606 | V15: 0.000164067 | W15: -0.000916671
A16: ='Without Opinion'!A15 -> VNQ | B16: =_xlfn.COVARIANCE.S(Returns!$F$2:$F$121, Returns!B2:B121) -> 0.0021814814 | C16: =_xlfn.COVARIANCE.S(Returns!$F$2:$F$121, Returns!C2:C121) -> 0.0029689796 | D16: =_xlfn.COVARIANCE.S(Returns!$F$2:$F$121, Returns!D2:D121) -> 0.00054970908 | E16: =_xlfn.COVARIANCE.S(Returns!$F$2:$F$121, Returns!E2:E121) -> 0.00036976877 | F16: =_xlfn.COVARIANCE.S(Returns!$F$2:$F$121, Returns!F2:F121) -> 0.0033430401 | G16: =_xlfn.COVARIANCE.S(Returns!$F$2:$F$121, Returns!G2:G121) -> 0.0015834079 | H16: =_xlfn.COVARIANCE.S(Returns!$F$2:$F$121, Returns!H2:H121) -> 0.0026768447 | I16: =_xlfn.COVARIANCE.S(Returns!$F$2:$F$121, Returns!I2:I121) -> 0.001129575 | ... K16: =_xlfn.COVARIANCE.S(Returns!$F$2:$F$121, Returns!K2:K121) -> 0.0019591618 | M16: VNQ | N16: 0.002181481 | O16: 0.00296898 | P16: 0.000549709 | Q16: 0.000369769 | R16: 0.00334304 | S16: 0.001583408 | T16: 0.002676845 | U16: 0.001129575 | V16: 0.001712991 | W16: 0.001959162
A17: ='Without Opinion'!A16 -> ORCL | B17: =_xlfn.COVARIANCE.S(Returns!$G$2:$G$121, Returns!B2:B121) -> 0.002062915 | C17: =_xlfn.COVARIANCE.S(Returns!$G$2:$G$121, Returns!C2:C121) -> 0.0020477912 | D17: =_xlfn.COVARIANCE.S(Returns!$G$2:$G$121, Returns!D2:D121) -> 0.00035741312 | E17: =_xlfn.COVARIANCE.S(Returns!$G$2:$G$121, Returns!E2:E121) -> 0.00027552442 | F17: =_xlfn.COVARIANCE.S(Returns!$G$2:$G$121, Returns!F2:F121) -> 0.0015834079 | G17: =_xlfn.COVARIANCE.S(Returns!$G$2:$G$121, Returns!G2:G121) -> 0.0056176054 | H17: =_xlfn.COVARIANCE.S(Returns!$G$2:$G$121, Returns!H2:H121) -> 0.0028941983 | I17: =_xlfn.COVARIANCE.S(Returns!$G$2:$G$121, Returns!I2:I121) -> 0.000997957 | ... K17: =_xlfn.COVARIANCE.S(Returns!$G$2:$G$121, Returns!K2:K121) -> 0.0052644773 | M17: ORCL | N17: 0.002062915 | O17: 0.002047791 | P17: 0.000357413 | Q17: 0.000275524 | R17: 0.001583408 | S17: 0.005617605 | T17: 0.002894198 | U17: 0.000997957 | V17: 0.001303221 | W17: 0.005264477
A18: ='Without Opinion'!A17 -> BLK | B18: =_xlfn.COVARIANCE.S(Returns!$H$2:$H$121, Returns!B2:B121) -> 0.0027580522 | C18: =_xlfn.COVARIANCE.S(Returns!$H$2:$H$121, Returns!C2:C121) -> 0.003651546 | D18: =_xlfn.COVARIANCE.S(Returns!$H$2:$H$121, Returns!D2:D121) -> 0.00018617315 | E18: =_xlfn.COVARIANCE.S(Returns!$H$2:$H$121, Returns!E2:E121) -> 0.00011273741 | F18: =_xlfn.COVARIANCE.S(Returns!$H$2:$H$121, Returns!F2:F121) -> 0.0026768447 | G18: =_xlfn.COVARIANCE.S(Returns!$H$2:$H$121, Returns!G2:G121) -> 0.0028941983 | H18: =_xlfn.COVARIANCE.S(Returns!$H$2:$H$121, Returns!H2:H121) -> 0.005173536 | I18: =_xlfn.COVARIANCE.S(Returns!$H$2:$H$121, Returns!I2:I121) -> 0.001326265 | ... K18: =_xlfn.COVARIANCE.S(Returns!$H$2:$H$121, Returns!K2:K121) -> 0.0032541176 | M18: BLK | N18: 0.002758052 | O18: 0.003651546 | P18: 0.000186173 | Q18: 0.000112737 | R18: 0.002676845 | S18: 0.002894198 | T18: 0.005173536 | U18: 0.001326265 | V18: 0.002036997 | W18: 0.003254118
A19: ='Without Opinion'!A18 -> LMT | B19: =_xlfn.COVARIANCE.S(Returns!$I$2:$I$121, Returns!B2:B121) -> 0.0010096872 | C19: =_xlfn.COVARIANCE.S(Returns!$I$2:$I$121, Returns!C2:C121) -> 0.0013341125 | D19: =_xlfn.COVARIANCE.S(Returns!$I$2:$I$121, Returns!D2:D121) -> -5.8570588e-05 | E19: =_xlfn.COVARIANCE.S(Returns!$I$2:$I$121, Returns!E2:E121) -> 0.00050060632 | F19: =_xlfn.COVARIANCE.S(Returns!$I$2:$I$121, Returns!F2:F121) -> 0.001129575 | G19: =_xlfn.COVARIANCE.S(Returns!$I$2:$I$121, Returns!G2:G121) -> 0.000997957 | H19: =_xlfn.COVARIANCE.S(Returns!$I$2:$I$121, Returns!H2:H121) -> 0.001326265 | I19: =_xlfn.COVARIANCE.S(Returns!$I$2:$I$121, Returns!I2:I121) -> 0.0035456911 | ... K19: =_xlfn.COVARIANCE.S(Returns!$I$2:$I$121, Returns!K2:K121) -> 0.00073921441 | M19: LMT | N19: 0.001009687 | O19: 0.001334112 | P19: -5.85706e-05 | Q19: 0.000500606 | R19: 0.001129575 | S19: 0.000997957 | T19: 0.001326265 | U19: 0.003545691 | V19: 0.001064543 | W19: 0.000739214
A20: ='Without Opinion'!A19 -> XLV | B20: =_xlfn.COVARIANCE.S(Returns!$J$2:$J$121, Returns!B2:B121) -> 0.001545371 | C20: =_xlfn.COVARIANCE.S(Returns!$J$2:$J$121, Returns!C2:C121) -> 0.0019506041 | D20: =_xlfn.COVARIANCE.S(Returns!$J$2:$J$121, Returns!D2:D121) -> 0.0001547872 | E20: =_xlfn.COVARIANCE.S(Returns!$J$2:$J$121, Returns!E2:E121) -> 0.00016406653 | F20: =_xlfn.COVARIANCE.S(Returns!$J$2:$J$121, Returns!F2:F121) -> 0.0017129906 | G20: =_xlfn.COVARIANCE.S(Returns!$J$2:$J$121, Returns!G2:G121) -> 0.0013032212 | H20: =_xlfn.COVARIANCE.S(Returns!$J$2:$J$121, Returns!H2:H121) -> 0.0020369971 | I20: =_xlfn.COVARIANCE.S(Returns!$J$2:$J$121, Returns!I2:I121) -> 0.0010645433 | ... K20: =_xlfn.COVARIANCE.S(Returns!$J$2:$J$121, Returns!K2:K121) -> 0.0013266617 | M20: XLV | N20: 0.001545371 | O20: 0.001950604 | P20: 0.000154787 | Q20: 0.000164067 | R20: 0.001712991 | S20: 0.001303221 | T20: 0.002036997 | U20: 0.001064543 | V20: 0.001769303 | W20: 0.001326662
A21: ='Without Opinion'!A20 -> SMCI | B21: =_xlfn.COVARIANCE.S(Returns!$K$2:$K$121, Returns!B2:B121) -> 0.0031414557 | C21: =_xlfn.COVARIANCE.S(Returns!$K$2:$K$121, Returns!C2:C121) -> 0.0034162165 | D21: =_xlfn.COVARIANCE.S(Returns!$K$2:$K$121, Returns!D2:D121) -> 0.00053475321 | E21: =_xlfn.COVARIANCE.S(Returns!$K$2:$K$121, Returns!E2:E121) -> -0.00091667148 | F21: =_xlfn.COVARIANCE.S(Returns!$K$2:$K$121, Returns!F2:F121) -> 0.0019591618 | G21: =_xlfn.COVARIANCE.S(Returns!$K$2:$K$121, Returns!G2:G121) -> 0.0052644773 | H21: =_xlfn.COVARIANCE.S(Returns!$K$2:$K$121, Returns!H2:H121) -> 0.0032541176 | I21: =_xlfn.COVARIANCE.S(Returns!$K$2:$K$121, Returns!I2:I121) -> 0.00073921441 | ... K21: =_xlfn.COVARIANCE.S(Returns!$K$2:$K$121, Returns!K2:K121) -> 0.035950299 | M21: SMCI | N21: 0.003141456 | O21: 0.003416216 | P21: 0.000534753 | Q21: -0.000916671 | R21: 0.001959162 | S21: 0.005264477 | T21: 0.003254118 | U21: 0.000739214 | V21: 0.001326662 | W21: 0.035950299
A23: BL Tracking Matrix | M23: BL Tracking Matrix
B24: SPY | C24: IWM | D24: TLT | E24: GLD | F24: VNQ | G24: ORCL | H24: BLK | I24: LMT | J24: XLV | K24: SMCI | N24: SPY | O24: IWM | P24: TLT | Q24: GLD | R24: VNQ | S24: ORCL | T24: BLK | U24: LMT | V24: XLV | W24: SMCI
A25: SPY | B25: =B12/(_xlfn.VAR.S(Returns!B$2:B$121)) -> 1 | C25: =C12/(_xlfn.VAR.S(Returns!C$2:C$121)) -> 0.64020779 | D25: =D12/(_xlfn.VAR.S(Returns!D$2:D$121)) -> 0.041377686 | E25: =E12/(_xlfn.VAR.S(Returns!E$2:E$121)) -> 0.10160712 | F25: =F12/(_xlfn.VAR.S(Returns!F$2:F$121)) -> 0.6525442 | G25: =G12/(_xlfn.VAR.S(Returns!G$2:G$121)) -> 0.3672232 | H25: =H12/(_xlfn.VAR.S(Returns!H$2:H$121)) -> 0.53310777 | I25: =I12/(_xlfn.VAR.S(Returns!I$2:I$121)) -> 0.28476456 | ... K25: =K12/(_xlfn.VAR.S(Returns!K$2:K$121)) -> 0.087383298 | M25: SPY | N25: 1 | O25: 0.64 | P25: 0.04 | Q25: 0.1 | R25: 0.65 | S25: 0.37 | T25: 0.53 | U25: 0.28 | V25: 0.87 | W25: 0.09
A26: IWM | B26: =B13/(_xlfn.VAR.S(Returns!B$2:B$121)) -> 1.2331922 | C26: =C13/(_xlfn.VAR.S(Returns!C$2:C$121)) -> 1 | D26: =D13/(_xlfn.VAR.S(Returns!D$2:D$121)) -> -0.10062503 | E26: =E13/(_xlfn.VAR.S(Returns!E$2:E$121)) -> -0.060621372 | F26: =F13/(_xlfn.VAR.S(Returns!F$2:F$121)) -> 0.88810769 | G26: =G13/(_xlfn.VAR.S(Returns!G$2:G$121)) -> 0.36453099 | H26: =H13/(_xlfn.VAR.S(Returns!H$2:H$121)) -> 0.70581243 | I26: =I13/(_xlfn.VAR.S(Returns!I$2:I$121)) -> 0.37626303 | ... K26: =K13/(_xlfn.VAR.S(Returns!K$2:K$121)) -> 0.095026093 | M26: IWM | N26: 1.23 | O26: 1 | P26: -0.1 | Q26: -0.06 | R26: 0.89 | S26: 0.36 | T26: 0.71 | U26: 0.38 | V26: 1.1 | W26: 0.1
A27: TLT | B27: =B14/(_xlfn.VAR.S(Returns!B$2:B$121)) -> 0.030938693 | C27: =C14/(_xlfn.VAR.S(Returns!C$2:C$121)) -> -0.039059978 | D27: =D14/(_xlfn.VAR.S(Returns!D$2:D$121)) -> 1 | E27: =E14/(_xlfn.VAR.S(Returns!E$2:E$121)) -> 0.4175115 | F27: =F14/(_xlfn.VAR.S(Returns!F$2:F$121)) -> 0.16443389 | G27: =G14/(_xlfn.VAR.S(Returns!G$2:G$121)) -> 0.06362375 | H27: =H14/(_xlfn.VAR.S(Returns!H$2:H$121)) -> 0.035985668 | I27: =I14/(_xlfn.VAR.S(Returns!I$2:I$121)) -> -0.016518807 | ... K27: =K14/(_xlfn.VAR.S(Returns!K$2:K$121)) -> 0.014874792 | M27: TLT | N27: 0.03 | O27: -0.04 | P27: 1 | Q27: 0.42 | R27: 0.16 | S27: 0.06 | T27: 0.04 | U27: -0.02 | V27: 0.09 | W27: 0.01
A28: GLD | B28: =B15/(_xlfn.VAR.S(Returns!B$2:B$121)) -> 0.075685602 | C28: =C15/(_xlfn.VAR.S(Returns!C$2:C$121)) -> -0.023442561 | D28: =D15/(_xlfn.VAR.S(Returns!D$2:D$121)) -> 0.41593149 | E28: =E15/(_xlfn.VAR.S(Returns!E$2:E$121)) -> 1 | F28: =F15/(_xlfn.VAR.S(Returns!F$2:F$121)) -> 0.11060853 | G28: =G15/(_xlfn.VAR.S(Returns!G$2:G$121)) -> 0.049046596 | H28: =H15/(_xlfn.VAR.S(Returns!H$2:H$121)) -> 0.021791172 | I28: =I15/(_xlfn.VAR.S(Returns!I$2:I$121)) -> 0.14118723 | ... K28: =K15/(_xlfn.VAR.S(Returns!K$2:K$121)) -> -0.025498299 | M28: GLD | N28: 0.08 | O28: -0.02 | P28: 0.42 | Q28: 1 | R28: 0.11 | S28: 0.05 | T28: 0.02 | U28: 0.14 | V28: 0.09 | W28: -0.03
A29: VNQ | B29: =B16/(_xlfn.VAR.S(Returns!B$2:B$121)) -> 0.9890399 | C29: =C16/(_xlfn.VAR.S(Returns!C$2:C$121)) -> 0.69881091 | D29: =D16/(_xlfn.VAR.S(Returns!D$2:D$121)) -> 0.3333185 | E29: =E16/(_xlfn.VAR.S(Returns!E$2:E$121)) -> 0.22506263 | F29: =F16/(_xlfn.VAR.S(Returns!F$2:F$121)) -> 1 | G29: =G16/(_xlfn.VAR.S(Returns!G$2:G$121)) -> 0.28186528 | H29: =H16/(_xlfn.VAR.S(Returns!H$2:H$121)) -> 0.51741104 | I29: =I16/(_xlfn.VAR.S(Returns!I$2:I$121)) -> 0.31857682 | ... K29: =K16/(_xlfn.VAR.S(Returns!K$2:K$121)) -> 0.054496399 | M29: VNQ | N29: 0.99 | O29: 0.7 | P29: 0.33 | Q29: 0.23 | R29: 1 | S29: 0.28 | T29: 0.52 | U29: 0.32 | V29: 0.97 | W29: 0.05
A30: ORCL | B30: =B17/(_xlfn.VAR.S(Returns!B$2:B$121)) -> 0.93528427 | C30: =C17/(_xlfn.VAR.S(Returns!C$2:C$121)) -> 0.48199013 | D30: =D17/(_xlfn.VAR.S(Returns!D$2:D$121)) -> 0.21671901 | E30: =E17/(_xlfn.VAR.S(Returns!E$2:E$121)) -> 0.16770007 | F30: =F17/(_xlfn.VAR.S(Returns!F$2:F$121)) -> 0.4736431 | G30: =G17/(_xlfn.VAR.S(Returns!G$2:G$121)) -> 1 | H30: =H17/(_xlfn.VAR.S(Returns!H$2:H$121)) -> 0.55942364 | I30: =I17/(_xlfn.VAR.S(Returns!I$2:I$121)) -> 0.28145627 | ... K30: =K17/(_xlfn.VAR.S(Returns!K$2:K$121)) -> 0.14643765 | M30: ORCL | N30: 0.94 | O30: 0.48 | P30: 0.22 | Q30: 0.17 | R30: 0.47 | S30: 1 | T30: 0.56 | U30: 0.28 | V30: 0.74 | W30: 0.15
A31: BLK | B31: =B18/(_xlfn.VAR.S(Returns!B$2:B$121)) -> 1.2504455 | C31: =C18/(_xlfn.VAR.S(Returns!C$2:C$121)) -> 0.85946707 | D31: =D18/(_xlfn.VAR.S(Returns!D$2:D$121)) -> 0.1128869 | E31: =E18/(_xlfn.VAR.S(Returns!E$2:E$121)) -> 0.068618499 | F31: =F18/(_xlfn.VAR.S(Returns!F$2:F$121)) -> 0.80072166 | G31: =G18/(_xlfn.VAR.S(Returns!G$2:G$121)) -> 0.51520143 | H31: =H18/(_xlfn.VAR.S(Returns!H$2:H$121)) -> 1 | I31: =I18/(_xlfn.VAR.S(Returns!I$2:I$121)) -> 0.37404978 | ... K31: =K18/(_xlfn.VAR.S(Returns!K$2:K$121)) -> 0.090517122 | M31: BLK | N31: 1.25 | O31: 0.86 | P31: 0.11 | Q31: 0.07 | R31: 0.8 | S31: 0.52 | T31: 1 | U31: 0.37 | V31: 1.15 | W31: 0.09
A32: LMT | B32: =B19/(_xlfn.VAR.S(Returns!B$2:B$121)) -> 0.4577719 | C32: =C19/(_xlfn.VAR.S(Returns!C$2:C$121)) -> 0.31401104 | D32: =D19/(_xlfn.VAR.S(Returns!D$2:D$121)) -> -0.035514532 | E32: =E19/(_xlfn.VAR.S(Returns!E$2:E$121)) -> 0.30469792 | F32: =F19/(_xlfn.VAR.S(Returns!F$2:F$121)) -> 0.33788856 | G32: =G19/(_xlfn.VAR.S(Returns!G$2:G$121)) -> 0.17764811 | H32: =H19/(_xlfn.VAR.S(Returns!H$2:H$121)) -> 0.25635561 | I32: =I19/(_xlfn.VAR.S(Returns!I$2:I$121)) -> 1 | ... K32: =K19/(_xlfn.VAR.S(Returns!K$2:K$121)) -> 0.020562121 | M32: LMT | N32: 0.46 | O32: 0.31 | P32: -0.04 | Q32: 0.3 | R32: 0.34 | S32: 0.18 | T32: 0.26 | U32: 1 | V32: 0.6 | W32: 0.02
A33: XLV | B33: =B20/(_xlfn.VAR.S(Returns!B$2:B$121)) -> 0.70064019 | C33: =C20/(_xlfn.VAR.S(Returns!C$2:C$121)) -> 0.45911513 | D33: =D20/(_xlfn.VAR.S(Returns!D$2:D$121)) -> 0.093855896 | E33: =E20/(_xlfn.VAR.S(Returns!E$2:E$121)) -> 0.099860366 | F33: =F20/(_xlfn.VAR.S(Returns!F$2:F$121)) -> 0.51240504 | G33: =G20/(_xlfn.VAR.S(Returns!G$2:G$121)) -> 0.23198875 | H33: =H20/(_xlfn.VAR.S(Returns!H$2:H$121)) -> 0.39373401 | I33: =I20/(_xlfn.VAR.S(Returns!I$2:I$121)) -> 0.30023577 | ... K33: =K20/(_xlfn.VAR.S(Returns!K$2:K$121)) -> 0.036902661 | M33: XLV | N33: 0.7 | O33: 0.46 | P33: 0.09 | Q33: 0.1 | R33: 0.51 | S33: 0.23 | T33: 0.39 | U33: 0.3 | V33: 1 | W33: 0.04
A34: SMCI | B34: =B21/(_xlfn.VAR.S(Returns!B$2:B$121)) -> 1.424273 | C34: =C21/(_xlfn.VAR.S(Returns!C$2:C$121)) -> 0.80407738 | D34: =D21/(_xlfn.VAR.S(Returns!D$2:D$121)) -> 0.32424995 | E34: =E21/(_xlfn.VAR.S(Returns!E$2:E$121)) -> -0.5579392 | F34: =F21/(_xlfn.VAR.S(Returns!F$2:F$121)) -> 0.58604198 | G34: =G21/(_xlfn.VAR.S(Returns!G$2:G$121)) -> 0.93713903 | H34: =H21/(_xlfn.VAR.S(Returns!H$2:H$121)) -> 0.62899294 | I34: =I21/(_xlfn.VAR.S(Returns!I$2:I$121)) -> 0.20848246 | ... K34: =K21/(_xlfn.VAR.S(Returns!K$2:K$121)) -> 1 | M34: SMCI | N34: 1.42 | O34: 0.8 | P34: 0.32 | Q34: -0.56 | R34: 0.59 | S34: 0.94 | T34: 0.63 | U34: 0.21 | V34: 0.75 | W34: 1
A36: Analyst Confidence Level, γ | B36: 0.6 | M36: Analyst Confidence Level, γ | N36: 0.6
B38: Expected Benchmark Return, No Opinion | C38: Analyst's Opinion, Δ | D38: Returns Adjusted for Opinions | E38: Returns adj for opinions and confidence levels | N38: Expected Benchmark Return, No Opinion | O38: Analyst's Opinion, Δ | P38: Returns Adjusted for Opinions | Q38: Returns adj for opinions and confidence levels
A39: =A25 -> SPY | B39: {=(MMULT(B12:K21,TRANSPOSE(B8:K8))*B4+B2)} -> 0.0086704673 | C39: 0.0044 | D39: {=(_xlfn.ANCHORARRAY(B39)+MMULT(B25:K34,C39:C48))} -> 0.01382051 | E39: =$B$36*D39+(1-$B$36)*B39 -> 0.011760493 | M39: SPY | N39: 0.0087 | O39: 0.0044 | P39: 0.0138 | Q39: 0.0118
A40: =A26 -> IWM | B40: 0.0094457813 | C40: 0.0012 | D40: 0.016116102 | E40: =$B$36*D40+(1-$B$36)*B40 -> 0.013447974 | M40: IWM | N40: 0.0094 | O40: 0.0012 | P40: 0.0161 | Q40: 0.0134
A41: =A27 -> TLT | B41: 0.0041124285 | C41: -0.00044 | D41: 0.0037616867 | E41: =$B$36*D41+(1-$B$36)*B41 -> 0.0039019834 | M41: TLT | N41: 0.0041 | O41: -0.0004 | P41: 0.0038 | Q41: 0.0039
A42: =A28 -> GLD | B42: 0.0041794969 | C42: 0 | D42: 0.0043013726 | E42: =$B$36*D42+(1-$B$36)*B42 -> 0.0042526224 | M42: GLD | N42: 0.0042 | O42: 0 | P42: 0.0043 | Q42: 0.0043
A43: =A29 -> VNQ | B43: 0.0082160429 | C43: 0 | D43: 0.013259731 | E43: =$B$36*D43+(1-$B$36)*B43 -> 0.011242256 | M43: VNQ | N43: 0.0082 | O43: 0 | P43: 0.0133 | Q43: 0.0112
A44: =A30 -> ORCL | B44: 0.012461229 | C44: 0 | D44: 0.017059511 | E44: =$B$36*D44+(1-$B$36)*B44 -> 0.015220198 | M44: ORCL | N44: 0.0125 | O44: 0 | P44: 0.0171 | Q44: 0.0152
A45: =A31 -> BLK | B45: 0.010737679 | C45: 0 | D45: 0.017221329 | E45: =$B$36*D45+(1-$B$36)*B45 -> 0.014627869 | M45: BLK | N45: 0.0107 | O45: 0 | P45: 0.0172 | Q45: 0.0146
...
