Workbook
Name IQ_CH: 110000
Name IQ_CQ: 5000
Name IQ_CY: 10000
Name IQ_DAILY: 500000
Name IQ_FH: 100000
Name IQ_FQ: 500
Name IQ_FY: 1000
Name IQ_LTM: 2000
Name IQ_MONTH: 15000
Name IQ_NTM: 6000
Name IQ_WEEK: 50000
Name IQ_YTD: 3000

Sheet FSM Complete
C2: ="Financial Statement Model for "&D5 -> Financial Statement Model for Apple
C3: $ mm except per share
C5: Company name | D5: Apple
C6: Ticker | D6: AAPL
C7: Circ break 1=off, 0=on | D7: 1
C8: Latest closing share price | D8: 171.25
C9: Latest closing share price date | D9: 43500
C10: Latest fiscal year end date | D10: 46022
C11: Shares outstanding (millions) | D11: 4745.398
A13: x | C13: INCOME STATEMENT
C14: Fiscal year | D14: =E14-1 -> 2023 | E14: =F14-1 -> 2024 | F14: =YEAR(D10) -> 2025 | G14: =F14+1 -> 2026 | H14: =G14+1 -> 2027 | I14: =H14+1 -> 2028 | J14: =I14+1 -> 2029 | K14: =J14+1 -> 2030
C15: Fiscal year end date | D15: =EOMONTH(E15,-12) -> 45291 | E15: =EOMONTH(F15,-12) -> 45657 | F15: =D10 -> 46022 | G15: =EOMONTH(F15,12) -> 46387 | H15: =EOMONTH(G15,12) -> 46752 | I15: =EOMONTH(H15,12) -> 47118 | J15: =EOMONTH(I15,12) -> 47483 | K15: =EOMONTH(J15,12) -> 47848
C17: Revenue | D17: 910488 | E17: 1041938 | F17: 1149088 | G17: =F17*(1+G37) -> 1260549.5 | H17: =G17*(1+H37) -> 1399210 | I17: =H17*(1+I37) -> 1539131 | J17: =I17*(1+J37) -> 1677652.8 | K17: =J17*(1+K37) -> 1811865
C18: Cost of sales (enter as -) | D18: -432690 | E18: -477540 | F18: -516234 | G18: =-G38*G17 -> -542036.3 | H18: =-H38*H17 -> -559683.99 | I18: =-I38*I17 -> -584869.77 | J18: =-J38*J17 -> -603955 | K18: =-K38*K17 -> -634152.75
C19: Gross Profit | D19: =SUM(D17:D18) -> 477798 | E19: =SUM(E17:E18) -> 564398 | F19: =SUM(F17:F18) -> 632854 | G19: =SUM(G17:G18) -> 718513.24 | H19: =SUM(H17:H18) -> 839525.99 | I19: =SUM(I17:I18) -> 954261.21 | J19: =SUM(J17:J18) -> 1073697.8 | K19: =SUM(K17:K18) -> 1177712.2
C20: Research & development (enter as -) | D20: -156582 | E20: -166197 | F20: -152334 | G20: =-G39*G17 -> -157568.69 | H20: =-H39*H17 -> -167905.2 | I20: =-I39*I17 -> -177000.06 | J20: =-J39*J17 -> -184541.8 | K20: =-K39*K17 -> -190245.82
C21: Sales & Marketing Expenses | D21: -296713 | E21: -311954 | F21: -311816 | G21: =-G40*G17 -> -327742.88 | H21: =-H40*H17 -> -349802.5 | I21: =-I40*I17 -> -369391.44 | J21: =-J40*J17 -> -385860.14 | K21: =-K40*K17 -> -398610.3
C22: Selling, general & administrative (enter as -) | D22: -123079 | E22: -137550 | F22: -139854 | G22: =-G17*G41 -> -144963.2 | H22: =-H17*H41 -> -153913.1 | I22: =-I17*I41 -> -161608.75 | J22: =-J17*J41 -> -167765.28 | K22: =-K17*K41 -> -172127.17
C23: Operating profit (EBIT) | D23: =SUM(D19:D22) -> -98576 | E23: =SUM(E19:E22) -> -51303 | F23: =SUM(F19:F22) -> 28850 | G23: =SUM(G19:G22) -> 88238.468 | H23: =SUM(H19:H22) -> 167905.2 | I23: =SUM(I19:I22) -> 246260.96 | J23: =SUM(J19:J22) -> 335530.55 | K23: =SUM(K19:K22) -> 416728.95
C24: Interest income | D24: 26799 | E24: 46745 | F24: 30168
C25: Interest expense (enter as -) | D25: -7646 | E25: -14812 | F25: -14076
C26: Other expense, net (enter as -) | D26: 0 | E26: 6615 | F26: 0 | G26: =F26 -> 0 | H26: =G26 -> 0 | I26: =H26 -> 0 | J26: =I26 -> 0 | K26: =J26 -> 0
C27: Pretax profit | D27: =SUM(D23:D26) -> -79423 | E27: =SUM(E23:E26) -> -12755 | F27: =SUM(F23:F26) -> 44942 | G27: =SUM(G23:G26) -> 88238.468 | H27: =SUM(H23:H26) -> 167905.2 | I27: =SUM(I23:I26) -> 246260.96 | J27: =SUM(J23:J26) -> 335530.55 | K27: =SUM(K23:K26) -> 416728.95
C28: Taxes (enter expense as -) | D28: -2341 | E28: -40 | F28: -5526 | G28: =-G42*G27 -> -11029.808 | H28: =-H42*H27 -> -21827.676 | I28: =-I42*I27 -> -33245.229 | J28: =-J42*J27 -> -46974.278 | K28: =-K42*K27 -> -60425.698
C29: Net income | D29: =SUM(D27:D28) -> -81764 | E29: =SUM(E27:E28) -> -12795 | F29: =SUM(F27:F28) -> 39416 | G29: =SUM(G27:G28) -> 77208.659 | H29: =SUM(H27:H28) -> 146077.52 | I29: =SUM(I27:I28) -> 213015.73 | J29: =SUM(J27:J28) -> 288556.28 | K29: =SUM(K27:K28) -> 356303.25
C31: Depreciation & amortization | D31: 10157 | E31: 10903 | F31: 12547 | G31: =G108 -> 13108.099 | H31: =H108 -> 14034.452 | I31: =I108 -> 14831.766 | J31: =J108 -> 16467.879 | K31: =K108 -> 18110.664
C32: EBITDA | D32: =D23+D31 -> -88419 | E32: =E23+E31 -> -40400 | F32: =F23+F31 -> 41397 | G32: =G23+G31 -> 101346.57 | H32: =H23+H31 -> 181939.65 | I32: =I23+I31 -> 261092.72 | J32: =J23+J31 -> 351998.43 | K32: =K23+K31 -> 434839.61
C33: Stock based compensation | D33: 4840 | E33: 5340 | F33: 6068 | G33: =F33*(1+G37) -> 6656.596 | H33: =G33*(1+H37) -> 7388.8216 | I33: =H33*(1+I37) -> 8127.7037 | J33: =I33*(1+J37) -> 8859.1971 | K33: =J33*(1+K37) -> 9567.9328
C34: Adjusted EBITDA | D34: =SUM(D32:D33) -> -83579 | E34: =SUM(E32:E33) -> -35060 | F34: =SUM(F32:F33) -> 47465 | G34: =SUM(G32:G33) -> 108003.16 | H34: =SUM(H32:H33) -> 189328.47 | I34: =SUM(I32:I33) -> 269220.43 | J34: =SUM(J32:J33) -> 360857.63 | K34: =SUM(K32:K33) -> 444407.55
C36: Growth rates & margins
C37: Revenue growth | E37: =E17/D17-1 -> 0.14437313 | F37: =F17/E17-1 -> 0.10283721 | G37: 0.097 | H37: 0.11 | I37: 0.1 | J37: 0.09 | K37: 0.08
C38: COGS % of Sales | D38: =-D18/D17 -> 0.47522867 | E38: =-E18/E17 -> 0.45831902 | F38: =-F18/F17 -> 0.44925541 | G38: 0.43 | H38: 0.4 | I38: 0.38 | J38: 0.36 | K38: 0.35
C39: R&D % of sales | D39: =-D20/D17 -> 0.17197591 | E39: =-E20/E17 -> 0.15950757 | F39: =-F20/F17 -> 0.13256948 | G39: 0.125 | H39: 0.12 | I39: 0.115 | J39: 0.11 | K39: 0.105
C40: S&M % of sales | D40: =-D21/D17 -> 0.32588348 | E40: =-E21/E17 -> 0.29939785 | F40: =-F21/F17 -> 0.27135955 | G40: 0.26 | H40: 0.25 | I40: 0.24 | J40: 0.23 | K40: 0.22
C41: SG&A % of sales | D41: =-D22/D17 -> 0.13517916 | E41: =-E22/E17 -> 0.13201361 | F41: =-F22/F17 -> 0.12170869 | G41: 0.115 | H41: 0.11 | I41: 0.105 | J41: 0.1 | K41: 0.095
A42: x | C42: Tax rate | D42: =-(D28/D27) -> -0.029475089 | E42: =-(E28/E27) -> -0.0031360251 | F42: =-(F28/F27) -> 0.12295848 | G42: 0.125 | H42: 0.13 | I42: 0.135 | J42: 0.14 | K42: 0.145
C44: BALANCE SHEET
C45: =C14 -> Fiscal year | E45: =E14 -> 2024 | F45: =F14 -> 2025 | G45: =G14 -> 2026 | H45: =H14 -> 2027 | I45: =I14 -> 2028 | J45: =J14 -> 2029 | K45: =K14 -> 2030
C46: =C15 -> Fiscal year end date | E46: =E15 -> 45657 | F46: =F15 -> 46022 | G46: =G15 -> 46387 | H46: =H15 -> 46752 | I46: =I15 -> 47118 | J46: =J15 -> 47483 | K46: =K15 -> 47848
C47: Cash & equivalents, ST and LT marketable securities | E47: =362546+643410 -> 1005956 | F47: =25913+40388+170799 -> 237100 | G47: =G92+F47 -> 233536.72 | H47: =H92+G47 -> 299003.35 | I47: =I92+H47 -> 433142.62 | J47: =J92+I47 -> 642935.32 | K47: =K92+J47 -> 922341.99
...

Sheet FSM
A2: x | C2: ="Financial Statement Model FIVN" -> Financial Statement Model FIVN
C3: =MVA!$B$3 -> $ and shares in thousands, except per share data
C5: Company name | D5: FIVE 9 | I5: Select an operating scenario: | L5: Weak case
C6: Ticker | D6: FIVN
C7: Circ break 1=off, 0=on | D7: 1
C8: Latest closing share price | D8: 22.52
C9: Latest closing share price date | D9: 46144
C10: Latest fiscal year end date | D10: 46022
C11: Shares outstanding (millions) | D11: 77194
A13: x | C13: INCOME STATEMENT
C14: Fiscal year | D14: =E14-1 -> 2023 | E14: =F14-1 -> 2024 | F14: =YEAR(D10) -> 2025 | G14: =F14+1 -> 2026 | H14: =G14+1 -> 2027 | I14: =H14+1 -> 2028 | J14: =I14+1 -> 2029 | K14: =J14+1 -> 2030
C15: Fiscal year end date | D15: =EOMONTH(E15,-12) -> 45291 | E15: 45657 | F15: =D10 -> 46022 | G15: =EOMONTH(F15,12) -> 46387 | H15: =EOMONTH(G15,12) -> 46752 | I15: =EOMONTH(H15,12) -> 47118 | J15: =EOMONTH(I15,12) -> 47483 | K15: =EOMONTH(J15,12) -> 47848
C17: Revenue | D17: 910488 | E17: 1041938 | F17: 1149088 | G17: =F17*(1+G37) -> 1241015 | H17: =G17*(1+H37) -> 1352706.4 | I17: =H17*(1+I37) -> 1433868.8 | J17: =I17*(1+J37) -> 1519900.9 | K17: =J17*(1+K37) -> 1611095
C18: Cost of sales (enter as -) | D18: -432690 | E18: -477540 | F18: -516234 | G18: =G19-G17 -> -1141733.8 | H18: =H19-H17 -> -1230962.8 | I18: =I19-I17 -> -1347836.7 | J18: =J19-J17 -> -1428706.8 | K18: =K19-K17 -> -1514429.3
C19: Gross Profit | D19: =SUM(D17:D18) -> 477798 | E19: =SUM(E17:E18) -> 564398 | F19: =SUM(F17:F18) -> 632854 | G19: =G17*G38 -> 99281.203 | H19: =H17*H38 -> 121743.58 | I19: =I17*I38 -> 86032.127 | J19: =J17*J38 -> 91194.054 | K19: =K17*K38 -> 96665.697
C20: Research & development (enter as -) | D20: -156582 | E20: -166197 | F20: -152334 | G20: =-G39*G17 -> -99281.203 | H20: =-H39*H17 -> -121743.58 | I20: =-I39*I17 -> -86032.127 | J20: =-J39*J17 -> -91194.054 | K20: =-K39*K17 -> -96665.697
C21: Sales and Marketing | D21: -296713 | E21: -311954 | F21: -311816
C22: Selling, general & administrative (enter as -) | D22: -123079 | E22: -137550 | F22: -139854 | G22: =-G17*G41 -> -99281.203 | H22: =-H17*H41 -> -121743.58 | I22: =-I17*I41 -> -86032.127 | J22: =-J17*J41 -> -91194.054 | K22: =-K17*K41 -> -96665.697
C23: Operating profit (EBIT) | D23: =SUM(D19:D22) -> -98576 | E23: =SUM(E19:E22) -> -51303 | F23: =SUM(F19:F22) -> 28850 | G23: =SUM(G19:G22) -> -99281.203 | H23: =SUM(H19:H22) -> -121743.58 | I23: =SUM(I19:I22) -> -86032.127 | J23: =SUM(J19:J22) -> -91194.054 | K23: =SUM(K19:K22) -> -96665.697
C24: Interest income | D24: 26799 | E24: 46745 | F24: 30168 | G24: =G158 -> #DIV/0! | H24: =H158 -> #DIV/0! | I24: =I158 -> #DIV/0! | J24: =J158 -> #DIV/0! | K24: =K158 -> #DIV/0!
C25: Interest expense (enter as -) | D25: -7646 | E25: -14812 | F25: -14076 | G25: =-G144 -> #DIV/0! | H25: =-H144 -> #DIV/0! | I25: =-I144 -> #DIV/0! | J25: =-J144 -> #DIV/0! | K25: =-K144 -> #DIV/0!
C26: Other expense, net (enter as -) | D26: 0 | E26: 6615 | F26: 0 | G26: =F26 -> 0 | H26: =G26 -> 0 | I26: =H26 -> 0 | J26: =I26 -> 0 | K26: =J26 -> 0
C27: Pretax profit | D27: =SUM(D23:D26) -> -79423 | E27: =SUM(E23:E26) -> -12755 | F27: =SUM(F23:F26) -> 44942 | G27: =SUM(G23:G26) -> #DIV/0! | H27: =SUM(H23:H26) -> #DIV/0! | I27: =SUM(I23:I26) -> #DIV/0! | J27: =SUM(J23:J26) -> #DIV/0! | K27: =SUM(K23:K26) -> #DIV/0!
C28: Taxes (enter expense as -) | D28: -2341 | E28: -40 | F28: -5526 | G28: =-G42*G27 -> #DIV/0! | H28: =-H42*H27 -> #DIV/0! | I28: =-I42*I27 -> #DIV/0! | J28: =-J42*J27 -> #DIV/0! | K28: =-K42*K27 -> #DIV/0!
C29: Net income | D29: =SUM(D27:D28) -> -81764 | E29: =SUM(E27:E28) -> -12795 | F29: =SUM(F27:F28) -> 39416 | G29: =SUM(G27:G28) -> #DIV/0! | H29: =SUM(H27:H28) -> #DIV/0! | I29: =SUM(I27:I28) -> #DIV/0! | J29: =SUM(J27:J28) -> #DIV/0! | K29: =SUM(K27:K28) -> #DIV/0!
C31: Depreciation & amortization | D31: 10157 | E31: 10903 | F31: 12547 | G31: =G108 -> #DIV/0! | H31: =H108 -> #DIV/0! | I31: =I108 -> #DIV/0! | J31: =J108 -> #DIV/0! | K31: =K108 -> #DIV/0!
C32: EBITDA | D32: =D23+D31 -> -88419 | E32: =E23+E31 -> -40400 | F32: =F23+F31 -> 41397 | G32: =G23+G31 -> #DIV/0! | H32: =H23+H31 -> #DIV/0! | I32: =I23+I31 -> #DIV/0! | J32: =J23+J31 -> #DIV/0! | K32: =K23+K31 -> #DIV/0!
C33: Stock based compensation | D33: 4840 | E33: 5340 | F33: 6068 | G33: =F33*(1+G37) -> 6553.44 | H33: =G33*(1+H37) -> 7143.2496 | I33: =H33*(1+I37) -> 7571.8446 | J33: =I33*(1+J37) -> 8026.1553 | K33: =J33*(1+K37) -> 8507.7246
C34: Adjusted EBITDA | D34: =SUM(D32:D33) -> -83579 | E34: =SUM(E32:E33) -> -35060 | F34: =SUM(F32:F33) -> 47465 | G34: =SUM(G32:G33) -> #DIV/0! | H34: =SUM(H32:H33) -> #DIV/0! | I34: =SUM(I32:I33) -> #DIV/0! | J34: =SUM(J32:J33) -> #DIV/0! | K34: =SUM(K32:K33) -> #DIV/0!
C36: Growth rates & margins
C37: Revenue growth | D37: =D17/#REF!-1 -> #REF! | E37: =E17/D17-1 -> 0.14437313 | F37: =F17/E17-1 -> 0.10283721 | G37: 0.08 | H37: 0.09 | I37: 0.06 | J37: 0.06 | K37: 0.06
C38: Gross profit margin | D38: =D19/D17 -> 0.52477133 | E38: =E19/E17 -> 0.54168098 | F38: =F19/F17 -> 0.55074459 | G38: 0.08 | H38: 0.09 | I38: 0.06 | J38: 0.06 | K38: 0.06
C39: R&D % of sales | D39: =-D20/D17 -> 0.17197591 | E39: =-E20/E17 -> 0.15950757 | F39: =-F20/F17 -> 0.13256948 | G39: 0.08 | H39: 0.09 | I39: 0.06 | J39: 0.06 | K39: 0.06
C40: S&M % of sales | D40: =-D21/D17 -> 0.32588348 | E40: =-E21/E17 -> 0.29939785 | F40: =-F21/F17 -> 0.27135955 | G40: 0.08 | H40: 0.09 | I40: 0.06 | J40: 0.06 | K40: 0.06
C41: SG&A % of sales | D41: =-D22/D17 -> 0.13517916 | E41: =-E22/E17 -> 0.13201361 | F41: =-F22/F17 -> 0.12170869 | G41: 0.08 | H41: 0.09 | I41: 0.06 | J41: 0.06 | K41: 0.06
C42: Tax rate | D42: =-(D28/D27) -> -0.029475089 | E42: =-(E28/E27) -> -0.0031360251 | F42: =-(F28/F27) -> 0.12295848 | G42: =F42 -> 0.12295848 | H42: =G42 -> 0.12295848 | I42: =H42 -> 0.12295848 | J42: =I42 -> 0.12295848 | K42: =J42 -> 0.12295848
A44: x | C44: BALANCE SHEET
C45: =C14 -> Fiscal year | D45: =D14 -> 2023 | E45: =E14 -> 2024 | F45: =F14 -> 2025 | G45: =G14 -> 2026 | H45: =H14 -> 2027 | I45: =I14 -> 2028 | J45: =J14 -> 2029 | K45: =K14 -> 2030
C46: =C15 -> Fiscal year end date | D46: =D15 -> 45291 | E46: =E15 -> 45657 | F46: =F15 -> 46022 | G46: =G15 -> 46387 | H46: =H15 -> 46752 | I46: =I15 -> 47118 | J46: =J15 -> 47483 | K46: =K15 -> 47848
C47: Cash & equivalents, ST and LT marketable securities | G47: =G92+F47 -> #DIV/0! | H47: =H92+G47 -> #DIV/0! | I47: =I92+H47 -> #DIV/0! | J47: =J92+I47 -> #DIV/0! | K47: =K92+J47 -> #DIV/0!
...

Sheet DCF
B2: Discounted Cash Flow Valuation
B3: =MVA!$B$3 -> $ and shares in thousands, except per share data
B4: Most recent fiscal year end | D4: 46022 | F4: Discount rate (WACC) | H4: ='[1]DCF Complete (post-WACC)'!H4 -> 0.077820797
B5: End of first fiscal year | D5: =EOMONTH(D4,12) -> 46387 | F5: Share price (Public Co) | H5: 22.24 | I5: Source: CIQ
B6: Most recent quarter end date | D6: 46112 | F6: Share price date | H6: 43888
B7: Valuation date | D7: 46144 | F7: Midyear adjustment? | H7: 0
B8: Portion of First Year Cash Flows | D8: =YEARFRAC(D7,D5) -> 0.66388889
F9: Case active: | H9: =FSM!L5 -> Weak case
A10: x | B10: Unlevered Free Cash Flows
C11: LTM | D11: Actual | E11: Forecasts
B12: Fiscal year ended | C12: =D7 -> 46144 | D12: =D4 -> 46022 | E12: =EOMONTH(D12,12) -> 46387 | F12: =EOMONTH(E12,12) -> 46752 | G12: =EOMONTH(F12,12) -> 47118 | H12: =EOMONTH(G12,12) -> 47483 | I12: =EOMONTH(H12,12) -> 47848
B14: Revenue | D14: =FSM!F17 -> 1149088
B15: % growth | E15: =IFERROR(E14/D14-1,"nm") -> -1 | F15: =IFERROR(F14/E14-1,"nm") -> nm | G15: =IFERROR(G14/F14-1,"nm") -> nm | H15: =IFERROR(H14/G14-1,"nm") -> nm | I15: =IFERROR(I14/H14-1,"nm") -> nm
B16: EBITDA | D16: =FSM!F34 -> 47465
B17: % margin | D17: =IFERROR(D16/D$14,"nm") -> 0.041306671 | E17: =IFERROR(E16/E$14,"nm") -> nm | F17: =IFERROR(F16/F$14,"nm") -> nm | G17: =IFERROR(G16/G$14,"nm") -> nm | H17: =IFERROR(H16/H$14,"nm") -> nm | I17: =IFERROR(I16/I$14,"nm") -> nm
B18: EBIT | D18: =FSM!F23 -> 28850
B19: % margin | D19: =IFERROR(D18/D$14,"nm") -> 0.025106867 | E19: =IFERROR(E18/E$14,"nm") -> nm | F19: =IFERROR(F18/F$14,"nm") -> nm | G19: =IFERROR(G18/G$14,"nm") -> nm | H19: =IFERROR(H18/H$14,"nm") -> nm | I19: =IFERROR(I18/I$14,"nm") -> nm
B21: Tax on EBIT
B22: Tax rate
B23: NOPAT (aka EBIAT)
B25: Depreciation & amortization
B26: Changes in net working capital
B27: Capital expenditures
B28: as % of revenue
B30: Unlevered free cash flows (UFCF)
B32: Net working capital (WC Assets - WC liabilities)
B33: as % of revenue
A35: x | B35: ="Present value of UFCF on "&TEXT(D7,"mmm dd, yyyy")&" valuation date" -> Present value of UFCF on May 02, 2026 valuation date
D36: Val date | E36: Yr 1 - Stub | F36: Year 2 | G36: Year 3 | H36: Year 4 | I36: Year 5
B37: Date for discounting cash flows | D37: =D7 -> 46144 | E37: =IF($H$7=1,AVERAGE(E12,D37),E12) -> 46387 | F37: =IF($H$7=1,AVERAGE(F12,E12),F12) -> 46752 | G37: =IF($H$7=1,AVERAGE(G12,F12),G12) -> 47118 | H37: =IF($H$7=1,AVERAGE(H12,G12),H12) -> 47483 | I37: =IF($H$7=1,AVERAGE(I12,H12),I12) -> 47848
B38: Unlevered free cash flows (UFCF) stub adjusted | C38: =D8 -> 0.66388889 | E38: =E30*C38 -> 0 | F38: =F30 -> 0 | G38: =G30 -> 0 | H38: =H30 -> 0 | I38: =I30 -> 0 | K38: <-Stub year counts first year cash flows starting at the valuation date
B39: Present value of unlevered free cash flows | E39: =E38/(1+$H$4)^((E37-$D$7)/365) -> 0 | F39: =F38/(1+$H$4)^((F37-$D$7)/365) -> 0 | G39: =G38/(1+$H$4)^((G37-$D$7)/365) -> 0 | H39: =H38/(1+$H$4)^((H37-$D$7)/365) -> 0 | I39: =I38/(1+$H$4)^((I37-$D$7)/365) -> 0
A41: x | B41: Terminal value - growth in perpetuity approach | E41: Terminal value - EBITDA multiple approach
B42: Long term growth rate | C42: 0.03 | E42: Terminal year EBITDA | I42: =I16 -> 0
B43: =YEAR(I12)&" FCF x (1+g)" -> 2030 FCF x (1+g) | C43: =I38*(1+C42) -> 0 | E43: EBITDA multiple | I43: 12.515439
B44: ="Terminal value in "&YEAR(I12) -> Terminal value in 2030 | C44: =C43/(H4-C42) -> 0 | E44: ="Terminal value in "&YEAR(I12) -> Terminal value in 2030 | I44: =I42*I43 -> 0
B45: Present value of terminal value | C45: =C44/(1+H4)^((I37-$D$37)/365) -> 0 | E45: Present value of terminal value | I45: =I44/(1+H4)^((I37-D37)/365) -> 0
B46: Present value of stage 1 cash flows | C46: =SUM(E39:I39) -> 0 | E46: Present value of stage 1 cash flows | I46: =C46 -> 0
B47: Total enterprise value (TEV) | C47: =C46+C45 -> 0 | E47: Enterprise value (stage 1 + 2) | I47: =SUM(I45:I46) -> 0
B49: Terminal value as % of TEV | C49: =IFERROR(C45/$C$47,"nm") -> nm | E49: Terminal value as % of TEV | I49: =+IFERROR(I45/I47,"nm") -> nm
...

Sheet MVA
B2: Financials
B3: $ and shares in thousands, except per share data
D5: Actual | E5: Forecast
B6: Fiscal year ended December 31, | D6: 2025 | E6: =D6+1 -> 2026 | F6: =E6+1 -> 2027 | G6: =F6+1 -> 2028 | H6: =G6+1 -> 2029 | I6: =H6+1 -> 2030
B8: Revenue | D8: 260174 | E8: =D8*(1+E9) -> 280987.92 | F8: =E8*(1+F9) -> 306276.83 | G8: =F8*(1+G9) -> 324653.44 | H8: =G8*(1+H9) -> 344132.65 | I8: =H8*(1+I9) -> 364780.61
B9: % Revenue growth | E9: 0.08 | F9: 0.09 | G9: 0.06 | H9: 0.06 | I9: 0.06
B10: EBITDA | D10: 76477 | E10: =E11*E$8 -> 81486.497 | F10: =F11*F$8 -> 88820.282 | G10: =G11*G$8 -> 92526.231 | H10: =H11*H$8 -> 98077.805 | I10: =I11*I$8 -> 102138.57
B11: % margin | E11: 0.29 | F11: 0.29 | G11: 0.285 | H11: 0.285 | I11: 0.28
B12: EBIT | D12: 63930 | E12: =E13*E$8 -> 69123.028 | F12: =F13*F$8 -> 76569.208 | G12: =G13*G$8 -> 81163.361 | H12: =H13*H$8 -> 87753.826 | I12: =I13*I$8 -> 91195.152
B13: % margin | E13: 0.246 | F13: 0.25 | G13: 0.25 | H13: 0.255 | I13: 0.25
B15: Tax rate | E15: 0.158 | F15: 0.166 | G15: 0.167 | H15: 0.173 | I15: 0.173
B16: Capex as % of revenue | E16: =D16 -> 0 | F16: 0.039 | G16: 0.038 | H16: 0.037 | I16: 0.036
B18: Net working capital (WC Assets - WC liabilities) | D18: =22926+4106+22878+12352-46236-37720-5522 -> -27216
B19: as % of revenue | D19: =D18/D8 -> -0.10460692 | E19: =D19 -> -0.10460692 | F19: =E19 -> -0.10460692 | G19: =F19 -> -0.10460692 | H19: =G19 -> -0.10460692 | I19: =H19 -> -0.10460692
