Workbook

Sheet Historicals 
A3: x | B3: INCOME STATEMENT
E4: 45291 | F4: 45657 | G4: =EOMONTH(F4,12) -> 46022 | M4: 2026
B5: Revenue | E5: 910488 | F5: 1041938 | G5: 1149088
B6: Cost of Revenue | E6: 432690 | F6: 477540 | G6: 516234
B7: Gross Profit | E7: 477798 | F7: 564398 | G7: 632854
B8: Operating expenses:
C9: Research and development | E9: 156582 | F9: 166197 | G9: 152334
C10: Sales and marketing | E10: 296713 | F10: 311954 | G10: 311816
C11: General and administrative | E11: 123079 | F11: 137550 | G11: 139854
B12: Total operating expenses | E12: 576374 | F12: 615701 | G12: 604004
B13: Income (loss) from operations | E13: -98576 | F13: -51303 | G13: 28850
B14: Other income (expense), net:
C15: Interest expense | E15: -7646 | F15: -14812 | G15: -14076
C16: Gain on early extinguishment of debt | E16: 0 | F16: 6615 | G16: —
C17: Interest income and other | E17: 26799 | F17: 46745 | G17: 30168
B18: Total other income (expense), net | E18: 19153 | F18: 38548 | G18: 16092
B19: Income (loss) before income taxes | E19: -79423 | F19: -12755 | G19: 44942
B20: Provision for income taxes | E20: 2341 | F20: 40 | G20: 5526
B21: Net income (loss) | E21: -81764 | F21: -12795 | G21: 39416
B22: Net income (loss) per share:
C23: Basic | E23: -1.13 | F23: -0.17 | G23: 0.51
C24: Diluted | E24: -1.13 | F24: -0.17 | G24: 0.45
B25: Shares used in computing net income (loss) per share:
C26: Basic | E26: 72048 | F26: 74503 | G26: 76916
C27: Diluted | E27: 72048 | F27: 74503 | G27: 88002
B28: Comprehensive Income (Loss):
B29: Net income (loss) | E29: -81764 | F29: -12795 | G29: 39416
B30: Other comprehensive income | E30: 3270 | F30: 54 | G30: 261
B31: Comprehensive income (loss) | E31: -78494 | F31: -12741 | G31: 39677
A42: x | B42: BALANCE SHEET
B43: Fiscal year
B44: Fiscal year end date | E44: =E4 -> 45291 | F44: =EOMONTH(E44,12) -> 45657 | G44: =EOMONTH(F44,12) -> 46022
B46: ASSETS
B47: Current assets:
C48: Cash and cash equivalents | F48: 362546 | G48: 232084
C49: Marketable investments | F49: 643410 | G49: 464835
C50: Accounts receivable, net | F50: 115172 | G50: 130984
C51: Prepaid expenses and other current assets | F51: 50840 | G51: 43107
C52: Deferred contract acquisition costs, net | F52: 76600 | G52: 88714
B53: Total current assets | F53: 1248568 | G53: 959724
...

Sheet FSM
B2: X | C2: ="Financial Statement Model for "&D5 -> Financial Statement Model for FIVE 9
C3: $ thousands, except XX
C5: Company name | D5: FIVE 9 | F5: Operating lease discount rate | H5: 0.048
C6: Ticker | D6: FIVN | F6: Weighted avg. lease life | H6: 7.8
C7: Circuit breaker (1=off) | D7: 1
C8: Last closing share price | D8: 22.09
C9: Last fiscal year end date | D9: 46022
B11: X | C11: INCOME STATEMENT
C12: Fiscal year | D12: 2024 | E12: 2025 | F12: 2026 | G12: 2027 | H12: 2028 | I12: 2029 | J12: 2030 | L12: Fiscal Year | M12: 2026 | N12: 2027 | O12: 2028 | P12: 2029 | Q12: 2030
C13: Fiscal year end date | D13: 45688 | E13: 46053 | F13: =EOMONTH(E13,12) -> 46418 | G13: =EOMONTH(F13,12) -> 46783 | H13: =EOMONTH(G13,12) -> 47149 | I13: =EOMONTH(H13,12) -> 47514 | J13: =EOMONTH(I13,12) -> 47879 | L13: Fiscal year end date | M13: 46418 | N13: =EOMONTH(M13,12) -> 46783 | O13: =EOMONTH(N13,12) -> 47149 | P13: =EOMONTH(O13,12) -> 47514 | Q13: =EOMONTH(P13,12) -> 47879
R14: %Change
C15: Revenue | D15: ='Historicals '!F5 -> 1041938 | E15: ='Historicals '!G5 -> 1149088 | F15: =E15*(1+F35) -> 1286978.6 | G15: =F15*(1+G35) -> 1434981.1 | H15: =G15*(1+H35) -> 1592829 | I15: =H15*(1+I35) -> 1760076.1 | J15: =I15*(1+J35) -> 1936083.7 | L15: Gross Profit Margin | M15: =F17/F15 -> 0.5598082 | N15: =G17/G15 -> 0.56887181 | O15: =H17/H15 -> 0.57793541 | P15: =I17/I15 -> 0.58699902 | Q15: =J17/J15 -> 0.59606263 | R15: =Q15-M15 -> 0.03625443
C16: COGS | D16: =-'Historicals '!F6 -> -477540 | E16: =-'Historicals '!G6 -> -516234 | F16: =-F15*(1-F36) -> -566517.41 | G16: =-G15*(1-G36) -> -618660.81 | H16: =-H15*(1-H36) -> -672276.72 | I16: =-I15*(1-I36) -> -726913.14 | J16: =-J15*(1-J36) -> -782056.55 | L16: Operating Margin | M16: =F21/F15 -> 0.028293625 | N16: =G21/G15 -> 0.028633558 | O16: =H21/H15 -> 0.025844647 | P16: =I21/I15 -> 0.020089141 | Q16: =J21/J15 -> 0.011126597 | R16: =Q16-M16 -> -0.017167027
C17: Gross Profit | D17: =SUM(D15:D16) -> 564398 | E17: =SUM(E15:E16) -> 632854 | F17: =SUM(F15:F16) -> 720461.15 | G17: =SUM(G15:G16) -> 816320.29 | H17: =SUM(H15:H16) -> 920552.29 | I17: =SUM(I15:I16) -> 1033162.9 | J17: =SUM(J15:J16) -> 1154027.1 | L17: Profit Margin | M17: =F27/F15 -> 14888.884 | N17: =G27/G15 -> 0.27981265 | O17: =H27/H15 -> 0.35824339 | P17: =I27/I15 -> 0.37476535 | Q17: =J27/J15 -> 0.34419452 | R17: =Q17-M17 -> -14888.54
C18: Research and development | D18: =-'Historicals '!F9 -> -166197 | E18: =-'Historicals '!G9 -> -152334 | F18: =E18*(1+F37) -> -173660.76 | G18: =F18*(1+G37) -> -198494.25 | H18: =G18*(1+H37) -> -227672.9 | I18: =H18*(1+I37) -> -261368.49 | J18: =I18*(1+J37) -> -300312.4
C19: Sales and marketing | D19: =-'Historicals '!F10 -> -311954 | E19: =-'Historicals '!G10 -> -311816 | F19: =E19*(1+F38) -> -352352.08 | G19: =F19*(1+G38) -> -398157.85 | H19: =G19*(1+H38) -> -449918.37 | I19: =H19*(1+I38) -> -508407.76 | J19: =I19*(1+J38) -> -574500.77
C20: General and administrative | D20: =-'Historicals '!F11 -> -137550 | E20: =-'Historicals '!G11 -> -139854 | F20: =E20*(1+F39) -> -158035.02 | G20: =F20*(1+G39) -> -178579.57 | H20: =G20*(1+H39) -> -201794.92 | I20: =H20*(1+I39) -> -228028.26 | J20: =I20*(1+J39) -> -257671.93
C21: Operating Profit | D21: =SUM(D17:D20) -> -51303 | E21: =SUM(E17:E20) -> 28850 | F21: =SUM(F17:F20) -> 36413.289 | G21: =SUM(G17:G20) -> 41088.614 | H21: =SUM(H17:H20) -> 41166.104 | I21: =SUM(I17:I20) -> 35358.416 | J21: =SUM(J17:J20) -> 21542.024
C22: Interest Income | D22: ='Historicals '!F17 -> 46745 | E22: ='Historicals '!G17 -> 30168 | F22: 0 | G22: 0 | H22: 0 | I22: 0 | J22: 0
C23: Interest Expense | D23: ='Historicals '!F15 -> -14812 | E23: ='Historicals '!G15 -> -14076 | F23: 0 | G23: 0 | H23: 0 | I23: 0 | J23: 0
C24: Gain on early extinguishment of debt | D24: ='Historicals '!F16 -> 6615 | E24: 0 | F24: =F259 -> 19178708270 | G24: =G259 -> 360794.94 | H24: =H259 -> 529962.68 | I24: =I259 -> 624844.7 | J24: =J259 -> 645441.01
C25: Pretax Profit | D25: =SUM(D21:D24) -> -12755 | E25: =SUM(E21:E24) -> 44942 | F25: =SUM(F21:F24) -> 1.9178745e+10 | G25: =SUM(G21:G24) -> 401883.56 | H25: =SUM(H21:H24) -> 571128.78 | I25: =SUM(I21:I24) -> 660203.12 | J25: =SUM(J21:J24) -> 666983.04
C26: Tax | D26: -40 | E26: -40 | F26: =-F25*F40 -> -17069774 | G26: =-G25*G40 -> -357.69085 | H26: =-H25*H40 -> -508.3252 | I26: =-I25*I40 -> -587.60457 | J26: =-J25*J40 -> -593.63894
C27: Net Income | D27: =SUM(D25:D26) -> -12795 | E27: =SUM(E25:E26) -> 44902 | F27: =SUM(F25:F26) -> 1.9161675e+10 | G27: =SUM(G25:G26) -> 401525.87 | H27: =SUM(H25:H26) -> 570620.46 | I27: =SUM(I25:I26) -> 659615.51 | J27: =SUM(J25:J26) -> 666389.4
C29: Depreciation & Amortization | D29: ='Historicals '!F96+'Historicals '!F98 -> 124388 | E29: ='Historicals '!G96+'Historicals '!G98 -> 147770 | F29: =F177 -> 28358.242 | G29: =G177 -> 27417.51 | H29: =H177 -> 28540.786 | I29: =I177 -> 27985.952 | J29: =J177 -> 29692.863
C30: EBITDA | F30: =F21+F29 -> 64771.53 | G30: =G21+G29 -> 68506.124 | H30: =H21+H29 -> 69706.89 | I30: =I21+I29 -> 63344.368 | J30: =J21+J29 -> 51234.887
C31: Stock based compensation | D31: ='Historicals '!F95 -> 0 | E31: ='Historicals '!G95 -> 0 | F31: =E31*(1+F41) -> 0 | G31: =F31*(1+G41) -> 0 | H31: =G31*(1+H41) -> 0 | I31: =H31*(1+I41) -> 0 | J31: =I31*(1+J41) -> 0
C32: Adjusted EBITDA | F32: =SUM(F30:F31) -> 64771.53 | G32: =SUM(G30:G31) -> 68506.124 | H32: =SUM(H30:H31) -> 69706.89 | I32: =SUM(I30:I31) -> 63344.368 | J32: =SUM(J30:J31) -> 51234.887
C34: Growth rates & margins
C35: Revenue growth | E35: =E15/D15-1 -> 0.10283721 | F35: 0.12 | G35: 0.115 | H35: 0.11 | I35: 0.105 | J35: 0.1
C36: Gross profit margin | D36: =D17/D15 -> 0.54168098 | E36: =E17/E15 -> 0.55074459 | F36: =E36+(E36-D36) -> 0.5598082 | G36: =F36+(F36-E36) -> 0.56887181 | H36: =G36+(G36-F36) -> 0.57793541 | I36: =H36+(H36-G36) -> 0.58699902 | J36: =I36+(I36-H36) -> 0.59606263
C37: R&D as a % of Revenue | D37: =-D18/D15 -> 0.15950757 | E37: =-E18/E15 -> 0.13256948 | F37: 0.14 | G37: 0.143 | H37: 0.147 | I37: 0.148 | J37: 0.149
C38: S&M as a % of Revenue | D38: =-D19/D15 -> 0.29939785 | E38: =-E19/E15 -> 0.27135955 | F38: 0.13 | G38: 0.13 | H38: 0.13 | I38: 0.13 | J38: 0.13
C39: G&A as a % of Revenue | D39: =-D20/D15 -> 0.13201361 | E39: =-E20/E15 -> 0.12170869 | F39: 0.13 | G39: 0.13 | H39: 0.13 | I39: 0.13 | J39: 0.13
C40: Tax rate | D40: =IF(AND(D25<0,D26<0),D26/D25,-D26/D25) -> 0.0031360251 | E40: =IF(AND(E25<0,E26<0),E26/E25,-E26/E25) -> 0.00089003605 | F40: =E40 -> 0.00089003605 | G40: =F40 -> 0.00089003605 | H40: =G40 -> 0.00089003605 | I40: =H40 -> 0.00089003605 | J40: =I40 -> 0.00089003605
C41: Stock based compensation growth | E41: =E31/D31-1 -> #DIV/0! | F41: 0.02 | G41: 0.02 | H41: 0.02 | I41: 0.02 | J41: 0.02
B43: X | C43: BALANCE SHEET
C44: Fiscal year | D44: 2024 | E44: =D44+1 -> 2025 | F44: =E44+1 -> 2026 | G44: =F44+1 -> 2027 | H44: =G44+1 -> 2028 | I44: =H44+1 -> 2029 | J44: =I44+1 -> 2030
C45: Fiscal year end date | D45: 45688 | E45: =EOMONTH(D45,12) -> 46053 | F45: =EOMONTH(E45,12) -> 46418 | G45: =EOMONTH(F45,12) -> 46783 | H45: =EOMONTH(G45,12) -> 47149 | I45: =EOMONTH(H45,12) -> 47514 | J45: =EOMONTH(I45,12) -> 47879
C47: Cash and cash equivalents | D47: 1118785 | E47: 1421233 | F47: =E47+F109 -> 1.8543069e+10 | G47: =F47+G109 -> 1.8485602e+10 | H47: =G47+H109 -> 1.8424262e+10 | I47: =H47+I109 -> 1.8363316e+10 | J47: =I47+J109 -> 1.8303246e+10
...

Sheet FCFM
B2: Discounted Cash Flow Valuation
B3: $ and shares in thousands, except per share metrics
B4: Most recent fiscal year end | C4: 46053 | E4: Discount rate | G4: 0.095327269
B5: end of first fiscal year | C5: 46053 | E5: Share price | G5: {=_xll.BDP("VEEV US EQUITY", "PX_Last")} -> #NAME?
B6: most recent quarter end date | E6: Share price date | G6: =TODAY() -> 46187
B7: Valuation date | C7: 46149 | E7: Midyear adjustment (1= off) | G7: 0
B8: Portion of first year cash flows | C8: =YEARFRAC(C5,C7) -> 0.26944444
B10: Unlevered free cash flows
B11: Fiscal year | D11: 2024 | E11: 2025E | F11: 2026E | G11: 2027E | H11: 2028E | I11: 2029E | J11: 2030E
B12: Fiscal year end date | D12: 45688 | E12: =EOMONTH(D12,12) -> 46053 | F12: =EOMONTH(E12,12) -> 46418 | G12: =EOMONTH(F12,12) -> 46783 | H12: =EOMONTH(G12,12) -> 47149 | I12: =EOMONTH(H12,12) -> 47514 | J12: =EOMONTH(I12,12) -> 47879
B14: Revenue | F14: =FSM!F15 -> 1286978.6 | G14: =FSM!G15 -> 1434981.1 | H14: =FSM!H15 -> 1592829 | I14: =FSM!I15 -> 1760076.1 | J14: =FSM!J15 -> 1936083.7
B15: % growth | F15: =FSM!F15/FSM!E15-1 -> 0.12 | G15: =G14/F14-1 -> 0.115 | H15: =H14/G14-1 -> 0.11 | I15: =I14/H14-1 -> 0.105 | J15: =J14/I14-1 -> 0.1
B16: EBITDA | F16: =FSM!F30 -> 64771.53 | G16: =FSM!G30 -> 68506.124 | H16: =FSM!H30 -> 69706.89 | I16: =FSM!I30 -> 63344.368 | J16: =FSM!J30 -> 51234.887
B17: % margin | F17: =F16/F14 -> 0.050328368 | G17: =G16/G14 -> 0.047740088 | H17: =H16/H14 -> 0.043762946 | I17: =I16/I14 -> 0.035989563 | J17: =J16/J14 -> 0.026463157
B18: EBIT | F18: =FSM!F21 -> 36413.289 | G18: =FSM!G21 -> 41088.614 | H18: =FSM!H21 -> 41166.104 | I18: =FSM!I21 -> 35358.416 | J18: =FSM!J21 -> 21542.024
B19: % margin | F19: =F18/F14 -> 0.028293625 | G19: =G18/G14 -> 0.028633558 | H19: =H18/H14 -> 0.025844647 | I19: =I18/I14 -> 0.020089141 | J19: =J18/J14 -> 0.011126597
B21: Tax on EBIT | F21: =F18*-1*F22 -> -32.409139 | G21: =G18*-1*G22 -> -36.570348 | H21: =H18*-1*H22 -> -36.639316 | I21: =I18*-1*I22 -> -31.470265 | J21: =J18*-1*J22 -> -19.173178
B22: Tax rate | F22: =FSM!F40 -> 0.00089003605 | G22: =FSM!G40 -> 0.00089003605 | H22: =FSM!H40 -> 0.00089003605 | I22: =FSM!I40 -> 0.00089003605 | J22: =FSM!J40 -> 0.00089003605
B23: NOPAT | F23: =F18+F21 -> 36380.879 | G23: =G18+G21 -> 41052.044 | H23: =H18+H21 -> 41129.464 | I23: =I18+I21 -> 35326.946 | J23: =J18+J21 -> 21522.85
B25: Depreciation & Amortization | F25: =FSM!F29 -> 28358.242 | G25: =FSM!G29 -> 27417.51 | H25: =FSM!H29 -> 28540.786 | I25: =FSM!I29 -> 27985.952 | J25: =FSM!J29 -> 29692.863
B26: Stock Based Compensation | F26: =FSM!F31 -> 0 | G26: =FSM!G31 -> 0 | H26: =FSM!H31 -> 0 | I26: =FSM!I31 -> 0 | J26: =FSM!J31 -> 0
B27: Change in net working capital | F27: =F33-E33 -> 6.1918171e+08 | G27: =G33-F33 -> 57176496 | H27: =H33-G33 -> 58803692 | I27: =I33-H33 -> 59937101 | J27: =J33-I33 -> 60509246
B28: Capital expenditures | F28: =FSM!F99 -> -30000 | G28: =FSM!G99 -> -32000 | H28: =FSM!H99 -> -32000 | I28: =FSM!I99 -> -32000 | J28: =FSM!J99 -> -32000
B29: as a % of revenue | F29: =F28/F14 -> -0.023310412 | G29: =G28/G14 -> -0.022299945 | H29: =H28/H14 -> -0.020090041 | I29: =I28/I14 -> -0.018181032 | J29: =J28/J14 -> -0.016528211
B31: Unlevered free cash flows | F31: =F23+F25+F27+F28+F26 -> 6.1921645e+08 | G31: =G23+G25+G27+G28+G26 -> 57212965 | H31: =H23+H25+H27+H28+H26 -> 58841362 | I31: =I23+I25+I27+I28+I26 -> 59968414 | J31: =J23+J25+J27+J28+J26 -> 60528462
F32: =F31/F14 -> 481.13968 | G32: =G31/G14 -> 39.870188 | H32: =H31/H14 -> 36.941418 | I32: =I31/I14 -> 34.07149 | J32: =J31/J14 -> 31.26335
B33: Net working capital | E33: =SUM(FSM!E49:E51)-SUM(FSM!E61:E63) -> 1307430 | F33: =SUM(FSM!F49:F51)-SUM(FSM!F61:F63) -> 6.2048914e+08 | G33: =SUM(FSM!G49:G51)-SUM(FSM!G61:G63) -> 6.7766563e+08 | H33: =SUM(FSM!H49:H51)-SUM(FSM!H61:H63) -> 7.3646933e+08 | I33: =SUM(FSM!I49:I51)-SUM(FSM!I61:I63) -> 7.9640643e+08 | J33: =SUM(FSM!J49:J51)-SUM(FSM!J61:J63) -> 8.5691567e+08
B35: ="Present value of UFCF on "&TEXT(C7,"mmm dd, yyyy") -> Present value of UFCF on May 07, 2026
F36: 1 Yr- Target | G36: 1 | H36: =G36+1 -> 2 | I36: =H36+1 -> 3 | J36: =I36+1 -> 4
B37: Date for discounting cash flows | D37: Stub adj. | F37: =EOMONTH(C7,12) -> 46538 | G37: =IF($G$7=1,G12,AVERAGE(G12,F12)) -> 46600.5 | H37: =IF($G$7=1,H12,AVERAGE(H12,G12)) -> 46966 | I37: =IF($G$7=1,I12,AVERAGE(I12,H12)) -> 47331.5 | J37: =IF($G$7=1,J12,AVERAGE(J12,I12)) -> 47696.5
B38: Unlevered free cash flows stub adjusted | D38: =C8 -> 0.26944444 | G38: =G31*D38 -> 15415716 | H38: =H31 -> 58841362 | I38: =I31 -> 59968414 | J38: =J31 -> 60528462
B39: Present value of unlevered free cash flows | G39: =G38/(1+$G$4)^((G37-$F$37)/365) -> 15177229 | H39: =H38/(1+$G$4)^((H37-$F$37)/365) -> 52882677 | I39: =I38/(1+$G$4)^((I37-$F$37)/365) -> 49198879 | J39: =J38/(1+$G$4)^((J37-$F$37)/365) -> 45336541
B41: Terminal value- growth to perpetuity | F41: Shares outstanding
B42: Long term growth rate | D42: 0.025 | F42: Shares outstanding | J42: =163330933/1000 -> 163330.93 | K42: Update
B43: 2031 FCF | D43: =J31*(1+D42) -> 62041674 | F43: RSUs | J43: 0
B44: Terminal value in 2030 | D44: =D43/(G4-D42) -> 8.8218517e+08 | F44: PSUs | J44: 0
B45: Present value of terminal value | D45: =D44/(1+$G$4)^(($J$37-F37)/365) -> 6.6076723e+08 | F45: Stock options | J45: =15134876/1000 -> 15134.876
B46: Present value of stage 1 cash flows | D46: =SUM(H39:J39) -> 1.474181e+08 | F46: Dilutive shares outstanding | J46: =SUM(J42:J45) -> 178465.81
B47: Total enterprise value (TEV) | D47: =SUM(D45:D46) -> 8.0818533e+08
B49: Terminal value as % of TEV | D49: =D45/D47 -> 0.8175937
...

Sheet RIM
B2: Residual Income Valuation
B3: $ and shares in thousands, except per share
B5: Most recent fiscal year end | C5: =FCFM!C4 -> 46053 | E5: Cost of Equity | G5: 0.10999824
B6: end of first fiscal year | C6: =FCFM!C5 -> 46053 | E6: Share price | G6: =FCFM!G5 -> #NAME?
B7: most recent quarter end date | C7: =FCFM!C6 -> 0 | E7: Share price date | G7: =TODAY() -> 46187
B8: Valuation date | C8: =FCFM!C7 -> 46149
B10: Residual Income
B11: Fiscal year | D11: 2025E | E11: 2026E | F11: 2027E | G11: 2028E | H11: 2029E | I11: 2030E
B12: Fiscal year end date | D12: 46053 | E12: =EOMONTH(D12,12) -> 46418 | F12: =EOMONTH(E12,12) -> 46783 | G12: =EOMONTH(F12,12) -> 47149 | H12: =EOMONTH(G12,12) -> 47514 | I12: =EOMONTH(H12,12) -> 47879
E14: 1 Yr- Target | F14: 1 | G14: 2 | H14: 3 | I14: 4
E15: =EOMONTH(C8,12) -> 46538 | F15: =F12 -> 46783 | G15: =G12 -> 47149 | H15: =H12 -> 47514 | I15: =I12 -> 47879
B16: Earnings per share | C16: ω: | D16: 0.5 | E16: =FSM!F268 -> 103199.62 | F16: =FSM!G268 -> 2.120108 | G16: =FSM!H268 -> 2.9538717 | H16: =FSM!I268 -> 3.3476109 | I16: =FSM!J268 -> 3.3156755
B17: Book value per share | E17: =FSM!F271 -> 103238.48 | F17: =E17+F16 -> 103240.6 | G17: =F17+G16 -> 103243.55 | H17: =G17+H16 -> 103246.9 | I17: =H17+I16 -> 103250.21
B18: Residual Income | F18: =F16-(F17*$G$5) -> -11354.164 | G18: =G16-(G17*$G$5) -> -11353.655 | H18: =H16-(H17*$G$5) -> -11353.629 | I18: =I16-(I17*$G$5) -> -11354.026
B19: Present Value of Residual Incomes | F19: =F18/(1+$G$5)^((F15-$E$15)/365) -> -10586.035 | G19: =G18/(1+$G$5)^((G15-$E$15)/365) -> -9533.8302 | H19: =H18/(1+$G$5)^((H15-$E$15)/365) -> -8589.0306 | I19: =I18/(1+$G$5)^((I15-$E$15)/365) -> -7738.148
K20: If time adjust for foreign currency translation gains / losss, hedginnig gain / loss
B21: Terminal value- growth to perpetuity
B22: Terminal growth rate | D22: =FCFM!D42 -> 0.025
B23: 2031 Residual income | D23: =I18*(1+D22) -> -11637.877
B24: Terminal value | D24: =D23/(1+G5-D16) -> -19078.541
B25: Present Value of terminal value | D25: =D24/(1+$G$5)^((I15-E15)/365) -> -13002.663
B26: Present value of term 1 Residual Income | D26: =SUM(G19:I19) -> -25861.009
B27: 2026 BVPS | D27: =F17 -> 103240.6
B28: 12-month price target | D28: =SUM(D25:D27) -> 64376.925
B30: Sensitvity Analysis
C32: Equity value per share
C33: Long term growth rate (g):
C34: =D28 -> 64376.925 | D34: =E34-0.0025 -> 0.02 | E34: =F34-0.0025 -> 0.0225 | F34: 0.025 | G34: =F34+0.0025 -> 0.0275 | H34: =G34+0.0025 -> 0.03
B35: Discount rate | C35: =C36-0.005 -> 0.099998237 | D35: 66807.004 | E35: 66776.703 | F35: 66746.402 | G35: 66716.1 | H35: 66685.799
C36: =C37-0.005 -> 0.10499824 | D36: 65602.032 | E36: 65570.999 | F36: 65539.967 | G36: 65508.934 | H36: 65477.902
C37: 0.10999824 | D37: 64440.352 | E37: 64408.639 | F37: 64376.925 | G37: 64345.211 | H37: 64313.497
C38: =C37+0.005 -> 0.11499824 | D38: 63320.355 | E38: 63288.008 | F38: 63255.66 | G38: 63223.312 | H38: 63190.965
C39: =C38+0.005 -> 0.11999824 | D39: 62240.498 | E39: 62207.561 | F39: 62174.625 | G39: 62141.689 | H39: 62108.752
B40: Check | C40: =IF(C37=G5,"Ok","Check") -> Ok
C41: Equity value per share
C42: ω
C43: =D28 -> 64376.925 | D43: =E43-0.1 -> 0.3 | E43: =F43-0.1 -> 0.4 | F43: 0.5 | G43: =F43+0.1 -> 0.6 | H43: =G43+0.1 -> 0.7
B44: Discount rate | C44: =C45-0.005 -> 0.099998237 | D44: 69852.289 | E44: 68521.195 | F44: 66746.402 | G44: 64261.689 | H44: 60534.614
C45: =C46-0.005 -> 0.10499824 | D45: 68701.048 | E45: 67344.698 | F45: 65539.967 | G45: 63020.488 | H45: 59256.816
C46: 0.10999824 | D46: 67587.466 | E46: 66208.29 | F46: 64376.925 | G46: 61827.374 | H46: 58034.135
...

Sheet MVAM
B2: Market Value Added Valuation
B3: $ and shares in thousands, except per share
B5: Most recent fiscal year end | C5: =FCFM!C4 -> 46053 | E5: WACC | G5: 0.10974247
B6: end of first fiscal year | C6: =FCFM!C5 -> 46053 | E6: Share price | G6: {=_xll.BDP("VEEV US EQUITY", "PX_Last")} -> #NAME?
B7: most recent quarter end date | E7: Share price date | G7: =TODAY() -> 46187
B8: Valuation date | C8: =FCFM!C7 -> 46149
B10: Residual Income
B11: Fiscal year | D11: 2025E | E11: 2026E | F11: 2027E | G11: 2028E | H11: 2029E | I11: 2030E
B12: Fiscal year end date | D12: 46022 | E12: 46387 | F12: 46752 | G12: 47118 | H12: 47483 | I12: 47848
E14: 1 Yr- Target | F14: 1 | G14: 2 | H14: 3 | I14: 4
E15: =EOMONTH(C8,12) -> 46538 | F15: 46752 | G15: 47118 | H15: 47483 | I15: 47848
B16: NOPAT | E16: =FCFM!F23 -> 36380.879 | F16: =FCFM!G23 -> 41052.044 | G16: =FCFM!H23 -> 41129.464 | H16: =FCFM!I23 -> 35326.946 | I16: =FCFM!J23 -> 21522.85 | J16: =I16*(1+D23) -> 22060.922
B17: CAPITAL | E17: =SUM(FSM!F72:F75,FSM!F66,FSM!F68) -> 1.9168978e+10 | F17: =SUM(FSM!G72:G75,FSM!G66,FSM!G68) -> 1.9169368e+10 | G17: =SUM(FSM!H72:H75,FSM!H66,FSM!H68) -> 1.916993e+10 | H17: =SUM(FSM!I72:I75,FSM!I66,FSM!I68) -> 1.9170581e+10 | I17: =SUM(FSM!J72:J75,FSM!J66,FSM!J68) -> 1.9171241e+10
B18: EROIC | F18: =G16/F17 -> 2.1455827e-06 | G18: =H16/G17 -> 1.8428313e-06 | H18: =I16/H17 -> 1.122702e-06 | I18: =J16/I17 -> 1.1507299e-06
B19: Market Value Added | F19: =F17*(F18-$G$5) -> -2.1036527e+09 | G19: =G17*(G18-$G$5) -> -2.1037202e+09 | H19: =H17*(H18-$G$5) -> -2.1038055e+09 | I19: =I17*(I18-$G$5) -> -2.1038774e+09
B20: Present value of Market Value Added | F20: =F19/(1+$G$5)^((F15-E15)/365) -> -1.9790656e+09 | G20: =G19/(1+$G$5)^((G15-F15)/365) -> -1.8951425e+09 | H20: =H19/(1+$G$5)^((H15-G15)/365) -> -1.8957601e+09 | I20: =I19/(1+$G$5)^((I15-H15)/365) -> -1.8958249e+09
B22: Terminal value- growth to perpetuity
B23: Long term growth rate | D23: =FCFM!D42 -> 0.025
B24: 2031 MVA | D24: =I20*(1+D23) -> -1.9432205e+09
B25: Terminal value in 2030 | D25: =D24/(G5-D23) -> -2.2930892e+10
B26: Present value of terminal value | D26: =D25/(1+$G$5)^((I15-E15)/365) -> -1.5780348e+10
B27: Present value of stage 1 cash flows | D27: =SUM(G20:I20) -> -5.6867274e+09
B28: Capital 2026 | D28: =E17 -> 1.9168978e+10
B29: Total enterprise value (TEV) | D29: =SUM(D26:D28) -> -2.2980978e+09
B31: Terminal value as % of TEV | D31: =D26/D29 -> 6.8666999
B32: Stage 1 cash flows as % of TEV | D32: =(D27+D28)/D29 -> -5.8666999
B34: Net debt
B35: Source document | D35: 10-K
B36: Source date | D36: 46066
B37: Gross debt and equivalents
B38: Debt | D38: =FCFM!D57 -> 95859
B39: Minority Interest | D39: =FCFM!D58 -> 0
B40: Preferred stock | D40: =FCFM!D59 -> 0
B41: Nonoperating assets
B42: Cash | D42: =FCFM!D61 -> 6560814
B44: Net debt | D44: =SUM(D38:D40)-D42 -> -6464955
B46: Valuation- growth to perpetuity
B47: Enterprise value | D47: =D29 -> -2.2980978e+09
B48: Net debt | D48: =D44 -> -6464955
B49: Equity value | D49: =D47-D48 -> -2.2916329e+09
...

Sheet Relative Valuation
B2: Company name | D2: VEEV US EQUITY
B3: last closing price | C3: PX_Last | D3: {=_xll.BDP($D$2,C3,"3/2/26")} -> #NAME?
B4: 52 week high | C4: HIGH_52WEEK | D4: {=_xll.BDP($D$2,C4,$C$9)} -> #NAME?
B5: 52 week low | C5: LOW_52WEEK | D5: {=_xll.BDP($D$2,C5,$C$9)} -> #NAME?
B6: Market cap | C6: CUR_MKT_CAP | D6: {=_xll.BDP($D$2,C6,$C$9)/1000000} -> #NAME?
B7: Shares outstanding | C7: EQY_SH_OUT | D7: {=_xll.BDP($D$2,C7,$C$9)} -> #NAME?
B8: YTD return | C8: CHG_PCT_YTD | D8: {=_xll.BDP($D$2,C8,$C$9)} -> #NAME?
D10: Equity 1 | E10: Equity 2 | F10: Equity 3 | G10: Equity 4 | H10: Equity 5 | I10: Peer group average | J10: My company
D11: IQV US EQUITY | E11: CRM US EQUITY | F11: DOCS US EQUITY | G11: MEDP US EQUITY | J11: =D2 -> VEEV US EQUITY
B13: Multiples | K13: Include?
B14: Price to sales ratio | C14: PX_TO_SALES_RATIO | D14: {=_xll.BDP(D$11,$C14)} -> #NAME? | E14: {=_xll.BDP(E$11,$C14)} -> #NAME? | F14: {=_xll.BDP(F$11,$C14)} -> #NAME? | G14: {=_xll.BDP(G$11,$C14)} -> #NAME? | I14: =AVERAGE(D14:H14) -> #NAME? | J14: {=_xll.BDP(J$11,C14)} -> #NAME? | K14: No
B15: Price to book ratio | C15: PX_TO_BOOK_RATIO | D15: {=_xll.BDP(D$11,$C15)} -> #NAME? | E15: {=_xll.BDP(E$11,$C15)} -> #NAME? | F15: {=_xll.BDP(F$11,$C15)} -> #NAME? | G15: {=_xll.BDP(G$11,$C15)} -> #NAME? | I15: =AVERAGE(D15:H15) -> #NAME? | J15: {=_xll.BDP(J$11,C15)} -> #NAME? | K15: Yes
B16: Price to EBITDA | C16: PX_TO_EBITDA | D16: {=_xll.BDP(D$11,$C16)} -> #NAME? | E16: {=_xll.BDP(E$11,$C16)} -> #NAME? | F16: {=_xll.BDP(F$11,$C16)} -> #NAME? | G16: {=_xll.BDP(G$11,$C16)} -> #NAME? | I16: =AVERAGE(D16:H16) -> #NAME? | J16: {=_xll.BDP(J$11,C16)} -> #NAME? | K16: No
B17: Price to FCF | C17: PX_TO_FREE_CASH_FLOW | D17: {=_xll.BDP(D$11,$C17)} -> #NAME? | E17: {=_xll.BDP(E$11,$C17)} -> #NAME? | F17: {=_xll.BDP(F$11,$C17)} -> #NAME? | G17: {=_xll.BDP(G$11,$C17)} -> #NAME? | I17: =AVERAGE(D17:H17) -> #NAME? | J17: {=_xll.BDP(J$11,C17)} -> #NAME? | K17: No
B18: Price to EPS | C18: PX_TO_EPS_BEFORE_ABNORMAL_ITEMS | D18: {=_xll.BDP(D$11,$C18)} -> #NAME? | E18: {=_xll.BDP(E$11,$C18)} -> #NAME? | F18: {=_xll.BDP(F$11,$C18)} -> #NAME? | G18: {=_xll.BDP(G$11,$C18)} -> #NAME? | I18: =AVERAGE(D18:H18) -> #NAME? | J18: {=_xll.BDP(J$11,C18)} -> #NAME? | K18: Yes
B19: EV to trailing 12M sales | C19: EV_TO_T12M_SALES | D19: {=_xll.BDP(D$11,$C19)} -> #NAME? | E19: {=_xll.BDP(E$11,$C19)} -> #NAME? | F19: {=_xll.BDP(F$11,$C19)} -> #NAME? | G19: {=_xll.BDP(G$11,$C19)} -> #NAME? | I19: =AVERAGE(D19:H19) -> #NAME? | J19: {=_xll.BDP(J$11,C19)} -> #NAME? | K19: Yes
B21: Data pull | D21: 44227 | E21: =D21+365 -> 44592 | F21: =E21+365 -> 44957 | G21: =F21+366 -> 45323 | H21: =G21+365 -> 45688
B22: Trailing 12M sales per share | C22: TRAIL_12M_SALES_PER_SH | D22: {=_xll.BDH($D$2,$C22,D$21)} -> 9.7215 | E22: {=_xll.BDH($D$2,$C22,E$21)} -> 12.0754 | F22: {=_xll.BDH($D$2,$C22,F$21)} -> 13.8708 | G22: {=_xll.BDH($D$2,$C22,G$21)} -> #N/A N/A | H22: {=_xll.BDH($D$2,$C22,H$21)} -> 16.966
B23: Trailing 12M net sales | C23: TRAIL_12M_NET_SALES | D23: {=_xll.BDH($D$2,$C23,D$21)} -> 1465.069 | E23: {=_xll.BDH($D$2,$C23,E$21)} -> 1850.777 | F23: {=_xll.BDH($D$2,$C23,F$21)} -> 2155.06 | G23: {=_xll.BDH($D$2,$C23,G$21)} -> #N/A N/A | H23: {=_xll.BDH($D$2,$C23,H$21)} -> 2746.619
B24: Short and long term debt | C24: SHORT_AND_LONG_TERM_DEBT | D24: {=_xll.BDH($D$2,$C24,D$21)} -> 63.118 | E24: {=_xll.BDH($D$2,$C24,E$21)} -> 54.588 | F24: {=_xll.BDH($D$2,$C24,F$21)} -> 60.976 | G24: {=_xll.BDH($D$2,$C24,G$21)} -> #N/A N/A | H24: {=_xll.BDH($D$2,$C24,H$21)} -> 75.775
B25: Cash and cash equivalents | C25: BS_CASH_NEAR_CASH_ITEM | D25: {=_xll.BDH($D$2,$C25,D$21)} -> 730.504 | E25: {=_xll.BDH($D$2,$C25,E$21)} -> 1138.04 | F25: {=_xll.BDH($D$2,$C25,F$21)} -> 886.465 | G25: {=_xll.BDH($D$2,$C25,G$21)} -> #N/A N/A | H25: {=_xll.BDH($D$2,$C25,H$21)} -> 1118.785
B26: Book value per share | C26: BOOK_VAL_PER_SH | D26: {=_xll.BDH($D$2,$C26,D$21)} -> 14.9044 | E26: {=_xll.BDH($D$2,$C26,E$21)} -> 20.882 | F26: {=_xll.BDH($D$2,$C26,F$21)} -> 23.4842 | G26: {=_xll.BDH($D$2,$C26,G$21)} -> #N/A N/A | H26: {=_xll.BDH($D$2,$C26,H$21)} -> 35.873
B27: EPS from Continuing Operations | C27: T12_EPS_CONT_OPS | D27: {=_xll.BDH($D$2,$C27,D$21)} -> 2.52 | E27: {=_xll.BDH($D$2,$C27,E$21)} -> 2.79 | F27: {=_xll.BDH($D$2,$C27,F$21)} -> 3.13 | G27: {=_xll.BDH($D$2,$C27,G$21)} -> #N/A N/A | H27: {=_xll.BDH($D$2,$C27,H$21)} -> 4.2833
B28: Trailing 12M FCF per share | C28: TRAIL_12M_FREE_CASH_FLOW_PER_SH | D28: {=_xll.BDH($D$2,$C28,D$21)} -> 3.6101 | E28: {=_xll.BDH($D$2,$C28,E$21)} -> 4.9101 | F28: {=_xll.BDH($D$2,$C28,F$21)} -> 4.9514 | G28: {=_xll.BDH($D$2,$C28,G$21)} -> #N/A N/A | H28: {=_xll.BDH($D$2,$C28,H$21)} -> 6.6189
B29: Trailing 12M EBITDA per share | C29: TRAIL_12M_EBITDA_PER_SHARE | D29: {=_xll.BDH($D$2,$C29,D$21)} -> 2.7888 | E29: {=_xll.BDH($D$2,$C29,E$21)} -> 3.5627 | F29: {=_xll.BDH($D$2,$C29,F$21)} -> 3.2462 | G29: {=_xll.BDH($D$2,$C29,G$21)} -> #N/A N/A | H29: {=_xll.BDH($D$2,$C29,H$21)} -> 4.6005
B31: Multiple | D31: Competitors' averages | E31: Price
B32: Price to sales ratio | D32: =I14 -> #NAME? | E32: =IF(K14="Yes",D32*H22,"")
B33: Price to book ratio | D33: =I15 -> #NAME? | E33: =IF(K15="Yes",D33*H26,"") -> #NAME?
B34: Price to EBITDA | D34: =I16 -> #NAME? | E34: =IF(K16="Yes",D34*H29,"")
B35: Price to FCF | D35: =I17 -> #NAME? | E35: =IF(K17="Yes",D35*H28,"")
B36: Price to EPS | D36: =I18 -> #NAME? | E36: =IF(K18="Yes",D36*H27,"") -> #NAME?
B37: EV to trailing 12M sales | D37: =I19 -> #NAME? | E37: =IF(K19="Yes",((D37*H23)-H24+H25)/D7,"") -> #NAME?
B38: Final target price | E38: =AVERAGE(E32:E37) -> #NAME?
B40: Last Price | E40: =D3 -> #NAME?
B41: Potential Upside | E41: =E38/E40-1 -> #NAME?

Sheet Blended Valuation
B2: Models | C2: 12-month Price Target | D2: Weight | E2: Include?
B3: FCFM | C3: =FCFM!D70 -> 4564.7415 | D3: 0.25 | E3: Yes
B4: RIM | C4: =RIM!D28 -> 64376.925 | D4: 0.125 | E4: Yes
B5: MVAM | C5: =MVAM!D51 -> -12840.739 | D5: 0.125 | E5: Yes
B6: COMPS | C6: ='Relative Valuation'!E38 -> #NAME? | D6: 0.5 | E6: Yes
B7: 12 Month Target Price | D7: =SUM(D3:D6) -> 1
B9: Models | C9: Weighted Valuation | F9: Current Price | G9: =FCFM!G5 -> #NAME?
B10: FCFM | C10: =IF(E3="Yes",C3*D3,0) -> 1141.1854 | F10: 12-Month Target | G10: =C14 -> #NAME?
B11: RIM | C11: =IF(E4="Yes",C4*D4,0) -> 8047.1156 | F11: Return | G11: =G10/G9-1 -> #NAME?
B12: MVAM | C12: =IF(E5="Yes",C5*D5,0) -> -1605.0924
B13: COMPS | C13: =IF(E6="Yes",C6*D6,0) -> #NAME?
B14: Blended 12-month price target | C14: =SUM(C10:C13) -> #NAME?
B15: Potential Upside
B17: Football Field
C18: Low | D18: Difference | E18: High
B19: FCFM | C19: =MIN(FCFM!D82:H86) -> 3246.9085 | D19: =E19-C19 -> 1312.4737 | E19: =MAX(FCFM!D82:H86) -> 4559.3823
B20: RIM | C20: =MIN(RIM!D35:H39,RIM!D44:H48) -> 55744.16 | D20: =E20-C20 -> 14108.129 | E20: =MAX(RIM!D35:H39,RIM!D44:H48) -> 69852.289
B21: MVAM | C21: =MIN(MVAM!D58:H62) -> -24066.326 | D21: =E21-C21 -> 18774.419 | E21: =MAX(MVAM!D58:H62) -> -5291.9077
B22: COMPS | C22: =0.95*C6 -> #NAME? | D22: =E22-C22 -> #NAME? | E22: =1.05*C6 -> #NAME?

Sheet WACC
B2: Ticker | C2: Levered Beta | D2: Tax Rate | E2: Debt/Equity | F2: Unlevered Beta | G2: Cash | H2: Firm Value | I2: Cash/ firm value | J2: Cash adj. unl beta
B3: IQV US EQUITY | C3: 1.12 | D3: {=_xll.BDP($B3,$N$9)/100} -> #NAME? | E3: {=_xll.BDP($B3,$N$9)/100} -> #NAME? | F3: =C3/(1+(1-D3)*E3) -> #NAME? | G3: {=_xll.BDP($B3,$N$11)} -> #NAME? | H3: {=_xll.BDP($B3,$N$12)} -> #NAME? | I3: =G3/H3 -> #NAME? | J3: =F3/(1-I3) -> #NAME?
B4: CRM US EQUITY | C4: 1.094 | D4: {=_xll.BDP($B4,$N$9)/100} -> #NAME? | E4: {=_xll.BDP($B4,$N$9)/100} -> #NAME? | F4: =C4/(1+(1-D4)*E4) -> #NAME? | G4: {=_xll.BDP($B4,$N$11)} -> #NAME? | H4: {=_xll.BDP($B4,$N$12)} -> #NAME? | I4: =G4/H4 -> #NAME? | J4: =F4/(1-I4) -> #NAME? | N4: {=_xll.BDP(N13,N11)} -> #NAME?
B5: DOCS US EQUITY | C5: 1.235 | D5: {=_xll.BDP($B5,$N$9)/100} -> #NAME? | E5: {=_xll.BDP($B5,$N$9)/100} -> #NAME? | F5: =C5/(1+(1-D5)*E5) -> #NAME? | G5: {=_xll.BDP($B5,$N$11)} -> #NAME? | H5: {=_xll.BDP($B5,$N$12)} -> #NAME? | I5: =G5/H5 -> #NAME? | J5: =F5/(1-I5) -> #NAME? | N5: {=_xll.BDP(N13,N12)} -> #NAME?
B6: MEDP US EQUITY | C6: 1.311 | D6: {=_xll.BDP($B6,$N$9)/100} -> #NAME? | E6: {=_xll.BDP($B6,$N$9)/100} -> #NAME? | F6: =C6/(1+(1-D6)*E6) -> #NAME? | G6: {=_xll.BDP($B6,$N$11)} -> #NAME? | H6: {=_xll.BDP($B6,$N$12)} -> #NAME? | I6: =G6/H6 -> #NAME? | J6: =F6/(1-I6) -> #NAME? | N6: =N4/N5 -> #NAME?
B7: ORCL US EQUITY | C7: 1.363 | D7: {=_xll.BDP($B7,$N$9)/100} -> #NAME? | E7: {=_xll.BDP($B7,$N$9)/100} -> #NAME? | F7: =C7/(1+(1-D7)*E7) -> #NAME? | G7: {=_xll.BDP($B7,$N$11)} -> #NAME? | H7: {=_xll.BDP($B7,$N$12)} -> #NAME? | I7: =G7/H7 -> #NAME? | J7: =F7/(1-I7) -> #NAME?
I8: Average | J8: =AVERAGE(J3:J7) -> #NAME?
B9: Cost of Equity | I9: VEEV cash/firm value | J9: =N6 -> #NAME? | N9: EFF_TAX_RATE
B10: Rrf | C10: {=_xll.BDP(N14,"PX_LAST")/100} -> #NAME? | I10: VEEV unlevered beta | J10: =J8*(1-J9) -> #NAME? | N10: TOT_DEBT_TO_TOT_EQY
B11: B | C11: =J13 -> #NAME? | I11: VEEV tax rate | J11: {=_xll.BDP(N13,N9)/100} -> #NAME? | N11: CASH_AND_MARKETABLE_SECURITIES
B12: ERP | C12: 0.0808 | I12: D/E Ratio | J12: {=_xll.BDP(N13,N10)/100} -> #NAME? | N12: CURR_ENTP_VAL
B13: Cost of E | C13: =C10+C11*C12 -> #NAME? | I13: VEEV levered beta | J13: =J10*(1+(1-J11)*J12) -> #NAME? | N13: VEEV US EQUITY
N14: USGG10YR Index
B15: Cost of Debt
B16: pre-tax cost | C16: 0.048 | N16: CUR_MKT_CAP
B17: tax rate | C17: =J11 -> #NAME?
B18: post-tax cost | C18: =C16*(1-C17) -> #NAME? | N18: {=_xll.BDP(N13,N16)} -> #NAME?
N19: =N18/1000 -> #NAME?
B20: Debt | C20: =FSM!E66+FSM!E68 -> 95859
B21: Equity | C21: =N19 -> #NAME?
B23: Wd | C23: =C20/SUM(C20:C21) -> #NAME? | E23: 0.2
B24: We | C24: =C21/SUM(C20:C21) -> #NAME? | E24: 0.8
B26: WACC | C26: =C23*C18+C24*C13 -> #NAME?
B28: Rs | C28: 0.10999824
B29: WACC | C29: 0.10974247 | E29: =E23*C18+E24*C13 -> #NAME?
