Workbook

Sheet Historicals
C2: INCOME STATEMENT
C3: Fiscal year | D3: 2020 | E3: 2021 | F3: 2022 | G3: 2023 | H3: 2024 | I3: 2025
C4: Fiscal year end date | D4: 44196 | E4: 44561 | F4: 44926 | G4: 45291 | H4: 45657 | I4: 46022 | J4: 46022
C5: in $ millions, except share amounts
P6: PX_LAST
C7: Service revenue and other | D7: 109872 | E7: 110449 | F7: 109625 | G7: 109652 | H7: 111571 | I7: 112721 | O7: T US EQUITY | Q7: {=_xll.BDP(O7,P6)} -> 25.26
C8: Wireless Equipment revenues | D8: 18420 | E8: 23164 | F8: 27210 | G8: 24322 | H8: 23217 | I8: 25470
C9: Total Operating Revenue | D9: =SUM(D7:D8) -> 128292 | E9: =SUM(E7:E8) -> 133613 | F9: =SUM(F7:F8) -> 136835 | G9: =SUM(G7:G8) -> 133974 | H9: =SUM(H7:H8) -> 134788 | I9: =SUM(I7:I8) -> 138191
C10: Cost of services | D10: -31401 | E10: -31234 | F10: -28637 | G10: -28100 | H10: -27997 | I10: -27789 | K10: =SUM(H10:H11) -> -54097 | L10: =SUM(I10:I11) -> -56765 | O10: =D7 -> 109872 | P10: =E7 -> 110449 | Q10: =F7 -> 109625 | R10: =G7 -> 109652 | S10: =H7 -> 111571 | T10: =I7 -> 112721
C11: Cost of Wirelss Equipment | D11: -19800 | E11: -25067 | F11: -30496 | G11: -26787 | H11: -26100 | I11: -28976 | O11: {=_xll.BDH(O7, "CF_FREE_CASH_FLOW", D4,I4, "Per=Y","DIR=H")} -> 44196 | P11: 44561 | Q11: 44926 | R11: 45291 | S11: 45657 | T11: 46022
C12: Gross Profit | D12: =SUM(D9:D11) -> 77091 | E12: =SUM(E9:E11) -> 77312 | F12: =SUM(F9:F11) -> 77702 | G12: =SUM(G9:G11) -> 79087 | H12: =SUM(H9:H11) -> 80691 | I12: =SUM(I9:I11) -> 81426 | O12: 27455 | P12: 26413 | Q12: 12397 | R12: 20461 | S12: 18508 | T12: 19442
C13: Selling, General, and administrative expensse | D13: -31573 | E13: -28658 | F13: -30136 | G13: -32745 | H13: -34113 | I13: -33818
C14: Depreciation and amortization expense | D14: -16720 | E14: -16206 | F14: -17099 | G14: -17624 | H14: -17892 | I14: -18349
C15: Verizon Business Group goodwill impairment | D15: 0 | E15: 0 | F15: 0 | G15: -5841 | H15: 0 | I15: 0
C16: Operating Income | D16: =SUM(D12:D15) -> 28798 | E16: =SUM(E12:E15) -> 32448 | F16: =SUM(F12:F15) -> 30467 | G16: =SUM(G12:G15) -> 22877 | H16: =SUM(H12:H15) -> 28686 | I16: =SUM(I12:I15) -> 29259
C17: Equity in earnings (losses) of unconsolidates busiensses | D17: -45 | E17: 145 | F17: 44 | G17: -53 | H17: -53 | I17: 0 | O17: =_xll.BDH($O$7, "CF_FREE_CASH_FLOW", $D$4, $I$4, "Dir", "H", "Period", $O$17) -> #NAME?
C18: Other income expense | D18: -539 | E18: 312 | F18: 1373 | G18: -313 | H18: 995 | I18: 107 | N18: Cap Ex | O18: {=_xll.BDH($O$7,"CAPITAL_EXPEND",D4)} -> -2392 | P18: {=_xll.BDH($O$7,"CAPITAL_EXPEND",E4)} -> -3494 | Q18: {=_xll.BDH($O$7,"CAPITAL_EXPEND",F4)} -> -4229 | R18: {=_xll.BDH($O$7,"CAPITAL_EXPEND",G4)} -> -4601 | S18: {=_xll.BDH($O$7,"CAPITAL_EXPEND",H4)} -> -6843 | T18: {=_xll.BDH($O$7,"CAPITAL_EXPEND",I4)} -> -6781
C19: Interest expense | D19: -4247 | E19: -3485 | F19: -3613 | G19: -5524 | H19: -6649 | I19: -6694
C20: Pretax Profit | D20: =SUM(D16:D19) -> 23967 | E20: =SUM(E16:E19) -> 29420 | F20: =SUM(F16:F19) -> 28271 | G20: =SUM(G16:G19) -> 16987 | H20: =SUM(H16:H19) -> 22979 | I20: =SUM(I16:I19) -> 22672
C21: Provision for income taxes | D21: -5619 | E21: -6802 | F21: -6523 | G21: -4892 | H21: -5030 | I21: -5064
C22: Net Income | D22: =SUM(D20:D21) -> 18348 | E22: =SUM(E20:E21) -> 22618 | F22: =SUM(F20:F21) -> 21748 | G22: =SUM(G20:G21) -> 12095 | H22: =SUM(H20:H21) -> 17949 | I22: =SUM(I20:I21) -> 17608
C24: Revenue Growth | E24: =E9/D9-1 -> 0.041475696 | F24: =F9/E9-1 -> 0.02411442 | G24: =G9/F9-1 -> -0.020908393 | H24: =H9/G9-1 -> 0.0060758058 | I24: =I9/H9-1 -> 0.025247055
C25: Service GP margin | D25: =(D7+D10)/D7 -> 0.7142038 | E25: =(E7+E10)/E7 -> 0.71720885 | F25: =(F7+F10)/F7 -> 0.73877309 | G25: =(G7+G10)/G7 -> 0.74373472 | H25: =(H7+H10)/H7 -> 0.74906562 | I25: =(I7+I10)/I7 -> 0.75347096
C26: Wireless Equipment GP margin | D26: =(D8+D11)/D8 -> -0.074918567 | E26: =(E8+E11)/E8 -> -0.082153341 | F26: =(F8+F11)/F8 -> -0.12076442 | G26: =(G8+G11)/G8 -> -0.10134857 | H26: =(H8+H11)/H8 -> -0.12417625 | I26: =(I8+I11)/I8 -> -0.13765214
C27: Total GP Margin | D27: =D12/D9 -> 0.60090263 | E27: =E12/E9 -> 0.57862633 | F27: =F12/F9 -> 0.56785179 | G27: =G12/G9 -> 0.59031603 | H27: =H12/H9 -> 0.59865122 | I27: =I12/I9 -> 0.58922795
C28: SG&A as a % of revenue | D28: =-D13/D9 -> 0.24610264 | E28: =-E13/E9 -> 0.21448512 | F28: =-F13/F9 -> 0.22023605 | G28: =-G13/G9 -> 0.2444131 | H28: =-H13/H9 -> 0.25308633 | I28: =-I13/I9 -> 0.24471927
C29: Profit Margin | D29: =D22/D9 -> 0.14301749 | E29: =E22/E9 -> 0.16927994 | F29: =F22/F9 -> 0.15893594 | G29: =G22/G9 -> 0.090278711 | H29: =H22/H9 -> 0.13316467 | I29: =I22/I9 -> 0.12741785
C30: D&A expense | D30: =-D14 -> 16720 | E30: =-E14 -> 16206 | F30: =-F14 -> 17099 | G30: =-G14 -> 17624 | H30: =-H14 -> 17892 | I30: =-I14 -> 18349
C31: Tax rate | D31: =D21/D20 -> -0.23444737 | E31: =E21/E20 -> -0.23120326 | F31: =F21/F20 -> -0.23073114 | G31: =G21/G20 -> -0.28798493 | H31: =H21/H20 -> -0.21889551 | I31: =I21/I20 -> -0.22335921
C33: BALANCE SHEET
C34: Fiscal year | D34: 2020 | E34: 2021 | F34: 2022 | G34: 2023 | H34: 2024 | I34: 2025
C35: Fiscal year end date | D35: 44196 | E35: 44561 | F35: 44926 | G35: 45291 | H35: 45657 | I35: 46022
C36: in $ millions, except share amounts
C38: Cash and Cash Equivalents | H38: 4194 | I38: 19048
C39: Accounts Recievable | D39: 23917 | E39: 23846 | F39: 25332 | G39: 26102 | H39: 27261 | I39: 28347
C40: Less Allowance for Credit Loss | D40: 1252 | E40: 896 | F40: 826 | G40: -1017 | H40: -1152 | I40: -1250
C41: Inventories | D41: 1796 | E41: 3055 | F41: 2388 | G41: 2057 | H41: 2247 | I41: 2441
C42: Prepaid expenses and other | H42: 7973 | I42: 8336
C43: Property, Plant, & Equipment, Net | H43: 108522 | I43: 109467
C44: Investments in unconsolidated businesses | F44: 1071 | G44: 953 | H44: 842 | I44: 785 | L44: =G44-F44 -> -118 | M44: =H44-G44 -> -111 | N44: =I44-H44 -> -57 | O44: =AVERAGE(L44:N44) -> -95.333333
...

Sheet Revenue Build

Sheet FSM
C2: ="Financial Statement Model for "&D5 -> Financial Statement Model for Verizon
C3: $ thousands, except XX
C5: Company name | D5: Verizon | F5: Operating lease discount rate | H5: 0.043
C6: Ticker | D6: VZ | F6: Financing lease discount rate | H6: 0.05
C7: Circuit breaker (1=off) | D7: 1 | F7: Weighted avg. OP lease life | H7: 8
C8: Last closing share price | D8: {=_xll.BDP("VZ US EQUITY", "PX_LAST")} -> 47.0666 | F8: Weighted avg. Fin lease life | H8: 4
C9: Last fiscal year end date | D9: 46022
C11: INCOME STATEMENT
C12: Fiscal year | D12: 2024 | E12: 2025 | F12: 2026 | G12: 2027 | H12: 2028 | I12: 2029 | J12: 2030
C13: Fiscal year end date | D13: 45657 | E13: =EOMONTH(D13,12) -> 46022 | F13: =EOMONTH(E13,12) -> 46387 | G13: =EOMONTH(F13,12) -> 46752 | H13: =EOMONTH(G13,12) -> 47118 | I13: =EOMONTH(H13,12) -> 47483 | J13: =EOMONTH(I13,12) -> 47848
C15: Revenue | D15: 134788 | E15: 138191 | F15: =E15*(1+F34) -> 141645.77 | G15: =F15*(1+G34) -> 145186.92 | H15: =G15*(1+H34) -> 148453.63 | I15: =H15*(1+I34) -> 151422.7 | J15: =I15*(1+J34) -> 154451.15
C16: Cost of Sales | D16: -54097 | E16: -56765 | F16: =-F15*(1-F35) -> -58184.125 | G16: =-G15*(1-G35) -> -59638.728 | H16: =-H15*(1-H35) -> -60980.6 | I16: =-I15*(1-I35) -> -62200.211 | J16: =-J15*(1-J35) -> -63444.216
C17: Gross Profit | D17: =SUM(D15:D16) -> 80691 | E17: =SUM(E15:E16) -> 81426 | F17: =SUM(F15:F16) -> 83461.65 | G17: =SUM(G15:G16) -> 85548.191 | H17: =SUM(H15:H16) -> 87473.026 | I17: =SUM(I15:I16) -> 89222.486 | J17: =SUM(J15:J16) -> 91006.936
C18: Selling, General, & Administrative | D18: -34113 | E18: -33818 | F18: =E18*(1+F36) -> -34156.18 | G18: =F18*(1+G36) -> -34497.742 | H18: =G18*(1+H36) -> -35187.697 | I18: =H18*(1+I36) -> -35891.451 | J18: =I18*(1+J36) -> -36609.28
C19: Depreciation and amortization | D19: -17892 | E19: -18349 | F19: =-F180 -> -21924.067 | G19: =-G180 -> -20233.066 | H19: =-H180 -> -18965.739 | I19: =-I180 -> -17775.796 | J19: =-J180 -> -17315.463
C20: Operating Profit | D20: =SUM(D17:D19) -> 28686 | E20: =SUM(E17:E19) -> 29259 | F20: =SUM(F17:F19) -> 27381.403 | G20: =SUM(G17:G19) -> 30817.383 | H20: =SUM(H17:H19) -> 33319.59 | I20: =SUM(I17:I19) -> 35555.24 | J20: =SUM(J17:J19) -> 37082.193
C21: Equity in earnings (losses) of unconsolidated businesses | D21: -53 | E21: 0 | F21: 0 | G21: 0 | H21: 0 | I21: 0 | J21: 0
C22: Other income expense | D22: 995 | E22: 107 | F22: 0 | G22: 0 | H22: 0 | I22: 0 | J22: 0
C23: Interest expense | D23: -6649 | E23: -6694 | F23: =-F253 -> -7298.539 | G23: =-G253 -> -7628.989 | H23: =-H253 -> -7959.439 | I23: =-I253 -> -8289.889 | J23: =-J253 -> -8620.339
C24: Pretax Profit | D24: =SUM(D20:D23) -> 22979 | E24: =SUM(E20:E23) -> 22672 | F24: =SUM(F20:F23) -> 20082.864 | G24: =SUM(G20:G23) -> 23188.394 | H24: =SUM(H20:H23) -> 25360.151 | I24: =SUM(I20:I23) -> 27265.351 | J24: =SUM(J20:J23) -> 28461.854
C25: Provision for income taxes | D25: -5030 | E25: -5064 | F25: =F24*F37 -> -4788.4539 | G25: =G24*G37 -> -5528.9204 | H25: =H24*H37 -> -6046.7427 | I25: =I24*I37 -> -6501.0087 | J25: =J24*J37 -> -6786.2969
C26: Net Income | D26: =SUM(D24:D25) -> 17949 | E26: =SUM(E24:E25) -> 17608 | F26: =SUM(F24:F25) -> 15294.41 | G26: =SUM(G24:G25) -> 17659.474 | H26: =SUM(H24:H25) -> 19313.408 | I26: =SUM(I24:I25) -> 20764.342 | J26: =SUM(J24:J25) -> 21675.558
C28: Depreciation and amortization | D28: =-D19 -> 17892 | E28: =-E19 -> 18349 | F28: =-F19 -> 21924.067 | G28: =-G19 -> 20233.066 | H28: =-H19 -> 18965.739 | I28: =-I19 -> 17775.796 | J28: =-J19 -> 17315.463
C29: EBITDA | D29: =D20+D28 -> 46578 | E29: =E20+E28 -> 47608 | F29: =F20+F28 -> 49305.47 | G29: =G20+G28 -> 51050.449 | H29: =H20+H28 -> 52285.329 | I29: =I20+I28 -> 53331.035 | J29: =J20+J28 -> 54397.656
C30: Stock based Compensation
C31: Adjusted EBITDA
C33: Growth rate & margins
C34: Revenue growth | E34: =E15/D15-1 -> 0.025247055 | F34: 0.025 | G34: 0.025 | H34: 0.0225 | I34: 0.02 | J34: 0.02
C35: Gross profit margin | D35: =D17/D15 -> 0.59865122 | E35: =E17/E15 -> 0.58922795 | F35: =E35 -> 0.58922795 | G35: =F35 -> 0.58922795 | H35: =G35 -> 0.58922795 | I35: =H35 -> 0.58922795 | J35: =I35 -> 0.58922795
C36: SG&A growth rate | E36: =E18/D18-1 -> -0.0086477296 | F36: 0.01 | G36: 0.01 | H36: 0.02 | I36: 0.02 | J36: 0.02
C37: Tax rate | D37: =D25/D24 -> -0.21889551 | E37: =E25/E24 -> -0.22335921 | F37: =AVERAGE(Historicals!E31:I31) -> -0.23843481 | G37: =F37 -> -0.23843481 | H37: =G37 -> -0.23843481 | I37: =H37 -> -0.23843481 | J37: =I37 -> -0.23843481
C38: SBC growth rate | F38: 0.02 | G38: 0.02 | H38: 0.02 | I38: 0.02 | J38: 0.02
C40: BALANCE SHEET
C41: Fiscal year | D41: 2024 | E41: =D41+1 -> 2025 | F41: =E41+1 -> 2026 | G41: =F41+1 -> 2027 | H41: =G41+1 -> 2028 | I41: =H41+1 -> 2029 | J41: =I41+1 -> 2030
C42: Fiscal year end date | D42: 45657 | E42: =EOMONTH(D42,12) -> 46022 | F42: =EOMONTH(E42,12) -> 46387 | G42: =EOMONTH(F42,12) -> 46752 | H42: =EOMONTH(G42,12) -> 47118 | I42: =EOMONTH(H42,12) -> 47483 | J42: =EOMONTH(I42,12) -> 47848
C44: Cash and Cash Equivalents | D44: 4194 | E44: 19048 | F44: =E44+F107 -> 21883.019 | G44: =F44+G107 -> 28921.537 | H44: =G44+H107 -> 37369.651 | I44: =H44+I107 -> 45359.13 | J44: =I44+J107 -> 54164.734
C45: Accounts Receivable | D45: 27261 | E45: 28347 | F45: =F116 -> 34010.977 | G45: =G116 -> 34861.251 | H45: =H116 -> 35645.63 | I45: =I116 -> 36358.542 | J45: =J116 -> 37085.713
C46: Less Allowance for Credit Loss | D46: -1152 | E46: -1250 | F46: =F138 -> -1420.7188 | G46: =G138 -> -1456.2367 | H46: =H138 -> -1489.0021 | I46: =I138 -> -1518.7821 | J46: =J138 -> -1549.1578
C47: Inventories | D47: 2247 | E47: 2441 | F47: =F127 -> 2357.1842 | G47: =G127 -> 2416.1138 | H47: =H127 -> 2470.4764 | I47: =I127 -> 2519.8859 | J47: =J127 -> 2570.2836
C48: Prepaid expenses and other | D48: 7973 | E48: 8336 | F48: =E48*(1+F34) -> 8544.4 | G48: =F48*(1+G34) -> 8758.01 | H48: =G48*(1+H34) -> 8955.0652 | I48: =H48*(1+I34) -> 9134.1665 | J48: =I48*(1+J34) -> 9316.8499
...

Sheet FCFM
B2: Discounted Cash Flow Valuation
B3: $ and shares in thousands, except per share
B4: Most recent fiscal year end | C4: 46022 | E4: Discount rate | G4: 0.094080346
B5: end of first fiscal year | C5: 46387 | E5: Share price | G5: {=_xll.BDP("VZ US EQUITY", "PX_Last")} -> 47.0666
B6: most recent quarter end date | E6: Share price date | G6: =TODAY() -> 46152
B7: Valuation date | C7: 46136 | E7: Midyear adjustment (1= off) | G7: 0
B8: Portion of first year cash flows | C8: =YEARFRAC(C5,C7) -> 0.68611111
B10: Unlevered free cash flows
B11: Fiscal year | D11: 2024 | E11: 2025E | F11: 2026E | G11: 2027E | H11: 2028E | I11: 2029E | J11: 2030E
B12: Fiscal year end date | D12: 45657 | E12: =EOMONTH(D12,12) -> 46022 | F12: =EOMONTH(E12,12) -> 46387 | G12: =EOMONTH(F12,12) -> 46752 | H12: =EOMONTH(G12,12) -> 47118 | I12: =EOMONTH(H12,12) -> 47483 | J12: =EOMONTH(I12,12) -> 47848
B14: Revenue | F14: =FSM!F15 -> 141645.77 | G14: =FSM!G15 -> 145186.92 | H14: =FSM!H15 -> 148453.63 | I14: =FSM!I15 -> 151422.7 | J14: =FSM!J15 -> 154451.15
B15: % growth | G15: =G14/F14-1 -> 0.025 | H15: =H14/G14-1 -> 0.0225 | I15: =I14/H14-1 -> 0.02 | J15: =J14/I14-1 -> 0.02
B16: EBITDA | F16: =FSM!F29 -> 49305.47 | G16: =FSM!G29 -> 51050.449 | H16: =FSM!H29 -> 52285.329 | I16: =FSM!I29 -> 53331.035 | J16: =FSM!J29 -> 54397.656
B17: % margin | F17: =F16/F14 -> 0.34808994 | G17: =G16/G14 -> 0.35161879 | H17: =H16/H14 -> 0.35219975 | I17: =I16/I14 -> 0.35219975 | J17: =J16/J14 -> 0.35219975
B18: EBIT | F18: =FSM!F20 -> 27381.403 | G18: =FSM!G20 -> 30817.383 | H18: =FSM!H20 -> 33319.59 | I18: =FSM!I20 -> 35555.24 | J18: =FSM!J20 -> 37082.193
B19: % margin | F19: =F18/F14 -> 0.193309 | G19: =G18/G14 -> 0.21226005 | H19: =H18/H14 -> 0.22444443 | I19: =I18/I14 -> 0.23480786 | J19: =J18/J14 -> 0.24009011
B21: Tax on EBIT | F21: =F18*-1*F22 -> -6528.6797 | G21: =G18*-1*G22 -> -7347.937 | H21: =H18*-1*H22 -> -7944.5501 | I21: =I18*-1*I22 -> -8477.6068 | J21: =J18*-1*J22 -> -8841.6858
B22: Tax rate | F22: 0.23843481 | G22: =F22 -> 0.23843481 | H22: =G22 -> 0.23843481 | I22: =H22 -> 0.23843481 | J22: =I22 -> 0.23843481
B23: NOPAT | F23: =F18+F21 -> 20852.724 | G23: =G18+G21 -> 23469.446 | H23: =H18+H21 -> 25375.04 | I23: =I18+I21 -> 27077.633 | J23: =J18+J21 -> 28240.508
B25: Depreciation & Amortization | F25: =FSM!F28 -> 21924.067 | G25: =FSM!G28 -> 20233.066 | H25: =FSM!H28 -> 18965.739 | I25: =FSM!I28 -> 17775.796 | J25: =FSM!J28 -> 17315.463
B26: Change in net working capital | F26: =F32-E32 -> 3907.5924 | G26: =G32-F32 -> 371.53981 | H26: =H32-G32 -> 1479.143 | I26: =I32-H32 -> 562.2055 | J26: =J32-I32 -> 645.58961
B27: Capital expenditures | F27: =FSM!F96 -> -18354 | G27: =FSM!G96 -> -18603 | H27: =FSM!H96 -> -18976.568 | I27: =FSM!I96 -> -19316.099 | J27: =FSM!J96 -> -19662.421
B28: as a % of revenue | F28: =F27/F14 -> -0.12957676 | G28: =G27/G14 -> -0.12813138 | H28: =H27/H14 -> -0.12782825 | I28: =I27/I14 -> -0.12756409 | J28: =J27/J14 -> -0.12730511
B30: Unlevered free cash flows | F30: =F23+F25+F26+F27 -> 28330.383 | G30: =G23+G25+G26+G27 -> 25471.052 | H30: =H23+H25+H26+H27 -> 26843.354 | I30: =I23+I25+I26+I27 -> 26099.535 | J30: =J23+J25+J26+J27 -> 26539.139
F31: =F30/F14 -> 0.20000867 | G31: =G30/G14 -> 0.17543627 | H31: =H30/H14 -> 0.1808198 | I31: =I30/I14 -> 0.17236211 | J31: =J30/J14 -> 0.17182869
B32: Net working capital | E32: =SUM(FSM!E45:E48)-SUM(FSM!E59:E61) -> -5878 | F32: =SUM(FSM!F45:F48)-SUM(FSM!F59:F61) -> -1970.4076 | G32: =SUM(FSM!G45:G48)-SUM(FSM!G59:G61) -> -1598.8678 | H32: =SUM(FSM!H45:H48)-SUM(FSM!H59:H61) -> -119.7248 | I32: =SUM(FSM!I45:I48)-SUM(FSM!I59:I61) -> 442.4807 | J32: =SUM(FSM!J45:J48)-SUM(FSM!J59:J61) -> 1088.0703
B34: ="Present value of UFCF on "&TEXT(C7,"mmm dd, yyyy") -> Present value of UFCF on Apr 24, 2026
F35: 1 Yr- Target | G35: 1 | H35: =G35+1 -> 2 | I35: =H35+1 -> 3 | J35: =I35+1 -> 4
B36: Date for discounting cash flows | D36: Stub adj. | F36: =EOMONTH(C7,12) -> 46507 | G36: =IF($G$7=1,G12,AVERAGE(G12,F12)) -> 46569.5 | H36: =IF($G$7=1,H12,AVERAGE(H12,G12)) -> 46935 | I36: =IF($G$7=1,I12,AVERAGE(I12,H12)) -> 47300.5 | J36: =IF($G$7=1,J12,AVERAGE(J12,I12)) -> 47665.5
B37: Unlevered free cash flows stub adjusted | D37: =C8 -> 0.68611111 | G37: =G30*D37 -> 17475.972 | H37: =H30 -> 26843.354 | I37: =I30 -> 26099.535 | J37: =J30 -> 26539.139
B38: Present value of unlevered free cash flows | G38: =G37/(1+$G$4)^((G36-$F$36)/365) -> 17208.968 | H38: =H37/(1+$G$4)^((H36-$F$36)/365) -> 24157.254 | I38: =I37/(1+$G$4)^((I36-$F$36)/365) -> 21465.492 | J38: =J37/(1+$G$4)^((J36-$F$36)/365) -> 19950.128
B40: Terminal value- growth to perpetuity | F40: Shares outstanding
B41: Long term growth rate | D41: 0.02 | F41: Shares outstanding | J41: 4217.6842
B42: 2031 FCF | D42: =J30*(1+D41) -> 27069.922 | F42: RSUs | J42: =28082/1000 -> 28.082
B43: Terminal value in 2030 | D43: =D42/(G4-D41) -> 365413.01 | F43: PSUs | J43: =6997/1000 -> 6.997
B44: Present value of terminal value | D44: =D43/(1+$G$4)^(($J$36-F36)/365) -> 274690.01 | F44: Stock options | J44: 0
B45: Present value of stage 1 cash flows | D45: =SUM(H38:J38) -> 65572.874 | F45: Dilutive shares outstanding | J45: =SUM(J41:J44) -> 4252.7632
B46: Total enterprise value (TEV) | D46: =SUM(D44:D45) -> 340262.88
B48: Terminal value as % of TEV | D48: =D44/D46 -> 0.80728761
B49: Stage 1 cash flows as % of TEV | D49: =D45/D46 -> 0.19271239
...

Sheet WACC
B2: Bloomberg function WACC buildup
B4: Name | C4: Ticker | D4: Levered beta | E4: Tax rate | F4: Debt/ equity | G4: Unlevered beta | H4: Cash | I4: Firm value ($ million) | J4: Cash / Firm value | K4: Cash Adj. unl. Beta
B5: AT&T | C5: T US EQUITY | D5: 0.312 | E5: =3621/27007 -> 0.13407635 | F5: {=_xll.BDP(C5,$F$14)/100} -> 1.2345049 | G5: =D5/(1+(1-E5)*F5) -> 0.15079844 | H5: {=IFERROR(_xll.BDP(C5,$F$15,),_xll.BDH(C5,$F$15,"-1FY"))} -> 18234 | I5: {=_xll.BDP(C5,$F$16)} -> 342486.62 | J5: =H5/I5 -> 0.053240035 | K5: =G5/(1-J5) -> 0.15927843
B6: T-Mobile | C6: TMUS US EQUITY | D6: 0.412 | E6: =3289/14281 -> 0.230306 | F6: {=_xll.BDP(C6,$F$14)/100} -> 2.0652501 | G6: =D6/(1+(1-E6)*F6) -> 0.15909728 | H6: {=IFERROR(_xll.BDP(C6,$F$15,),_xll.BDH(C6,$F$15,"-1FY"))} -> 5598 | I6: {=_xll.BDP(C6,$F$16)} -> 319380.25 | J6: =H6/I6 -> 0.017527696 | K6: =G6/(1-J6) -> 0.16193564
B7: Charter Communication | C7: CHTR US EQUITY | D7: 1.004 | E7: =1692/7458 -> 0.22687047 | F7: {=_xll.BDP(C7,$F$14)/100} -> 4.6882402 | G7: =D7/(1+(1-E7)*F7) -> 0.21709906 | H7: {=IFERROR(_xll.BDP(C7,$F$15,),_xll.BDH(C7,$F$15,"-1FY"))} -> 571 | I7: {=_xll.BDP(C7,$F$16)} -> 118225.09 | J7: =H7/I7 -> 0.0048297701 | K7: =G7/(1-J7) -> 0.21815269
J8: Average | K8: =AVERAGE(K5:K7) -> 0.17978892
B12: Average cash adj. unl. Beta | C12: =AVERAGE(K5:K9) -> 0.17978892
B13: VZ cash/firm value | C13: =J13/J14 -> 0.049427935 | F13: Plugs | I13: Cash | J13: {=_xll.BDP(F17,F15)} -> 19048
B14: VZ unlevered beta | C14: =C12*(1-C13) -> 0.17090232 | F14: TOT_DEBT_TO_TOT_EQY | I14: EV | J14: {=_xll.BDP(F17,F16)} -> 385369.12
B15: VZ tax rate | C15: =-Historicals!I21/Historicals!I20 -> 0.22335921 | F15: CASH_AND_MARKETABLE_SECURITIES
B16: D/E ratio | C16: {=_xll.BDP(F17,F14)/100} -> 1.7178105 | F16: CURR_ENTP_VAL
B17: VZ's levered beta | C17: =C14*(1+(1-C15)*C16) -> 0.39890682 | F17: VZ US EQUITY
F18: USGG10YR Index
B19: WACC Buildup | F19: PX_Last
F20: CUR_MKT_CAP
B21: Cost of equity
B22: risk free rate | C22: {=_xll.BDP(F18,F19)/100} -> 0.043355
B23: Beta | C23: =C17 -> 0.39890682
B24: Equity risk premium | C24: 0.0754
B25: Cost of equity | C25: =C22+C23*C24 -> 0.073432574
B27: Cost of debt
B28: Weighted average cost of debt | C28: 0.0561
B29: Tax rate | C29: =C15 -> 0.22335921
B30: Post tax cost of debt | C30: =C28*(1-C29) -> 0.043569548
B32: Weights
B33: Debt | C33: =12582+146032 -> 158614
B34: Equity | C34: {=_xll.BDP(F17,F20)/1000000} -> 196550.12
B36: Wd | C36: =C33/SUM(C33:C34) -> 0.44659353
B37: We | C37: =C34/SUM(C33:C34) -> 0.55340647
B39: WACC | C39: =C25*C37+C36*C30 -> 0.06009594
E40: Add
B41: Cost of Equity | C41: =7.34285924250969%+E41 -> 0.073428592 | E41: 0 | F41: 0.02
B42: WACC | C42: =6.01659994054048%+E42 -> 0.060165999 | E42: 0 | F42: 0.013

Sheet DDM
B2: Discounted Dividend Valuation
B3: $ and shares in thousands, except per share
B5: Most recent fiscal year end | C5: 46022 | E5: Cost of Equity | G5: =WACC!C41 -> 0.073428592
B6: end of first fiscal year | C6: 46387 | E6: Share price | G6: {=_xll.BDP("VZ US EQUITY", "PX_Last")} -> 47.0666
B7: most recent quarter end date | E7: Share price date | G7: =TODAY() -> 46152
B8: Valuation date | C8: =FCFM!C7 -> 46136
B11: Dividends
B12: Fiscal year | D12: 2025E | E12: 2026E | F12: 2027E | G12: 2028E | H12: 2029E | I12: 2030E
B13: Fiscal year end date | D13: 46022 | E13: =EOMONTH(D13,12) -> 46387 | F13: =EOMONTH(E13,12) -> 46752 | G13: =EOMONTH(F13,12) -> 47118 | H13: =EOMONTH(G13,12) -> 47483 | I13: =EOMONTH(H13,12) -> 47848
E15: 1 Yr- Target | F15: 1 | G15: =F15+1 -> 2 | H15: =G15+1 -> 3 | I15: =H15+1 -> 4
E16: =EOMONTH(C8,12) -> 46507 | F16: =F13 -> 46752 | G16: =G13 -> 47118 | H16: =H13 -> 47483 | I16: =I13 -> 47848
B17: Dividend per share | F17: =FSM!G226 -> 2.835 | G17: =FSM!H226 -> 2.885 | H17: =FSM!I226 -> 2.935 | I17: =FSM!J226 -> 2.985
B18: % growth | G18: =G17/F17-1 -> 0.017636684 | H18: =H17/G17-1 -> 0.017331023 | I18: =I17/H17-1 -> 0.017035775
B19: Present value of Dividends | F19: =F17/(1+$G$5)^((F13-$E$16)/365) -> 2.7033178 | G19: =G17/(1+$G$5)^((G13-$E$16)/365) -> 2.5623143 | H19: =H17/(1+$G$5)^((H13-$E$16)/365) -> 2.4284073 | I19: =I17/(1+$G$5)^((I13-$E$16)/365) -> 2.3008303
B21: Terminal value- growth to perpetuity
B22: Long term growth rate | D22: 0.02
B23: 2031 Dividend | D23: =I17*(1+D22) -> 3.0447
B24: Terminal value in 2030 | D24: =D23/(G5-D22) -> 56.986341
B25: Present value of terminal value | D25: =D24/(1+$G$5)^((I13-E16)/365) -> 43.924925
B26: Present value of term 1 dividends | D26: =SUM(G19:I19) -> 7.2915518
B27: 12-month price target | D27: =SUM(D25:D26) -> 51.216477
B29: Sensitvity Analysis
C31: Equity value per share
C32: Long term growth rate (g):
C33: =D27 -> 51.216477 | D33: =E33-0.00125 -> 0.0175 | E33: =F33-0.00125 -> 0.01875 | F33: 0.02 | G33: =F33+0.00125 -> 0.02125 | H33: =G33+0.00125 -> 0.0225
B34: Discount rate | C34: =C35-0.001 -> 0.071428592 | D34: 51.036996 | E34: 52.129141 | F34: 53.274376 | G34: 54.476669 | H34: 55.740393
C35: =C36-0.001 -> 0.072428592 | D35: 50.076395 | E35: 51.126059 | F35: 52.225776 | G35: 53.379212 | H35: 54.590403
C36: 0.073428592 | D36: 49.150192 | E36: 50.159716 | F36: 51.216477 | G36: 52.32387 | H36: 53.485623
C37: =C36+0.001 -> 0.074428592 | D37: 48.256576 | E37: 49.228132 | F37: 50.244313 | G37: 51.308266 | H37: 52.423441
C38: =C37+0.001 -> 0.075428592 | D38: 47.393859 | E38: 48.329467 | F38: 49.307274 | G38: 50.330201 | H38: 51.401444
B40: Check | C40: =IF(C36=G5,"Ok","Update Discount Rate") -> Ok

Sheet RIM
B2: Residual Income Valuation
B3: $ and shares in thousands, except per share
B5: Most recent fiscal year end | C5: 46022 | E5: Cost of Equity | G5: =WACC!C41 -> 0.073428592
B6: end of first fiscal year | C6: 46387 | E6: Share price | G6: {=_xll.BDP("VZ US EQUITY", "PX_Last")} -> 47.0666
B7: most recent quarter end date | E7: Share price date | G7: =TODAY() -> 46152
B8: Valuation date | C8: =FCFM!C7 -> 46136
B10: Residual Income
B11: Fiscal year | D11: 2025E | E11: 2026E | F11: 2027E | G11: 2028E | H11: 2029E | I11: 2030E
B12: Fiscal year end date | D12: 46022 | E12: 46387 | F12: 46752 | G12: 47118 | H12: 47483 | I12: 47848
E14: 1 Yr- Target | F14: 1 | G14: 2 | H14: 3 | I14: 4
E15: =EOMONTH(C8,12) -> 46507 | F15: 46752 | G15: 47118 | H15: 47483 | I15: 47848
B16: Earnings per share | C16: ω | D16: 0.5 | E16: =FSM!F268 -> 3.5639393 | F16: =FSM!G268 -> 4.115052 | G16: =FSM!H268 -> 4.5004555 | H16: =FSM!I268 -> 4.8385556 | I16: =FSM!J268 -> 5.0508892
B17: Book value per share | E17: =FSM!F280 -> 24.542693 | F17: =E17+F16-DDM!F17 -> 25.822745 | G17: =F17+G16-DDM!G17 -> 27.4382 | H17: =G17+H16-DDM!H17 -> 29.341756 | I17: =H17+I16-DDM!I17 -> 31.407645
B18: Residual Income | F18: =F16-(F17*$G$5) -> 2.2189242 | G18: =G16-(G17*$G$5) -> 2.4857071 | H18: =H16-(H17*$G$5) -> 2.6840318 | I18: =I16-(I17*$G$5) -> 2.74467
B19: Present Value of Residual Incomes | F19: =F18/(1+$G$5)^((F15-$E$15)/365) -> 2.1158579 | G19: =G18/(1+$G$5)^((G15-$E$15)/365) -> 2.2076821 | H19: =H18/(1+$G$5)^((H15-$E$15)/365) -> 2.2207571 | I19: =I18/(1+$G$5)^((I15-$E$15)/365) -> 2.1155846
B21: Terminal value- growth to perpetuity
B22: Terminal growth rate | D22: 0.02
B23: 2031 Residual income | D23: =I18*(1+D22) -> 2.7995634
B24: Terminal value | D24: =D23/(1+G5-D16) -> 4.8821483
B25: Present Value of terminal value | D25: =D24/(1+$G$5)^((I15-E15)/365) -> 3.7631473
B26: Present value of term 1 Residual Income | D26: =SUM(G19:I19) -> 6.5440238
B27: 2026 BVPS | D27: =F17 -> 25.822745
B28: 12-month price target | D28: =SUM(D25:D27) -> 36.129916
B30: Sensitvity Analysis
C32: Equity value per share
C33: Long term growth rate (g):
C34: =D28 -> 36.129916 | D34: =E34-0.0025 -> 0.015 | E34: =F34-0.0025 -> 0.0175 | F34: 0.02 | G34: =F34+0.0025 -> 0.0225 | H34: =G34+0.0025 -> 0.025
B35: Discount rate | C35: =C36-0.002 -> 0.069428592 | D35: 36.724529 | E35: 36.734377 | F35: 36.744224 | G35: 36.754072 | H35: 36.763919
C36: =C37-0.002 -> 0.071428592 | D36: 36.415993 | E36: 36.425526 | F36: 36.435059 | G36: 36.444591 | H36: 36.454124
C37: 0.073428592 | D37: 36.111469 | E37: 36.120692 | F37: 36.129916 | G37: 36.139139 | H37: 36.148363
C38: =C37+0.002 -> 0.075428592 | D38: 35.810896 | E38: 35.819815 | F38: 35.828735 | G38: 35.837655 | H38: 35.846575
C39: =C38+0.002 -> 0.077428592 | D39: 35.514215 | E39: 35.522836 | F39: 35.531458 | G39: 35.540079 | H39: 35.548701
B40: Check | C40: =IF(C37=G5,"Ok","Check") -> Ok
C41: Equity value per share
C42: ω
C43: =D28 -> 36.129916 | D43: =E43-0.1 -> 0.3 | E43: =F43-0.1 -> 0.4 | F43: 0.5 | G43: =F43+0.1 -> 0.6 | H43: =G43+0.1 -> 0.7
B44: Discount rate | C44: =C45-0.002 -> 0.069428592 | D44: 35.699872 | E44: 36.144045 | F44: 36.744224 | G44: 37.60011 | H44: 38.919353
C45: =C46-0.002 -> 0.071428592 | D45: 35.426721 | E45: 35.855801 | F45: 36.435059 | G45: 37.260062 | H45: 38.529298
C46: 0.073428592 | D46: 35.156808 | E46: 35.571112 | F46: 36.129916 | G46: 36.924787 | H46: 38.145373
C47: =C46+0.002 -> 0.075428592 | D47: 34.890088 | E47: 35.289926 | F47: 35.828735 | G47: 36.594206 | H47: 37.767463
...

Sheet MVA
B2: Market Value Added Valuation
B3: $ and shares in thousands, except per share
B5: Most recent fiscal year end | C5: 46022 | E5: WACC | G5: =WACC!C42 -> 0.060165999
B6: end of first fiscal year | C6: 46387 | E6: Share price | G6: {=_xll.BDP("VZ US EQUITY", "PX_Last")} -> 47.0666
B7: most recent quarter end date | E7: Share price date | G7: =TODAY() -> 46152
B8: Valuation date | C8: =FCFM!C7 -> 46136
B10: Residual Income
B11: Fiscal year | D11: 2025E | E11: 2026E | F11: 2027E | G11: 2028E | H11: 2029E | I11: 2030E
B12: Fiscal year end date | D12: 46022 | E12: 46387 | F12: 46752 | G12: 47118 | H12: 47483 | I12: 47848
E14: 1 Yr- Target | F14: 1 | G14: 2 | H14: 3 | I14: 4
E15: =EOMONTH(C8,12) -> 46507 | F15: 46752 | G15: 47118 | H15: 47483 | I15: 47848
B16: NOPAT | E16: =FCFM!F23 -> 20852.724 | F16: =FCFM!G23 -> 23469.446 | G16: =FCFM!H23 -> 25375.04 | H16: =FCFM!I23 -> 27077.633 | I16: =FCFM!J23 -> 28240.508 | J16: =I16*(1.02) -> 28805.318
B17: CAPITAL | E17: =FSM!F275+FSM!F69+FSM!F62+FSM!F58 -> 270973.35 | F17: =FSM!G275+FSM!G69+FSM!G62+FSM!G58 -> 280743.77 | G17: =FSM!H275+FSM!H69+FSM!H62+FSM!H58 -> 292219.08 | H17: =FSM!I275+FSM!I69+FSM!I62+FSM!I58 -> 304270.74 | I17: =FSM!J275+FSM!J69+FSM!J62+FSM!J58 -> 317370.21
B18: EROIC | F18: =G16/F17 -> 0.09038505 | G18: =H16/G17 -> 0.092662098 | H18: =I16/H17 -> 0.092813746 | I18: =J16/I17 -> 0.090762512
B19: Market Value Added | F19: =F17*(F18-$G$5) -> 8483.8101 | G19: =G17*(G18-$G$5) -> 9495.98 | H19: =H17*(H18-$G$5) -> 9933.7543 | I19: =I17*(I18-$G$5) -> 9710.4217
B20: Present value of Market Value Added | F20: =F19/(1+$G$5)^((F15-E15)/365) -> 8157.539 | G20: =G19/(1+$G$5)^((G15-F15)/365) -> 8955.6353 | H20: =H19/(1+$G$5)^((H15-G15)/365) -> 9369.9989 | I20: =I19/(1+$G$5)^((I15-H15)/365) -> 9159.3408
B22: Terminal value- growth to perpetuity
B23: Long term growth rate | D23: 0.02
B24: 2031 MVA | D24: =I20*(1+D23) -> 9342.5276
B25: Terminal value in 2030 | D25: =D24/(G5-D23) -> 232597.91
B26: Present value of terminal value | D26: =D25/(1+$G$5)^((I15-E15)/365) -> 187664.84
B27: Present value of stage 1 cash flows | D27: =SUM(G20:I20) -> 27484.975
B28: Capital 2026 | D28: =E17 -> 270973.35
B29: Total enterprise value (TEV) | D29: =SUM(D26:D28) -> 486123.16
B31: Terminal value as % of TEV | D31: =D26/D29 -> 0.38604381
B32: Stage 1 cash flows as % of TEV | D32: =(D27+D28)/D29 -> 0.61395619
B34: Net debt
B35: Source document | D35: 10-K
B36: Source date | D36: 46066
B37: Gross debt and equivalents
B38: Debt | D38: 158150
B39: Minority Interest | D39: 1281
B40: Preferred stock | D40: 0
B41: Nonoperating assets
B42: Cash | D42: 19048
B44: Net debt | D44: =SUM(D38:D40)-D42 -> 140383
B46: Valuation- growth to perpetuity
B47: Enterprise value | D47: =D29 -> 486123.16
B48: Net debt | D48: =D44 -> 140383
B49: Equity value | D49: =D47-D48 -> 345740.16
...

Sheet Relative
B2: Company name | D2: VZ US EQUITY
B3: last closing price | C3: PX_Last | D3: {=_xll.BDP($D$2,C3,"3/2/26")} -> 47.0666
B4: 52 week high | C4: HIGH_52WEEK | D4: {=_xll.BDP($D$2,C4,$C$9)} -> 51.68
B5: 52 week low | C5: LOW_52WEEK | D5: {=_xll.BDP($D$2,C5,$C$9)} -> 38.39
B6: Market cap | C6: CUR_MKT_CAP | D6: {=_xll.BDP($D$2,C6,$C$9)/1000000} -> 196550.12
B7: Shares outstanding | C7: EQY_SH_OUT | D7: {=_xll.BDP($D$2,C7,$C$9)} -> 4176
B8: YTD return | C8: CHG_PCT_YTD | D8: {=_xll.BDP($D$2,C8,$C$9)} -> 15.55758
D10: Equity 1 | E10: Equity 2 | F10: Equity 3 | G10: Equity 4 | H10: Equity 5 | I10: Peer group average | J10: My company
D11: T US EQUITY | E11: TMUS US EQUITY | J11: =D2 -> VZ US EQUITY
B13: Multiples | K13: Include?
B14: Price to sales ratio | C14: PX_TO_SALES_RATIO | D14: {=_xll.BDP(D$11,$C14)} -> 1.4472474 | E14: {=_xll.BDP(E$11,$C14)} -> 2.3487438 | I14: =AVERAGE(D14:H14) -> 1.8979956 | J14: {=_xll.BDP(J$11,C14)} -> 1.4280431 | K14: No
B15: Price to book ratio | C15: PX_TO_BOOK_RATIO | D15: {=_xll.BDP(D$11,$C15)} -> 1.6339105 | E15: {=_xll.BDP(E$11,$C15)} -> 3.4397175 | I15: =AVERAGE(D15:H15) -> 2.536814 | J15: {=_xll.BDP(J$11,C15)} -> 1.902546 | K15: No
B16: Price to EBITDA | C16: PX_TO_EBITDA | D16: {=_xll.BDP(D$11,$C16)} -> 4.005306 | E16: {=_xll.BDP(E$11,$C16)} -> 6.5298485 | I16: =AVERAGE(D16:H16) -> 5.2675772 | J16: {=_xll.BDP(J$11,C16)} -> 4.1228955 | K16: Yes
B17: Price to FCF | C17: PX_TO_FREE_CASH_FLOW | D17: {=_xll.BDP(D$11,$C17)} -> 10.577099 | E17: {=_xll.BDP(E$11,$C17)} -> 11.532887 | I17: =AVERAGE(D17:H17) -> 11.054993 | J17: {=_xll.BDP(J$11,C17)} -> 9.8050005 | K17: Yes
B18: Price to EPS | C18: PX_TO_EPS_BEFORE_ABNORMAL_ITEMS | D18: {=_xll.BDP(D$11,$C18)} -> 13.928889 | E18: {=_xll.BDP(E$11,$C18)} -> 17.183613 | I18: =AVERAGE(D18:H18) -> 15.556251 | J18: {=_xll.BDP(J$11,C18)} -> 10.114056 | K18: No
B19: EV to trailing 12M sales | C19: EV_TO_T12M_SALES | D19: {=_xll.BDP(D$11,$C19)} -> 2.8865338 | E19: {=_xll.BDP(E$11,$C19)} -> 3.866222 | I19: =AVERAGE(D19:H19) -> 3.3763779 | J19: {=_xll.BDP(J$11,C19)} -> 2.8635692 | K19: No
B21: Data pull | D21: 44561 | E21: =D21+365 -> 44926 | F21: =E21+365 -> 45291 | G21: =F21+366 -> 45657 | H21: =G21+365 -> 46022
B22: Trailing 12M sales per share | C22: TRAIL_12M_SALES_PER_SH | D22: {=_xll.BDH($D$2,$C22,D$21)} -> 32.2126 | E22: {=_xll.BDH($D$2,$C22,E$21)} -> 32.5641 | F22: {=_xll.BDH($D$2,$C22,F$21)} -> 31.8185 | G22: {=_xll.BDH($D$2,$C22,G$21)} -> 31.9548 | H22: {=_xll.BDH($D$2,$C22,H$21)} -> 32.6996
B23: Trailing 12M net sales | C23: TRAIL_12M_NET_SALES | D23: {=_xll.BDH($D$2,$C23,D$21)} -> 133613 | E23: {=_xll.BDH($D$2,$C23,E$21)} -> 136835 | F23: {=_xll.BDH($D$2,$C23,F$21)} -> 133974 | G23: {=_xll.BDH($D$2,$C23,G$21)} -> 134788 | H23: {=_xll.BDH($D$2,$C23,H$21)} -> 138191
B24: Short and long term debt | C24: SHORT_AND_LONG_TERM_DEBT | D24: {=_xll.BDH($D$2,$C24,D$21)} -> 177930 | E24: {=_xll.BDH($D$2,$C24,E$21)} -> 150639 | F24: {=_xll.BDH($D$2,$C24,F$21)} -> 174942 | G24: {=_xll.BDH($D$2,$C24,G$21)} -> 168357 | H24: {=_xll.BDH($D$2,$C24,H$21)} -> 181643
B25: Cash and cash equivalents | C25: BS_CASH_NEAR_CASH_ITEM | D25: {=_xll.BDH($D$2,$C25,D$21)} -> 2921 | E25: {=_xll.BDH($D$2,$C25,E$21)} -> 2605 | F25: {=_xll.BDH($D$2,$C25,F$21)} -> 2065 | G25: {=_xll.BDH($D$2,$C25,G$21)} -> 4194 | H25: {=_xll.BDH($D$2,$C25,H$21)} -> 19048
B26: Book value per share | C26: BOOK_VAL_PER_SH | D26: {=_xll.BDH($D$2,$C26,D$21)} -> 19.484 | E26: {=_xll.BDH($D$2,$C26,E$21)} -> 21.7123 | F26: {=_xll.BDH($D$2,$C26,F$21)} -> 21.9848 | G26: {=_xll.BDH($D$2,$C26,G$21)} -> 23.5735 | H26: {=_xll.BDH($D$2,$C26,H$21)} -> 24.7712
B27: EPS from Continuing Operations | C27: T12_EPS_CONT_OPS | D27: {=_xll.BDH($D$2,$C27,D$21)} -> 5.4156 | E27: {=_xll.BDH($D$2,$C27,E$21)} -> 5.1959 | F27: {=_xll.BDH($D$2,$C27,F$21)} -> 4.5678 | G27: {=_xll.BDH($D$2,$C27,G$21)} -> 4.4505 | H27: {=_xll.BDH($D$2,$C27,H$21)} -> 4.5779
B28: Trailing 12M FCF per share | C28: TRAIL_12M_FREE_CASH_FLOW_PER_SH | D28: {=_xll.BDH($D$2,$C28,D$21)} -> 4.6461 | E28: {=_xll.BDH($D$2,$C28,E$21)} -> 3.3448 | F28: {=_xll.BDH($D$2,$C28,F$21)} -> 4.4427 | G28: {=_xll.BDH($D$2,$C28,G$21)} -> 4.6989 | H28: {=_xll.BDH($D$2,$C28,H$21)} -> 4.7621
B29: Trailing 12M EBITDA per share | C29: TRAIL_12M_EBITDA_PER_SHARE | D29: {=_xll.BDH($D$2,$C29,D$21)} -> 12.6609 | E29: {=_xll.BDH($D$2,$C29,E$21)} -> 11.3199 | F29: {=_xll.BDH($D$2,$C29,F$21)} -> 9.6203 | G29: {=_xll.BDH($D$2,$C29,G$21)} -> 11.0429 | H29: {=_xll.BDH($D$2,$C29,H$21)} -> 11.2662
B31: Multiple | D31: Competitors' averages | E31: Price
B32: Price to sales ratio | D32: =I14 -> 1.8979956 | E32: =IF(K14="Yes",D32*H22,"")
B33: Price to book ratio | D33: =I15 -> 2.536814 | E33: =IF(K15="Yes",D33*H26,"")
B34: Price to EBITDA | D34: =I16 -> 5.2675772 | E34: =IF(K16="Yes",D34*H29,"") -> 59.345579
B35: Price to FCF | D35: =I17 -> 11.054993 | E35: =IF(K17="Yes",D35*H28,"") -> 52.644983
B36: Price to EPS | D36: =I18 -> 15.556251 | E36: =IF(K18="Yes",D36*H27,"")
B37: EV to trailing 12M sales | D37: =I19 -> 3.3763779 | E37: =IF(K19="Yes",((D37*H23)-H24+H25)/D7,"")
B38: Final target price | E38: =AVERAGE(E32:E37) -> 55.995281
B40: Last Price | E40: =D3 -> 47.0666
B41: Potential Upside | E41: =E38/E40-1 -> 0.18970312

Sheet Blended
B3: Models | C3: 12-month Price Target | D3: Weight | E3: Include?
B4: FCFM | C4: =FCFM!D69 -> 47.000003 | D4: 0.125 | E4: Yes | M4: Givne current market price, what is implied discount rate
B5: DDM | C5: =DDM!D27 -> 51.216477 | D5: 0.125 | E5: Yes
B6: RIM | C6: =RIM!D28 -> 36.129916 | D6: 0.125 | E6: Yes | M6: Investors punshing FCF for its massive debt loads
B7: MVAM | C7: =MVA!D51 -> 81.297769 | D7: 0.125 | E7: Yes
B8: COMPS | C8: =Relative!E38 -> 55.995281 | D8: 0.5 | E8: Yes | I8: 60.74
B9: 12 Month Target Price | C9: =C17 -> 54.953161 | D9: =SUM(D4:D8) -> 1 | I9: {=_xll.BDP("VZ US EQUITY", "PX_LAST")} -> 47.09
I10: =I8/I9-1 -> 0.28987046
B11: Models | C11: Weighted Valuation
B12: FCFM | C12: =IF(E4="Yes",C4*D4,0) -> 5.8750003
B13: DDM | C13: =IF(E5="Yes",C5*D5,0) -> 6.4020596
B14: RIM | C14: =IF(E6="Yes",C6*D6,0) -> 4.5162395
B15: MVAM | C15: =IF(E7="Yes",C7*D7,0) -> 10.162221
B16: COMPS | C16: =IF(E8="Yes",C8*D8,0) -> 27.99764
B17: Blended 12-month price target | C17: =SUM(C12:C16) -> 54.953161
B18: Potential Upside | C18: =C17/MVA!G6-1 -> 0.16756173
B21: Football Field
C22: Low | D22: Difference | E22: High
B23: FCFM | C23: =MIN(FCFM!D81:H85) -> 100.79953 | D23: =E23-C23 -> 32.257649 | E23: =MAX(FCFM!D81:H85) -> 133.05718
B24: DDM | C24: =MIN(DDM!D34:H38) -> 47.393859 | D24: =E24-C24 -> 8.3465341 | E24: =MAX(DDM!D34:H38) -> 55.740393
B25: RIM | C25: =MIN(RIM!$D$35:$H$39,RIM!$D$44:$H$48) -> 34.62652 | D25: =E25-C25 -> 4.292833 | E25: =MAX(RIM!$D$35:$H$39,RIM!$D$44:$H$48) -> 38.919353
B26: MVAM | C26: =MIN(MVA!D58:H62) -> 73.425947 | D26: =E26-C26 -> 17.706484 | E26: =MAX(MVA!D58:H62) -> 91.132431
B27: COMPS | C27: =C8*0.95 -> 53.195517 | D27: =E27-C27 -> 5.5995281 | E27: =C8*1.05 -> 58.795045
