Workbook

Sheet FCF
B2: Unlevered Free Cash Flow (mm)
B3: Fiscal Year | C3: 2023A | D3: 2024A | E3: 2025A | F3: 2026E | G3: 2027E | H3: 2028E | I3: 2029E | J3: 2030E
B4: Revenue | C4: ='Income Statement'!D5 -> 32653000 | D4: ='Income Statement'!E5 -> 35926000 | E4: ='Income Statement'!F5 -> 40000000 | F4: =E4*(1+F25) -> 44000000 | G4: =F4*(1+G25) -> 47960000 | H4: =G4*(1+H25) -> 51796800 | I4: =H4*(1+I25) -> 55422576 | J4: =I4*(1+J25) -> 58747931
B5: COGS | C5: ='Income Statement'!D6 -> 6567000 | D5: ='Income Statement'!E6 -> 7042000 | E5: ='Income Statement'!F6 -> 7855000 | F5: =F4*F27 -> 8704722.1 | G5: =G4*G27 -> 9488147.1 | H5: =H4*H27 -> 10247199 | I5: =I4*I27 -> 10964503 | J5: =J4*J27 -> 11622373
B6: Gross Profit | C6: =C4-C5 -> 26086000 | D6: =D4-D5 -> 28884000 | E6: =E4-E5 -> 32145000 | F6: =F4-F5 -> 35295278 | G6: =G4-G5 -> 38471853 | H6: =H4-H5 -> 41549601 | I6: =I4-I5 -> 44458073 | J6: =J4-J5 -> 47125558
B7: Operating Expenses | C7: ='Income Statement'!D16 -> 5086000 | D7: ='Income Statement'!E16 -> 5289000 | E7: ='Income Statement'!F16 -> 8151000 | F7: =F4*F28 -> 7432382.1 | G7: =G4*G28 -> 8101296.5 | H7: =H4*H28 -> 8749400.2 | I7: =I4*I28 -> 9361858.2 | J7: =J4*J28 -> 9923569.7
B8: Selling, General, Administrative | C8: =SUM('Income Statement'!D12:D15) -> 6432000 | D8: =SUM('Income Statement'!E12:E15) -> 7586000 | E8: =SUM('Income Statement'!F12:F15) -> 8738000 | F8: =F29*F4 -> 9189937.3 | G8: =G29*G4 -> 10017032 | H8: =H29*H4 -> 10818394 | I8: =I29*I4 -> 11575682 | J8: =J29*J4 -> 12270223
B9: Total Operating Expenses | C9: =SUM(C7:C8) -> 11518000 | D9: =SUM(D7:D8) -> 12875000 | E9: =SUM(E7:E8) -> 16889000 | F9: =SUM(F7:F8) -> 16622319 | G9: =SUM(G7:G8) -> 18118328 | H9: =SUM(H7:H8) -> 19567794 | I9: =SUM(I7:I8) -> 20937540 | J9: =SUM(J7:J8) -> 22193792
B10: EBITDA | C10: ='Income Statement'!D19 -> 22624000 | D10: ='Income Statement'!E19 -> 25591000 | E10: ='Income Statement'!F19 -> 26003000 | F10: =F6-F9 -> 18672958 | G10: =G6-G9 -> 20353525 | H10: =H6-H9 -> 21981807 | I10: =I6-I9 -> 23520533 | J10: =J6-J9 -> 24931765
B11: Depreciation & Amortization | C11: ='Income Statement'!D47 -> 943000 | D11: ='Income Statement'!E47 -> 1034000 | E11: ='Income Statement'!F47 -> 1220000 | F11: ='Fixed Assets'!F5 -> 1293025.3 | G11: ='Fixed Assets'!G5 -> 1409397.5 | H11: ='Fixed Assets'!H5 -> 1522149.3 | I11: ='Fixed Assets'!I5 -> 1628699.8 | J11: ='Fixed Assets'!J5 -> 1726421.8
B12: Operating Profit (EBIT) | C12: =C10-C11 -> 21681000 | D12: =D10-D11 -> 24557000 | E12: =E10-E11 -> 24783000 | F12: =F10-F11 -> 17379933 | G12: =G10-G11 -> 18944127 | H12: =H10-H11 -> 20459657 | I12: =I10-I11 -> 21891833 | J12: =J10-J11 -> 23205343
B13: Operating Taxes | C13: ='Income Statement'!D35 -> 3764000 | D13: ='Income Statement'!E35 -> 4173000 | E13: ='Income Statement'!F35 -> 4136000 | F13: =F30*F12 -> 2957068.2 | G13: =G30*G12 -> 3223204.3 | H13: =H30*H12 -> 3481060.7 | I13: =I30*I12 -> 3724734.9 | J13: =J30*J12 -> 3948219
B14: NOPAT (Net Operating Profit After Taxes) | C14: =C12-C13 -> 17917000 | D14: =D12-D13 -> 20384000 | E14: =E12-E13 -> 20647000 | F14: =F12-F13 -> 14422865 | G14: =G12-G13 -> 15720923 | H14: =H12-H13 -> 16978597 | I14: =I12-I13 -> 18167098 | J14: =J12-J13 -> 19257124
B15: (+) Depreciation & Amortization | C15: =C11 -> 943000 | D15: =D11 -> 1034000 | E15: =E11 -> 1220000 | F15: =F11 -> 1293025.3 | G15: =G11 -> 1409397.5 | H15: =H11 -> 1522149.3 | I15: =I11 -> 1628699.8 | J15: =J11 -> 1726421.8
B16: (-) Capital Expenditures | C16: ='Fixed Assets'!C6 -> 1454000 | D16: ='Fixed Assets'!D6 -> 2318000 | E16: ='Fixed Assets'!E6 -> 2454000 | F16: ='Fixed Assets'!F6 -> 2420000 | G16: ='Fixed Assets'!G6 -> 2398000 | H16: ='Fixed Assets'!H6 -> 2330856 | I16: ='Fixed Assets'!I6 -> 2383170.8 | J16: ='Fixed Assets'!J6 -> 2232421.4
B17: (-) Change in NWC | C17: =C18-('Net Working Capital '!C6 - 'Net Working Capital '!C11) -> -2539000 | D17: =D18-C18 -> -782000 | E17: =E18-D18 -> -674000 | F17: =F18-E18 -> -1635787 | G17: =G18-F18 -> -1128580.8 | H17: =H18-G18 -> -907384.63 | I17: =I18-H18 -> -968064.64 | J17: =J18-I18 -> -691657.65
B18: NWC | C18: =C19-C20 -> -14244000 | D18: =D19-D20 -> -15026000 | E18: =E19-E20 -> -15700000 | F18: =F19-F20 -> -17335787 | G18: =G19-G20 -> -18464368 | H18: =H19-H20 -> -19371752 | I18: =I19-I20 -> -20339817 | J18: =J19-J20 -> -21031475
B19: Current Assets | C19: ='Net Working Capital '!D6 -> 7354000 | D19: ='Net Working Capital '!E6 -> 11491000 | E19: ='Net Working Capital '!F6 -> 13779000 | F19: ='Net Working Capital '!G6 -> 14613675 | G19: ='Net Working Capital '!H6 -> 15880945 | H19: ='Net Working Capital '!I6 -> 17099624 | I19: ='Net Working Capital '!J6 -> 18241175 | J19: ='Net Working Capital '!K6 -> 19276898
B20: Current Liabilitites | C20: ='Net Working Capital '!D11 -> 21598000 | D20: ='Net Working Capital '!E11 -> 26517000 | E20: ='Net Working Capital '!F11 -> 29479000 | F20: ='Net Working Capital '!G11 -> 31949462 | G20: ='Net Working Capital '!H11 -> 34345313 | H20: ='Net Working Capital '!I11 -> 36471377 | I20: ='Net Working Capital '!J11 -> 38580993 | J20: ='Net Working Capital '!K11 -> 40308373
B21: Unlevered Free Cash Flow | C21: =C14+C15-C16-C17 -> 19945000 | D21: =D14+D15-D16-D17 -> 19882000 | E21: =E14+E15-E16-E17 -> 20087000 | F21: =F14+F15-F16-F17 -> 14931677 | G21: =G14+G15-G16-G17 -> 15860901 | H21: =H14+H15-H16-H17 -> 17077275 | I21: =I14+I15-I16-I17 -> 18380692 | J21: =J14+J15-J16-J17 -> 19442782
B23: Assumptions
B24: =B3 -> Fiscal Year | C24: =C3 -> 2023A | D24: =D3 -> 2024A | E24: =E3 -> 2025A | F24: =F3 -> 2026E | G24: =G3 -> 2027E | H24: =H3 -> 2028E | I24: =I3 -> 2029E | J24: =J3 -> 2030E
B25: Revenue Growth | D25: =D4/C4-1 -> 0.10023581 | E25: =E4/D4-1 -> 0.11339977 | F25: 0.1 | G25: 0.09 | H25: 0.08 | I25: 0.07 | J25: 0.06
B27: COGS % of Revenue | C27: =C5/C4 -> 0.20111475 | D27: =D5/D4 -> 0.19601403 | E27: =E5/E4 -> 0.196375 | F27: =AVERAGE($C$27:$E$27) -> 0.19783459 | G27: =AVERAGE($C$27:$E$27) -> 0.19783459 | H27: =AVERAGE($C$27:$E$27) -> 0.19783459 | I27: =AVERAGE($C$27:$E$27) -> 0.19783459 | J27: =AVERAGE($C$27:$E$27) -> 0.19783459
B28: OPEX% of Revenue | C28: =C7/C4 -> 0.15575904 | D28: =D7/D4 -> 0.14721928 | E28: =E7/E4 -> 0.203775 | F28: =AVERAGE($C$28:$E$28) -> 0.16891778 | G28: =AVERAGE($C$28:$E$28) -> 0.16891778 | H28: =AVERAGE($C$28:$E$28) -> 0.16891778 | I28: =AVERAGE($C$28:$E$28) -> 0.16891778 | J28: =AVERAGE($C$28:$E$28) -> 0.16891778
B29: SG&A % of Revenue | C29: =C8/C4 -> 0.19698037 | D29: =D8/D4 -> 0.21115627 | E29: =E8/E4 -> 0.21845 | F29: =AVERAGE($C$29:$E$29) -> 0.20886221 | G29: =AVERAGE($C$29:$E$29) -> 0.20886221 | H29: =AVERAGE($C$29:$E$29) -> 0.20886221 | I29: =AVERAGE($C$29:$E$29) -> 0.20886221 | J29: =AVERAGE($C$29:$E$29) -> 0.20886221
B30: Tax % of EBIT | C30: =C13/C12 -> 0.17360823 | D30: =D13/D12 -> 0.16993118 | E30: =E13/E12 -> 0.16688859 | F30: =AVERAGE($C$30:$E$30) -> 0.17014267 | G30: =AVERAGE($C$30:$E$30) -> 0.17014267 | H30: =AVERAGE($C$30:$E$30) -> 0.17014267 | I30: =AVERAGE($C$30:$E$30) -> 0.17014267 | J30: =AVERAGE($C$30:$E$30) -> 0.17014267

Sheet Fixed Assets
B2: Fixed Assets Schedule
B3: Fiscal Year | C3: 2023A | D3: 2024A | E3: 2025A | F3: 2026E | G3: 2027E | H3: 2028E | I3: 2029E | J3: 2030E
B4: Beginning PP&E | C4: =('Balance Sheet'!C20 + 'Balance Sheet'!C15) -> 10308000 | D4: =C7 -> 10819000 | E4: =D7 -> 12103000 | F4: =E7 -> 13337000 | G4: =F7 -> 14463975 | H4: =G7 -> 15452577 | I4: =H7 -> 16261284 | J4: =I7 -> 17015755
B5: D&A | C5: =FCF!C11 -> 943000 | D5: =FCF!D11 -> 1034000 | E5: =FCF!E11 -> 1220000 | F5: =F11*FCF!F4 -> 1293025.3 | G5: =G11*FCF!G4 -> 1409397.5 | H5: =H11*FCF!H4 -> 1522149.3 | I5: =I11*FCF!I4 -> 1628699.8 | J5: =J11*FCF!J4 -> 1726421.8
B6: CapEx | C6: =C7-C4+C5 -> 1454000 | D6: =D7-D4+D5 -> 2318000 | E6: =E7-E4+E5 -> 2454000 | F6: =F12*FCF!F4 -> 2420000 | G6: =G12*FCF!G4 -> 2398000 | H6: =H12*FCF!H4 -> 2330856 | I6: =I12*FCF!I4 -> 2383170.8 | J6: =J12*FCF!J4 -> 2232421.4
B7: Ending PP&E | C7: ='Balance Sheet'!D20 + 'Balance Sheet'!D15 -> 10819000 | D7: ='Balance Sheet'!E20 + 'Balance Sheet'!E15 -> 12103000 | E7: ='Balance Sheet'!F20 + 'Balance Sheet'!F15 -> 13337000 | F7: =F4-F5+F6 -> 14463975 | G7: =G4-G5+G6 -> 15452577 | H7: =H4-H5+H6 -> 16261284 | I7: =I4-I5+I6 -> 17015755 | J7: =J4-J5+J6 -> 17521754
B9: Assumptions
B10: Fiscal Year | C10: 2023A | D10: 2024A | E10: 2025A | F10: 2026E | G10: 2027E | H10: 2028E | I10: 2029E | J10: 2030E
B11: D&A as a % of Rev | C11: =C5/FCF!C4 -> 0.028879429 | D11: =D5/FCF!D4 -> 0.028781384 | E11: =E5/FCF!E4 -> 0.0305 | F11: =AVERAGE($C$11:$E$11) -> 0.029386938 | G11: =AVERAGE($C$11:$E$11) -> 0.029386938 | H11: =AVERAGE($C$11:$E$11) -> 0.029386938 | I11: =AVERAGE($C$11:$E$11) -> 0.029386938 | J11: =AVERAGE($C$11:$E$11) -> 0.029386938
B12: CapEx as a % of Rev | C12: =C6/FCF!C4 -> 0.044528833 | D12: =D6/FCF!D4 -> 0.064521516 | E12: =E6/FCF!E4 -> 0.06135 | F12: 0.055 | G12: 0.05 | H12: 0.045 | I12: 0.043 | J12: 0.038

Sheet Net Working Capital 
B2: Net Working Capital
B3: Fiscal Year | C3: 44926 | D3: 45291 | E3: 45657 | F3: 46022 | G3: 46387 | H3: 46752 | I3: 47118 | J3: 47483 | K3: 47848
B4: Accounts Receivables | C4: ='Balance Sheet'!C9 -> 2020000 | D4: ='Balance Sheet'!D9 -> 2291000 | E4: ='Balance Sheet'!E9 -> 2561000 | F4: ='Balance Sheet'!F9 -> 3126000 | G4: =G18*G15/360 -> 3173674.7 | H4: =H18*H15/360 -> 3459305.5 | I4: =I18*I15/360 -> 3736049.9 | J4: =J18*J15/360 -> 3997573.4 | K4: =K18*K15/360 -> 4237427.8
B5: Other Current Assets | C5: ='Balance Sheet'!B13 -> 4513000 | D5: ='Balance Sheet'!C13 -> 5063000 | E5: ='Balance Sheet'!D13 -> 8930000 | F5: ='Balance Sheet'!E13 -> 10653000 | G5: =G15*G21 -> 11440000 | H5: =H15*H21 -> 12421640 | I5: =I15*I21 -> 13363574 | J5: =J15*J21 -> 14243602 | K5: =K15*K21 -> 15039470
B6: Total Current Assets | C6: =SUM(C4:C5) -> 6533000 | D6: =SUM(D4:D5) -> 7354000 | E6: =SUM(E4:E5) -> 11491000 | F6: =SUM(F4:F5) -> 13779000 | G6: =SUM(G4:G5) -> 14613675 | H6: =SUM(H4:H5) -> 15880945 | I6: =SUM(I4:I5) -> 17099624 | J6: =SUM(J4:J5) -> 18241175 | K6: =SUM(K4:K5) -> 19276898
B8: Accounts Payable | C8: ='Balance Sheet'!C30 -> 340000 | D8: ='Balance Sheet'!D30 -> 375000 | E8: ='Balance Sheet'!E30 -> 479000 | F8: ='Balance Sheet'!F30 -> 555000 | G8: =G19*G16/360 -> 621461.75 | H8: =H19*H16/360 -> 677393.31 | I8: =I19*I16/360 -> 731584.78 | J8: =J19*J16/360 -> 782795.71 | K8: =K19*K16/360 -> 829763.45
B9: Accrued Expenses | C9: ='Balance Sheet'!C32 -> 1359000 | D9: ='Balance Sheet'!D32 -> 1506000 | E9: ='Balance Sheet'!E32 -> 5567000 | F9: ='Balance Sheet'!F32 -> 1863000 | G9: =G22*G15 -> 2068000 | H9: =H22*H15 -> 2254120 | I9: =I22*I15 -> 2434449.6 | J9: =J22*J15 -> 2604861.1 | K9: =K22*K15 -> 2761152.7
B10: Other Current Liabilities | C10: ='Balance Sheet'!C52 -> 16539000 | D10: ='Balance Sheet'!D52 -> 19717000 | E10: ='Balance Sheet'!E52 -> 20471000 | F10: ='Balance Sheet'!F52 -> 27061000 | G10: =G23*G15 -> 29260000 | H10: =H23*H15 -> 31413800 | I10: =I23*I15 -> 33305342 | J10: =J23*J15 -> 35193336 | K10: =K23*K15 -> 36717457
B11: Current Liabilities | C11: =SUM(C8:C10) -> 18238000 | D11: =SUM(D8:D10) -> 21598000 | E11: =SUM(E8:E10) -> 26517000 | F11: =SUM(F8:F10) -> 29479000 | G11: =SUM(G8:G10) -> 31949462 | H11: =SUM(H8:H10) -> 34345313 | I11: =SUM(I8:I10) -> 36471377 | J11: =SUM(J8:J10) -> 38580993 | K11: =SUM(K8:K10) -> 40308373
B13: Assumptions
B14: Fiscal Year | C14: 44926 | D14: 2023A | E14: 2024A | F14: 2025A | G14: 2026E | H14: 2027E | I14: 2028E | J14: 2029E | K14: 2030E
B15: Revenue | C15: ='Income Statement'!C5 -> 29310000 | D15: ='Income Statement'!D5 -> 32653000 | E15: ='Income Statement'!E5 -> 35926000 | F15: ='Income Statement'!F5 -> 40000000 | G15: =FCF!F4 -> 44000000 | H15: =FCF!G4 -> 47960000 | I15: =FCF!H4 -> 51796800 | J15: =FCF!I4 -> 55422576 | K15: =FCF!J4 -> 58747931
B16: COGS | C16: ='Income Statement'!B6 -> 4970000 | D16: ='Income Statement'!C6 -> 5733000 | E16: ='Income Statement'!D6 -> 6567000 | F16: ='Income Statement'!E6 -> 7042000 | G16: =FCF!F5 -> 8704722.1 | H16: =FCF!G5 -> 9488147.1 | I16: =FCF!H5 -> 10247199 | J16: =FCF!I5 -> 10964503 | K16: =FCF!J5 -> 11622373
B18: Days Sales Outstanding (DSO) | C18: =C4/C15*360 -> 24.810645 | D18: =D4/D15*360 -> 25.258322 | E18: =E4/E15*360 -> 25.662751 | F18: =F4/F15*360 -> 28.134 | G18: =AVERAGE($C$18:$F$18) -> 25.96643 | H18: =AVERAGE($C$18:$F$18) -> 25.96643 | I18: =AVERAGE($C$18:$F$18) -> 25.96643 | J18: =AVERAGE($C$18:$F$18) -> 25.96643 | K18: =AVERAGE($C$18:$F$18) -> 25.96643
B19: Days Payable Outstanding (DPO) | C19: =C8/C16*360 -> 24.627767 | D19: =D8/D16*360 -> 23.547881 | E19: =E8/E16*360 -> 26.258566 | F19: =F8/F16*360 -> 28.372621 | G19: =AVERAGE($C$19:$F$19) -> 25.701709 | H19: =AVERAGE($C$19:$F$19) -> 25.701709 | I19: =AVERAGE($C$19:$F$19) -> 25.701709 | J19: =AVERAGE($C$19:$F$19) -> 25.701709 | K19: =AVERAGE($C$19:$F$19) -> 25.701709
B21: Other Current Assets as a % of Revenue | C21: =C5/C15 -> 0.15397475 | D21: =D5/D15 -> 0.15505467 | E21: =E5/E15 -> 0.2485665 | F21: =F5/F15 -> 0.266325 | G21: 0.26 | H21: 0.259 | I21: 0.258 | J21: 0.257 | K21: 0.256
B22: Accrued Expenses as a % of Revenue | C22: =C9/C15 -> 0.046366428 | D22: =D9/D15 -> 0.046121336 | E22: =E9/E15 -> 0.15495741 | F22: =F9/F15 -> 0.046575 | G22: 0.047 | H22: 0.047 | I22: 0.047 | J22: 0.047 | K22: 0.047
B23: Other Current Liabilities as a % of Revenue | C23: =C10/C15 -> 0.5642784 | D23: =D10/D15 -> 0.60383426 | E23: =E10/E15 -> 0.56981017 | F23: =F10/F15 -> 0.676525 | G23: 0.665 | H23: 0.655 | I23: 0.643 | J23: 0.635 | K23: 0.625

Sheet DCF
B2: Unlevered Free Cash Flow (mm)
B3: Fiscal Year | D3: 45291 | E3: 45657 | F3: 46022 | G3: 46387 | H3: 46752 | I3: 47118 | J3: 47483 | K3: 47848
B4: Unlevered Free Cash Flow | D4: =FCF!C21 -> 19945000 | E4: =FCF!D21 -> 19882000 | F4: =FCF!E21 -> 20087000 | G4: =FCF!F21 -> 14931677 | H4: =FCF!G21 -> 15860901 | I4: =FCF!H21 -> 17077275 | J4: =FCF!I21 -> 18380692 | K4: =FCF!J21 -> 19442782
B6: Projection Year | G6: 1 | H6: 2 | I6: 3 | J6: 4 | K6: 5
B7: Present Value of Free Cash Flow | G7: =G4/(1+$C$12)^G6 -> 14062295 | H7: =H4/(1+$C$12)^H6 -> 14067700 | I7: =I4/(1+$C$12)^I6 -> 14264660 | J7: =J4/(1+$C$12)^J6 -> 14459469 | K7: =K4/(1+$C$12)^K6 -> 14404445
B9: Implied Share Price Calculation | E9: Sensitivity Table
B10: Sum of PV of FCF | C10: =SUM(G7:K7) -> 71258570
B11: Growth Rate | C11: 0.035 | G11: Growth Rate
B12: WACC | C12: =WACC!C18 -> 0.061823609 | F12: =C21 -> 303.43562 | G12: =H12-0.5% -> 0.025 | H12: =I12-0.5% -> 0.03 | I12: 0.035 | J12: =I12+0.5% -> 0.04 | K12: =J12+0.5% -> 0.045
B13: Terminal Value | C13: =K4*(1+C11)/(C12-C11) -> 7.5020778e+08 | E13: WACC | F13: =F14-0.5% -> 0.051823609 | G13: 314.83398 | H13: 381.01892 | I13: 486.54436 | J13: 681.31958 | K13: 1161.5379
B14: PV of Terminal Value | C14: =C13/((1+C12)^K6) -> 5.5580145e+08 | F14: =F15-0.5% -> 0.056823609 | G14: 264.53354 | H14: 309.06817 | I14: 374.00944 | J14: 477.55198 | K14: 668.66723
B15: Enterprise Value | C15: =C14+C10 -> 6.2706002e+08 | F15: 0.061823609 | G15: 227.90005 | H15: 259.73391 | I15: 303.43562 | J15: 367.1623 | K15: 468.7683
B16: (+) Cash | C16: ='Balance Sheet'!F5 -> 20154000 | F16: =F15+0.5% -> 0.066823609 | G16: 200.03174 | H16: 223.80322 | I16: 255.04446 | J16: 297.93263 | K16: 360.47298
B17: (-) Debt | C17: =WACC!C4 -> 25171000 | F17: =F16+0.5% -> 0.071823609 | G17: 178.12053 | H17: 196.46879 | I17: 219.79979 | J17: 250.46215 | K17: 292.55561
B18: (-) Minority Interest | C18: ='Balance Sheet'!F63 -> 0
B19: Equity Value | C19: =(C15+C16-C17-C18) -> 6.2204302e+08
B20: Diluted Shares Outstanding (000s) | C20: 2050000
B21: Implied Share Price | C21: =(C19)/C20 -> 303.43562

Sheet WACC
B2: Weighted Average Cost of Capital (WACC)
B3: Equity (mm) | C3: 662298000
B4: Debt (mm) | C4: =('Balance Sheet'!F64) -> 25171000
B6: Cost of Debt | C6: =-(('Income Statement'!F26))/WACC!C4 -> 0.023399944
B7: Tax Rate | C7: 0.18
B8: D/(D+E) | C8: =C4/SUM(C3:C4) -> 0.036614015
B9: After Tax Cost of Debt | C9: =C6*(1-C7) -> 0.019187954
B11: Risk Free Rate (10-Yr Treasury Yield) | C11: 0.04161
B12: Expected Market Return | C12: 0.078
B13: Market Risk Premium | C13: =C12-C11 -> 0.03639
B14: Levered Beta | C14: 0.6
B15: E/(D+E) | C15: =C3/SUM(C3:C4) -> 0.96338599
B16: Cost of Equity | C16: =C11+C14*(C13) -> 0.063444
B18: WACC | C18: =C9*C8+C16*C15 -> 0.061823609

Sheet Data -->

Sheet Income Statement
A1: V — Income Statement | F1: USD ($000s)
A3: Line Item | B3: 2021 | C3: 2022 | D3: 2023 | E3: 2024 | F3: 2025
A4: Revenue
A5: Revenue | B5: 24105000 | C5: 29310000 | D5: 32653000 | E5: 35926000 | F5: 40000000
A6: Cost Of Revenue | B6: 4970000 | C6: 5733000 | D6: 6567000 | E6: 7042000 | F6: 7855000
A8: Gross Profit
A9: Gross Profit | B9: 19135000 | C9: 23577000 | D9: 26086000 | E9: 28884000 | F9: 32145000
A11: Operating Expenses
A12: Research And Development Expenses | B12: 0 | C12: 0 | D12: 0 | E12: 0 | F12: 0
A13: General And Administrative Expenses | B13: 1388000 | C13: 1699000 | D13: 1875000 | E13: 2233000 | F13: 2685000
A14: Selling And Marketing Expenses | B14: 1136000 | C14: 1336000 | D14: 1341000 | E14: 1560000 | F14: 1684000
A15: Selling General And Administrative Expenses | B15: 2524000 | C15: 3035000 | D15: 3216000 | E15: 3793000 | F15: 4369000
A16: Operating Expenses | B16: 3331000 | C16: 4764000 | D16: 5086000 | E16: 5289000 | F16: 8151000
C17: =SUM(C13:C16) -> 10834000 | D17: =SUM(D13:D16) -> 11518000 | E17: =SUM(E13:E16) -> 12875000 | F17: =SUM(F13:F16) -> 16889000
A18: Operating Income
A19: Ebitda | B19: 17380000 | C19: 19535000 | D19: 22624000 | E19: 25591000 | F19: 26003000
A20: Ebit | B20: 16576000 | C20: 18674000 | D20: 21681000 | E20: 24557000 | F20: 24783000
A21: Non Operating Income Excluding Interest | B21: -772000 | C21: 139000 | D21: -681000 | E21: -962000 | F21: -789000
A22: Operating Income | B22: 15804000 | C22: 18813000 | D22: 21000000 | E22: 23595000 | F22: 23994000
A24: Other Income / Expense
A25: Other Expenses | B25: 807000 | C25: 1729000 | D25: 1870000 | E25: 1496000 | F25: 3782000
A26: Net Interest Income | B26: -513000 | C26: -538000 | D26: -644000 | E26: -641000 | F26: -589000
A27: Interest Income | B27: 0 | C27: 0 | D27: 0 | E27: 0 | F27: 0
A28: Interest Expense | B28: 513000 | C28: 538000 | D28: 644000 | E28: 641000 | F28: 589000
A29: Total Other Income Expenses Net | B29: 259000 | C29: -677000 | D29: 37000 | E29: 321000 | F29: 200000
A31: Pre-Tax Income
A32: Income Before Tax | B32: 16063000 | C32: 18136000 | D32: 21037000 | E32: 23916000 | F32: 24194000
A34: Taxes
A35: Income Tax Expense | B35: 3752000 | C35: 3179000 | D35: 3764000 | E35: 4173000 | F35: 4136000
A37: Net Income
A38: Net Income From Continuing Operations | B38: 12311000 | C38: 14957000 | D38: 17273000 | E38: 19743000 | F38: 20058000
A39: Net Income From Discontinued Operations | B39: 0 | C39: 0 | D39: 0 | E39: 0 | F39: 0
A40: Other Adjustments To Net Income | B40: 0 | C40: 0 | D40: 0 | E40: 0 | F40: 0
A41: Net Income | B41: 12311000 | C41: 14957000 | D41: 17273000 | E41: 19743000 | F41: 20058000
A42: Net Income Deductions | B42: 0 | C42: 0 | D42: 0 | E42: 0 | F42: 0
A43: Bottom Line Net Income | B43: 12311000 | C43: 14957000 | D43: 17273000 | E43: 19743000 | F43: 20058000
A45: Other Income Statement Items
A46: Cost And Expenses | B46: 8301000 | C46: 10497000 | D46: 11653000 | E46: 12331000 | F46: 16006000
A47: Depreciation And Amortization | B47: 804000 | C47: 861000 | D47: 943000 | E47: 1034000 | F47: 1220000
A48: Eps | B48: 0.00563 | C48: 0.00701 | D48: 0.00829 | E48: 0.00974 | F48: 0.01022
...

Sheet Balance Sheet
A1: V — Balance Sheet | F1: USD ($000s)
A3: Line Item | B3: 2021 | C3: 2022 | D3: 2023 | E3: 2024 | F3: 2025
A4: Current Assets
A5: Cash And Cash Equivalents | B5: 16487000 | C5: 15689000 | D5: 16286000 | E5: 11975000 | F5: 20154000
A6: Short Term Investments | B6: 2025000 | C6: 2833000 | D6: 3842000 | E6: 3200000 | F6: 1833000
A7: Cash And Short Term Investments | B7: 18512000 | C7: 18522000 | D7: 20128000 | E7: 15175000 | F7: 21987000
A8: Net Receivables | B8: 3726000 | C8: 3952000 | D8: 4474000 | E8: 7015000 | F8: 7317000
A9: Accounts Receivables | B9: 1968000 | C9: 2020000 | D9: 2291000 | E9: 2561000 | F9: 3126000
A10: Other Receivables | B10: 1758000 | C10: 1932000 | D10: 2183000 | E10: 4454000 | F10: 4191000
A11: Inventory | B11: 0 | C11: 0 | D11: 0 | E11: 0 | F11: 0
A12: Prepaids | B12: 856000 | C12: 2668000 | D12: 0 | E12: 1190000 | F12: 0
A13: Other Current Assets | B13: 4513000 | C13: 5063000 | D13: 8930000 | E13: 10653000 | F13: 8462000
A14: Total Current Assets | B14: 27607000 | C14: 30205000 | D14: 33532000 | E14: 34033000 | F14: 37766000
A15: Other Non Current Assets | B15: 7247000 | C15: 7085000 | D15: 7394000 | E15: 8279000 | F15: 9101000
A16: Total Non Current Assets | B16: 55289000 | C16: 55296000 | D16: 56967000 | E16: 60478000 | F16: 61861000
A17: Short Term Debt | B17: 999000 | C17: 2250000 | D17: 0 | E17: 0 | F17: 5569000
A19: Non-Current Assets
A20: Property Plant Equipment Net | B20: 2715000 | C20: 3223000 | D20: 3425000 | E20: 3824000 | F20: 4236000
A21: Goodwill | B21: 15958000 | C21: 17787000 | D21: 17997000 | E21: 18941000 | F21: 19879000
A22: Intangible Assets | B22: 27664000 | C22: 25065000 | D22: 26104000 | E22: 26889000 | F22: 27646000
A23: Goodwill And Intangible Assets | B23: 43622000 | C23: 42852000 | D23: 44101000 | E23: 45830000 | F23: 47525000
A24: Long Term Investments | B24: 1705000 | C24: 2136000 | D24: 1921000 | E24: 2545000 | F24: 999000
A25: Long Term Debt | B25: 19978000 | C25: 20200000 | D25: 20463000 | E25: 20836000 | F25: 19602000
A26: Total Investments | B26: 3730000 | C26: 4969000 | D26: 5763000 | E26: 5745000 | F26: 2832000
A28: Current Liabilities
A29: Total Payables | B29: 2709000 | C29: 705000 | D29: 1875000 | E29: 479000 | F29: 555000
A30: Account Payables | B30: 266000 | C30: 340000 | D30: 375000 | E30: 479000 | F30: 555000
A31: Other Payables | B31: 2443000 | C31: 365000 | D31: 1500000 | E31: 0 | F31: 0
A32: Accrued Expenses | B32: 3317000 | C32: 1359000 | D32: 1506000 | E32: 5567000 | F32: 1863000
A33: Tax Payables | B33: 325000 | C33: 365000 | D33: 1500000 | E33: 0 | F33: 0
A34: Deferred Revenue | B34: 0 | C34: 0 | D34: -106000 | E34: 0 | F34: 0
A35: Deferred Revenue Non Current | B35: 0 | C35: 0 | D35: 0 | E35: 0 | F35: 0
A37: Equity
A38: Treasury Stock | B38: 0 | C38: 0 | D38: 0 | E38: 0 | F38: 0
A39: Common Stock | B39: 21935000 | C39: 21869000 | D39: 0 | E39: 0 | F39: 0
A40: Retained Earnings | B40: 15351000 | C40: 16116000 | D40: 18040000 | E40: 17289000 | F40: 15106000
A41: Additional Paid In Capital | B41: 18855000 | C41: 0 | D41: 20452000 | E41: 21229000 | F41: 21934000
A42: Other Total Stockholders Equity | B42: -22068000 | C42: -2359000 | D42: -140000 | E42: 0 | F42: 0
A43: Total Stockholders Equity | B43: 37589000 | C43: 35581000 | D43: 38733000 | E43: 39137000 | F43: 37909000
A44: Total Equity | B44: 37589000 | C44: 35581000 | D44: 38733000 | E44: 39137000 | F44: 37909000
...

Sheet Cash Flow Statement
A1: V — Cash Flow Statement | F1: USD ($000s)
A3: Line Item | B3: 2021 | C3: 2022 | D3: 2023 | E3: 2024 | F3: 2025
A4: Cash Flow From Operations
A5: Net Income | B5: 12311000 | C5: 14957000 | D5: 17273000 | E5: 19743000 | F5: 20058000
A6: Depreciation And Amortization | B6: 804000 | C6: 861000 | D6: 943000 | E6: 1034000 | F6: 1220000
A7: Stock Based Compensation | B7: 542000 | C7: 602000 | D7: 765000 | E7: 850000 | F7: 897000
A8: Change In Working Capital | B8: -6702000 | C8: -7657000 | D8: -10022000 | E8: -15432000 | F8: -11788000
A9: Accounts Receivables | B9: -343000 | C9: -97000 | D9: -250000 | E9: -237000 | F9: -542000
A10: Inventory | B10: 1063000 | C10: 0 | D10: 1208000 | E10: 0 | F10: 0
A11: Accounts Payables | B11: 88000 | C11: 67000 | D11: 34000 | E11: 109000 | F11: 67000
A12: Other Working Capital | B12: -7510000 | C12: -7627000 | D12: -11014000 | E12: -15304000 | F12: -11313000
A13: Net Cash Provided By Operating Activities | B13: 15227000 | C13: 18849000 | D13: 20755000 | E13: 19950000 | F13: 23059000
A15: Cash Flow From Investing
A16: Investments In Property Plant And Equipment | B16: -705000 | C16: -970000 | D16: -1059000 | E16: -1257000 | F16: -1482000
A17: Acquisitions Net | B17: -75000 | C17: -1948000 | D17: 0 | E17: -915000 | F17: -887000
A18: Purchases Of Investments | B18: -5182000 | C18: -6083000 | D18: -4484000 | E18: -4674000 | F18: -68000
A19: Sales Maturities Of Investments | B19: 5701000 | C19: 4585000 | D19: 3562000 | E19: 5013000 | F19: 3024000
A20: Other Investing Activities | B20: 109000 | C20: 128000 | D20: -25000 | E20: -93000 | F20: 121000
A21: Net Cash Provided By Investing Activities | B21: -152000 | C21: -4288000 | D21: -2006000 | E21: -1926000 | F21: 708000
A22: Capital Expenditure | B22: -705000 | C22: -970000 | D22: -1059000 | E22: -1257000 | F22: -1482000
A24: Cash Flow From Financing
A25: Net Debt Issuance | B25: -3000000 | C25: 2218000 | D25: -2250000 | E25: 0 | F25: 3924000
A26: Long Term Net Debt Issuance | B26: -3000000 | C26: 2218000 | D26: -2250000 | E26: 0 | F26: 3924000
A27: Short Term Net Debt Issuance | B27: 0 | C27: 0 | D27: 0 | E27: 0 | F27: 0
A28: Net Stock Issuance | B28: -8468000 | C28: -11589000 | D28: -11841000 | E28: -16713000 | F28: -13294000
A29: Net Common Stock Issuance | B29: -8676000 | C29: -11589000 | D29: -12101000 | E29: -16713000 | F29: -13294000
A30: Common Stock Issuance | B30: 0 | C30: 0 | D30: 0 | E30: 0 | F30: 95000
A31: Common Stock Repurchased | B31: -8676000 | C31: -11589000 | D31: -12101000 | E31: -16713000 | F31: -13389000
A32: Net Preferred Stock Issuance | B32: 208000 | C32: 0 | D32: 260000 | E32: 0 | F32: 0
A33: Net Dividends Paid | B33: -2798000 | C33: -3203000 | D33: -3751000 | E33: -4217000 | F33: -4634000
A34: Common Dividends Paid | B34: -2798000 | C34: -3203000 | D34: -3751000 | E34: -4217000 | F34: -4634000
A35: Preferred Dividends Paid | B35: 0 | C35: 0 | D35: 0 | E35: 0 | F35: 0
A36: Other Financing Activities | B36: -144000 | C36: -122000 | D36: 70000 | E36: 297000 | F36: -4959000
A37: Net Cash Provided By Financing Activities | B37: -14410000 | C37: -12696000 | D37: -17772000 | E37: -20633000 | F37: -18963000
A39: Other Cash Flow Items
A40: Deferred Income Tax | B40: 873000 | C40: -336000 | D40: -483000 | E40: -100000 | F40: 152000
A41: Other Non Cash Items | B41: 7399000 | C41: 10422000 | D41: 12279000 | E41: 13855000 | F41: 12520000
A42: Effect Of Forex Changes On Cash | B42: -37000 | C42: -1287000 | D42: 636000 | E42: 382000 | F42: 420000
A43: Net Change In Cash | B43: 628000 | C43: 578000 | D43: 1613000 | E43: -2227000 | F43: 5224000
A44: Cash At End Of Period | B44: 19799000 | C44: 20377000 | D44: 21990000 | E44: 19763000 | F44: 24987000
...
